Workbook
Name RentangBernama1: #REF!

Sheet WO
A1: 46308 | E1: ALL GROUP LEADER CABIN MAINTENANCE PLEASE REMARKS JIKA OPEN ATAU CLOSE
A2: DATE | B2: WG | C2: REG | D2: WO | E2: WO CAT | F2: WO DESCRIPTION | G2: PN PICKLIST (NO. PICKLIST) | H2: MAN HOURS | I2: OPERATOR | J2: TYPE | K2: PLAN STA | L2: REMARKS PPC WG TO LM | M2: ACT STA | N2: STATUS | O2: REASON OPEN | P2: CODE OPEN
A3: 46308 | B3: WG 11 | C3: PK-WJV | D3: 2316519 | E3: OP | F3: CLEANING OF FWD, AFT, AND LAV SMOKE DETECTOR | G3: --- | H3: 2,00 | I3: IW | J3: ATR72 | K3: BTH | L3: REQ PIC | M3: BTH | N3: CLOSED
A4: 46308 | B4: WG 09 | C4: PK-STI | D4: 2333487 | E4: OP | F4: VACUUM TOILET SYSTEM . CLEANING OF VACUUM CLEANING OF VACUUM WASTE LINES WITH CHEMICAL CLEANING AGENT. | G4: --- | H4: 1,00 | I4: IU | J4: A320 | K4: CGK | M4: CGK | N4: CLOSED
A5: 46308 | B5: WG 06 | C5: PK-BKR | D5: 2285964 | E5: OP | F5: POTABLE WATER SYSTEM STERILIZATION OF POTABLE WATER SYSTEM AND DISCARD OF WATER FILTER ELEMENTS. | G5: PN: EV949000 (594700) @ S1 | H5: 3,00 | I5: ID | J5: A320 | K5: CGK | L5: WO OVER DUE PN: EV949000 AVAIL K1 | M5: SUB | N5: OPEN | O5: RON SUB | P5: IRR
A6: 46308 | B6: WG 06 | C6: PK-BKF | D6: 1553162 | E6: OP | F6: CLEANING OF VACUUM WASTE LINES WITH CHEMICAL CLEANING AGENT. | G6: --- | H6: 1,00 | I6: ID | J6: A320 | K6: CGK | M6: CGK | N6: CLOSED
A7: 46308 | B7: WG 07 | C7: PK-BKM | D7: 2288601 | E7: HT | F7: RESTORATION OF MEDICAL KITNOTE:P/N EMK-1000 S/N OFF: LAEMK-338 | G7: --- | H7: 1,00 | I7: ID | J7: A320 | K7: CGK | L7: sn off: LAEMK-338 used spare feee | M7: CGK | N7: CLOSED
A8: 46308 | B8: WG 02 | C8: PK-LSJ | D8: 2283731 | E8: HT | F8: RESTORE THE FIRST AID KITS | G8: PN: LA-FAK / SN: MLI-N132 (595545) @ K1 | H8: 1,00 | I8: JT | J8: B737 | K8: CGK | L8: PN OFF: LA-FAK SN OFF: MLI-N174 PL#595545 // SN: MLI-N132 @K1 | M8: CGK | N8: CLOSED
A9: 46308 | B9: WG 12 | C9: PK-WFS | D9: 2328164 | E9: CBMS | F9: AIRCRAFT PEST CONTROL APPLICATION GUIDE FOR ATR | G9: --- | H9: 2,00 | I9: IW | J9: ATR72 | K9: KOE | L9: REQ PIC MAXFORCE FORTE GEL PN M00023 SEND FROM SUB | M9: KOE | N9: CLOSED
A10: 46308 | B10: WG 12 | C10: PK-WFS | D10: 2289838 | E10: CBMS | F10: LAVATORY WASTE SYSTEM LINE CLEANING | G10: --- | H10: 1,00 | I10: IW | J10: ATR72 | K10: KOE | M10: KOE | N10: CLOSED
A11: 46308 | B11: WG 12 | C11: PK-WJL | D11: 2333427 | E11: CBMS | F11: AIRCRAFT PEST CONTROL APPLICATION GUIDE FOR ATR | G11: --- | H11: 2,00 | I11: IW | J11: ATR72 | K11: LOP | L11: REQ PIC BAIT STATION PN BAIT STATION SEND FROM DPS | M11: LOP | N11: CLOSED
A12: 46308 | B12: WG 08 | C12: PK-SAG | D12: 2295353 | E12: AD | F12: DETAILED INSPECTION OF WASTE COMPARTMENT FOR FIRE CONTAINMENT CAPABILITY & INSPECTION OF ASHTRAYS ON LAVATORY | G12: --- | H12: 1,00 | I12: IU | J12: A320 | K12: SRG | M12: SRG | N12: CLOSED
A13: 46308 | B13: WG 07 | C13: PK-BKT | D13: 2345598 | E13: CBMS | F13: AIRCRAFT PEST CONTROL APPLICATION GUIDE | G13: --- | H13: 1,00 | I13: ID | J13: A320 | K13: SUB | M13: SUB | N13: CLOSED
A14: 46308 | B14: WG 07 | C14: PK-BLB | D14: 2334099 | E14: CBMS | F14: AIRCRAFT PEST CONTROL APPLICATION GUIDE | G14: --- | H14: 1,00 | I14: ID | J14: A320 | K14: SUB | M14: SUB | N14: CLOSED
A15: 46308 | B15: WG 02 | C15: PK-LFY | D15: 2294091 | E15: HT | F15: RESTORE THE RIGHT MID-EXIT DOOR EMERGENCY ESCAPE SLIDE | G15: PN: 65520-102 / SN: 65520-0182 (594723) @ K1 | H15: 1,00 | I15: JT | J15: B737 | K15: SUB | L15: PN OFF: 65520-102 SN OFF: 65520-0166 PL#594723 // SN: 65520-0182 @K1 SEND VIA ID-6406/ETD 13.30 TO.2626700 // S1 | M15: SUB | N15: CLOSED
A16: 46308 | B16: WG 07 | C16: PK-BKT | D16: 1746609 | E16: EO | F16: PINNACLE® / INSPECTION OF SEAT BEAMS / GENERIC / ALL AIRCRAFT TYPES | G16: --- | H16: 2,00 | I16: ID | J16: A320 | K16: SUB | M16: SUB | N16: CLOSED
A17: 46308 | B17: WG 08 | C17: PK-SJG | D17: 2264969 | E17: EO | F17: INSPECTION FOR INVENTORY EMERGENCY EQUIPMENT ON THE AIRCRAFT | G17: --- | H17: 3,00 | I17: IU | J17: A320 | K17: UPG | M17: UPG | N17: CLOSED
A18: 46308 | B18: WG 11 | C18: PK-WFU | D18: 2315243 | E18: OP | F18: CLEANING OF FWD, AFT, AND LAV SMOKE DETECTOR | G18: --- | H18: 2,00 | I18: IW | J18: ATR72 | K18: UPG | L18: REQ PIC | M18: UPG | N18: CLOSED
A19: 46308 | B19: WG 01 | C19: PK-LFO | D19: 2349136 | E19: HT | F19: LIFE VEST REPLACEMENT | G19: --- | H19: 2,00 | I19: JT | J19: B737 | K19: UPG | M19: UPG | N19: CLOSED
A20: 46308 | B20: WG 01 | C20: PK-LFO | D20: 2349136 | E20: HT | F20: PLEASE REPLACED AND RECORD LIFE VEST UNDERSEAT NO: 27E QTY: 1EA D/T EXPIRE | G20: --- | H20: 0,25 | I20: JT | J20: B737 | K20: UPG | M20: UPG | N20: CLOSED
A21: 46308 | C21: PK-LJI | D21: 2329645 | E21: HT | F21: DISCARD THE CHEMICAL OXYGEN GENERATORS. | G21: --- | H21: 3,00 | I21: JT | J21: B737 | K21: SUB | L21: PLIERS - FIRING PIN RETRACTION, OXYGEN GENERATOR PN : E71516-00 AVAIL S1 SPARE PN: E71740-00 AVAIL @S1 TOOL PN: E71401-00 AVAIL @S1 | M21: SUB | N21: OPEN | O21: A/C NOT RON SUB | P21: IRR
A22: 46308 | B22: WG 07 | C22: PK-LUK | D22: 2315756 | E22: EO | F22: CLEANING OF THE SYSTEM CONTROL UNIT 3 (SCU3) IFE RAVE SYSTEM A320 | G22: --- | H22: 1,00 | I22: ID | J22: A320 | K22: KOE | M22: KOE | N22: OPEN | O22: D/T OVER CAPACITY MH

Sheet DMI CBM
A1: INPUT DATE | B1: WG | C1: REG | D1: DMI NO | E1: DMI CAT | F1: DEFER TYPE | G1: STATUS DMI | H1: WO | I1: DMI DESCRIPTION | J1: ATA CHAPTER | K1: DUE DATE DMI | L1: PN REQUIRED | M1: PICKLIST NUMBER | N1: AOC | O1: TYPE | P1: PLAN STA | Q1: PLAN DATE | R1: REMARKS | S1: STATUS WO | T1: CLOSE DATE | U1: ACT STA | V1: REASON OPEN | W1: CODE OPEN | X1: HIGHLIGHT
A2: 46290 | B2: WG 06 | C2: PK-BKF | D2: ID031878 | E2: D | F2: WTG INST | G2: CLOSED | H2: 2322855 | I2: SEAT 1F INOP (RECLINE CANT BE SET TO UP POSITION) | J2: 25 | K2: 46332 | L2: NEED BOLT PN : NAS6603-16 (2EA) AVAIL K1 SEAT MUST BE REMOVED AND BRING TO DELTA FOR INSTALLATION BOLT NEED REPAIRMAN | N2: ID | O2: A320 | P2: CGK | Q2: 46308 | R2: NEED REPAIRMAN | S2: CLOSED | T2: 46308 | U2: CGK | X2: DJA DMI
A3: 46308 | B3: WG 07 | C3: PK-LAM | D3: 019199 | E3: C | F3: INVESTIG | G3: CLOSED | H3: 2148223 | I3: CAPTAIN SEAT CANT RECLINE / ADJUST RECLINE | J3: 25 | K3: 46317 | L3: NEED T/S | N3: ID | O3: A320 | P3: SOC | Q3: 46308 | S3: CLOSED | T3: 46308 | U3: SOC | X3: DJA DMI
A4: 46308 | B4: WG 03 | C4: PK-LKH | D4: 017690 | E4: C | F4: WTG INST | G4: OPEN | H4: 2353523 | I4: WINDOW LIGHTS NO 18ABC-25ABC NOT ILLUMINATE | J4: 33 | K4: 46312 | L4: NEED PART PN : 9701-14-0000 1EA AVAIL K4 PL 593326 PN 9651-35-0002 1EA AVAIL K171 | N4: JT | O4: B737 | P4: SUB | Q4: 46308 | R4: PART PN : 9701-14-0000 1EA AVAIL K4 PL 593326 TP.2626766//S1 SEND VIA JT-707/ETD 14.25 PN 9651-35-0002 1EA (PLEASE SWAP INTERNAL) | S4: OPEN | U4: SUB | V4: NOT COMPLETE SPARE 9651-35-0002 | W4: NS | X4: DJA DMI
A5: 46305 | B5: WG 08 | C5: PK-SGD | D5: SAJ025633 | E5: C1 | F5: WTG INST | G5: CLOSED | H5: 2351361 | I5: CEILING LIGHT SN 16DEF AND 29DEF NOT ILLUMINATE | J5: 33-20-01A | K5: 46309 | L5: NEED PART LAMP PN: ABS1238-26-30B 2EA AVAIL AT K1, PL#596045 | N5: IU | O5: A320 | P5: SRG | Q5: 46308 | R5: REF TP.2627033 & TP.2627037 | S5: CLOSED | T5: 46308 | U5: SRG | X5: DJA DMI
A6: 46308 | B6: WG 03 | C6: PK-LKH | D6: 017690 | E6: C | F6: WTG INST | G6: OPEN | H6: 2353523 | I6: WINDOW LIGHTS NO 18ABC-25ABC NOT ILLUMINATE | J6: 33 | K6: 46312 | L6: NEED PART PN : 9701-14-0000 1EA AVAIL K4 PL 593326 PN 9651-35-0002 1EA AVAIL K171 | N6: JT | O6: B737 | P6: SUB | Q6: 46308 | R6: PART PN : 9701-14-0000 1EA AVAIL K4 PL 593326 TP.2626766//S1 SEND VIA JT-707/ETD 14.25 PN 9651-35-0002 1EA (PLEASE SWAP INTERNAL) | S6: OPEN | U6: SUB | V6: NOT COMPLETE SPARE 9651-35-0002 | W6: NS | X6: DJA DMI
A7: 46305 | B7: WG 08 | C7: PK-SGD | D7: SAJ025633 | E7: C1 | F7: WTG INST | G7: CLOSED | H7: 2351361 | I7: CEILING LIGHT SN 16DEF AND 29DEF NOT ILLUMINATE | J7: 33-20-01A | K7: 46309 | L7: NEED PART LAMP PN: ABS1238-26-30B 2EA AVAIL AT K1, PL#596045 | N7: IU | O7: A320 | P7: SRG | Q7: 46308 | R7: REF TP.2627033 & TP.2627037 | S7: CLOSED | T7: 46308 | U7: SRG | X7: DJA DMI
A8: 46305 | B8: WG 08 | C8: PK-SJG | D8: SAJ-039572 | E8: C1 | F8: WTG INST | G8: CLOSED | H8: 2353546 | I8: CEILING LIGHT AT 18 DEF, 25 DEF NOT ILL | L8: NEED PART FLUORESCENT TUBE QTY : 2EA PN : F30WT8-840 AVAIL AT S1, PL#596351 | N8: IU | O8: A320 | P8: UPG | Q8: 46308 | R8: WTG TP. 2627274 | S8: CLOSED | T8: 46308 | U8: UPG | X8: DJA DMI
A9: 46305 | B9: WG 09 | C9: PK-STF | D9: SAJ008401 | E9: C1 | F9: WTG INST | G9: CLOSED | H9: 2348090 | I9: FLAPER DOOR WASTE BIN AT LAV E NOT FULLY CLOSED (DEACTIVATED OF FLAPPER DOOR WASTE COMPARTMENT C/O) | J9: 25-40-01A | K9: 46308 | L9: NEED DAMPER PN : 9855DV AVAIL AT K5, PL#594545 | N9: IU | O9: A320 | P9: CGK | Q9: 46308 | R9: DMI DUE TODAY REF TP.2626869 | S9: CLOSED | T9: 46308 | U9: CGK | X9: DJA DMI
A10: 46305 | B10: WG 09 | C10: PK-STZ | D10: SAJ-025905 | E10: C1 | F10: WTG INST | G10: CLOSED | H10: 2351554 | I10: CEILING LIGHT 16ABC,28DEF,32ABC NOT ILLUMINATE | J10: 33-20-01A | K10: 46308 | L10: NEED PART LAMP PN : F30WT8-840 (3EA) AVAIL AT K1 PL#596037 | N10: IU | O10: A320 | P10: PDG | Q10: 46308 | S10: CLOSED | T10: 46308 | U10: CGK | V10: ALREADY ACTUAL DMI CLOSED AT KNO | X10: DJA DMI
A11: 46305 | B11: WG 08 | C11: PK-SJA | D11: SAJ017272 | E11: D | F11: WTG INST | G11: CLOSED | H11: 2351634 | I11: FOOT REST CAPTAIN SIDE LOOSE (SECURE STOWED POSITION) | L11: NEED BUFFER PN : ASNA2151-02 QTY : 1EA | N11: IU | O11: A320 | P11: CGK | Q11: 46308 | R11: REF K1, PL#596514 | S11: CLOSED | T11: 46308 | U11: CGK | X11: DJA DMI
A12: 46305 | B12: WG 08 | C12: PK-SJG | D12: SAJ-039572 | E12: C1 | F12: WTG INST | G12: CLOSED | H12: 2353546 | I12: CEILING LIGHT AT 18 DEF, 25 DEF NOT ILL | L12: NEED PART FLUORESCENT TUBE QTY : 2EA PN : F30WT8-840 AVAIL AT S1, PL#596351 | N12: IU | O12: A320 | P12: UPG | Q12: 46308 | R12: WTG TP. 2627274 | S12: CLOSED | T12: 46308 | U12: UPG | X12: DJA DMI
A13: 46305 | B13: WG 09 | C13: PK-SJO | D13: SAJ013156 | E13: C1 | F13: WTG INST | G13: CLOSED | H13: 2352306 | I13: ONE OF ENTRY LIGHT 4R (AFT) NOT ILLUMINATE | J13: 33-20-01A | K13: 46308 | L13: NEED LAMP PN : F30WT8-840 AVAIL AT L2, PL#596109 BALLAS UNIT PN : 3250-81 PO#2581763 PAYMENT PROCESS CIA | N13: IU | O13: A320 | P13: CGK | Q13: 46308 | R13: LAMP REF TP.2626623 BALLAS UNIT PN : 3250-81 ref wo : 2353023 FROM PK-SAP | S13: CLOSED | T13: 46308 | U13: CGK | X13: DJA DMI
A14: 46305 | B14: WG 08 | C14: PK-SGD | D14: SAJ025634 | E14: C1 | F14: WTG INST | G14: CLOSED | H14: 2353542 | I14: L/H FWD ENTRY LIGHT NOT ILLUMINATE | J14: 33-20-01A | K14: 46309 | L14: NEED PART LAMP PN: ABS1238-26-30B 1EA AVAIL AT K1, PL#596045 BALLAST UNIT PN 4197-20-04 1EA AVAIL AT K1 SN 298819 PL 594200 | N14: IU | O14: A320 | P14: SRG | Q14: 46308 | R14: REF TP.2627033 & TP.2627037 | S14: CLOSED | T14: 46308 | U14: SRG | X14: DJA DMI
A15: 46308 | C15: PK-BKP | D15: ID026356 | G15: CLOSED | I15: REF CML B143800 CEILING LIGHT S/N 17DEF ,18ABC,21ABC,25ABC,26DEF,29ABC,29DEF NOT ILLUMINATE | N15: ID | O15: A320 | Q15: 46308 | S15: CLOSED | T15: 46308 | U15: CGK | X15: UNPLANNED DMI

Sheet Sheet47
A1: 46308 | D1: ALL GROUP LEADER CABIN MAINTENANCE PLEASE REMARKS JIKA OPEN ATAU CLOSE
A2: DATE | B2: REG | C2: AOC | D2: DMI DESCRIPTION | E2: PN REQUIRED | F2: DMI NO | G2: DMI CAT | H2: PLAN STA | I2: CAT | J2: STATUS | K2: REMARK
A3: 46308 | B3: PK-BKF | C3: ID | D3: SEAT 1F INOP (RECLINE CANT BE SET TO UP POSITION) | E3: NEED BOLT PN : NAS6603-16 (2EA) AVAIL K1 SEAT MUST BE REMOVED AND BRING TO DELTA FOR INSTALLATION BOLT NEED REPAIRMAN | F3: ID031878 | G3: D | H3: CGK | I3: DJA DMI R01 | J3: CLOSED
A4: 46308 | B4: PK-LAM | C4: ID | D4: CAPTAIN SEAT CANT RECLINE / ADJUST RECLINE | E4: CAPTAIN SEAT CANT RECLINE / ADJUST RECLINE | F4: 019199 | G4: C | H4: SOC | I4: DJA DMI R01 | J4: CLOSED
A5: 46308 | B5: PK-LKH | C5: JT | D5: WINDOW LIGHTS NO 18ABC-25ABC NOT ILLUMINATE | E5: WINDOW LIGHTS NO 18ABC-25ABC NOT ILLUMINATE | F5: 017690 | G5: C | H5: SUB | I5: DJA DMI R01 | J5: OPEN | K5: SPARE NOT AVAILABLE AT S1
A6: 46308 | B6: PK-SGD | C6: IU | D6: CEILING LIGHT SN 16DEF AND 29DEF NOT ILLUMINATE | E6: CEILING LIGHT SN 16DEF AND 29DEF NOT ILLUMINATE | F6: SAJ025633 | G6: C1 | H6: SRG | I6: DJA DMI R01 | J6: CLOSED
A7: 46308 | B7: PK-LKH | C7: JT | D7: WINDOW LIGHTS NO 18ABC-25ABC NOT ILLUMINATE | E7: NEED PART PN : 9701-14-0000 1EA AVAIL K4 PL 593326 PN 9651-35-0002 1EA AVAIL K171 | F7: 017690 | G7: C | H7: SUB | I7: DJA DMI R01 | J7: OPEN | K7: SPARE NOT AVAILABLE AT S1
A8: 46308 | B8: PK-SGD | C8: IU | D8: CEILING LIGHT SN 16DEF AND 29DEF NOT ILLUMINATE | E8: NEED PART LAMP PN: ABS1238-26-30B 2EA AVAIL AT K1, PL#596045 | F8: SAJ025633 | G8: C1 | H8: SRG | I8: DJA DMI R01 | J8: CLOSED
A9: 46308 | B9: PK-SJG | C9: IU | D9: CEILING LIGHT AT 18 DEF, 25 DEF NOT ILL | E9: CEILING LIGHT AT 18 DEF, 25 DEF NOT ILL | F9: SAJ-039572 | G9: C1 | H9: UPG | I9: DJA DMI R01 | J9: CLOSED
A10: 46308 | B10: PK-STF | C10: IU | D10: FLAPER DOOR WASTE BIN AT LAV E NOT FULLY CLOSED (DEACTIVATED OF FLAPPER DOOR WASTE COMPARTMENT C/O) | E10: NEED DAMPER PN : 9855DV AVAIL AT K5, PL#594545 | F10: SAJ008401 | G10: C1 | H10: CGK | I10: DJA DMI R01 | J10: CLOSED
A11: 46308 | B11: PK-STZ | C11: IU | D11: CEILING LIGHT 16ABC,28DEF,32ABC NOT ILLUMINATE | E11: NEED PART LAMP PN : F30WT8-840 (3EA) AVAIL AT K7, PL#596037 | F11: SAJ-025905 | G11: C1 | H11: CGK | I11: DJA DMI R01 | J11: OPEN | K11: RON PDG
A12: 46308 | B12: PK-SJA | C12: IU | D12: FOOT REST CAPTAIN SIDE LOOSE (SECURE STOWED POSITION) | E12: NEED BUFFER PN : ASNA2151-02 QTY : 1EA REF PL#596422 | F12: SAJ017272 | G12: D | H12: CGK | I12: DJA DMI R01 | J12: CLOSED
A13: 46308 | B13: PK-SJG | C13: IU | D13: CEILING LIGHT AT 18 DEF, 25 DEF NOT ILL | E13: NEED PART FLUORESCENT TUBE QTY : 2EA PN : F30WT8-840 AVAIL AT S1, PL#596351 | F13: SAJ-039572 | G13: C1 | H13: UPG | I13: DJA DMI R01 | J13: CLOSED
A14: 46308 | B14: PK-SJO | C14: IU | D14: ONE OF ENTRY LIGHT 4R (AFT) NOT ILLUMINATE | E14: NEED LAMP PN : F30WT8-840 AVAIL AT L2, PL#596109 BALLAS UNIT PN : 3250-81 PO#2581763 PAYMENT PROCESS CIA | F14: SAJ013156 | G14: C1 | H14: CGK | I14: DJA DMI R01 | J14: CLOSED
A15: 46308 | B15: PK-SGD | C15: IU | D15: L/H FWD ENTRY LIGHT NOT ILLUMINATE NOT ILLUMINATE | E15: LAMP PN:ABS1238-26-30B, BALLAST UNIT PN:4197-20-04 | F15: SAJ-025634 | G15: C1 | H15: SRG | I15: DJA DMI R01 | J15: CLOSED
A16: 46308 | B16: PK-BKP | C16: ID | D16: REF CML B143800 CEILING LIGHT S/N 17DEF ,18ABC,21ABC,25ABC,26DEF,29ABC,29DEF NOT ILLUMINATE | F16: ID026356 | H16: CGK | I16: UNPLANNED DMI | J16: CLOSED

Sheet DJA AOC NSRDIL R01
A1: 46308
A2: REFRESH DATE | B2: WG | C2: AC REG | D2: NSRDI | E2: FINDING DESCRIPTION | F2: CATEGORY | G2: REPORT DATE | H2: DUE DATE | I2: PART NUMBER | J2: PART DESCRIPTION | K2: DEFER | L2: AOC | M2: TYPE | N2: PLAN STA | O2: PLAN DATE | P2: REMARKS | Q2: STATUS | R2: CLOSE DATE | S2: ACT STA | T2: REASON OPEN | U2: CODE OPEN
A3: 46287 | B3: WG 01 | C3: PK-LQT | D3: NLA087294 | E3: DAILY RON CHECK OVERHEAD BIN AT SEAT NO 1BC AND 39ABCDEF NOT PROPER | F3: CBM | G3: 46229 | H3: 46349 | I3: SP23988 | J3: CONTROL | K3: WAITING PERFORM | L3: JT | M3: B737 | N3: KOE | O3: 46308 | P3: AVAIL K1 TP.2626615 // K126 | Q3: OPEN | S3: UPG | T3: D/T NOT RON KOE | U3: IRR
A4: 46304 | B4: WG 12 | C4: PK-WHK | D4: NWA033029 | E4: WORD "EXIT " KELUAR" AT EMERGENCY EXIT WINDOW ARE NOT CLEAR (TORN) | F4: CBM | G4: 46278 | I4: LT11-11-PLC-0025 | J4: EXIT / KELUAR PLACARD | K4: WAITING PERFORM | L4: IW | M4: ATR72 | N4: BDJ | O4: 46308 | P4: PART AVAIL B1 | Q4: CLOSED | R4: 46308 | S4: BDJ
A5: 46261 | B5: WG 06 | C5: PK-LUI | D5: NID002111 | E5: REFF NSRDI NO NBA048520, CARGO NET FWD AND AFT BAD CONDITION | F5: CBM | G5: 46210 | H5: 46330 | K5: INVESTIGATE | L5: ID | M5: A320 | N5: CGK | O5: 46308 | P5: FACING OVERDUE. PLEASE INVESTIGATE/RE-INSPECT. JIKA SUDAH ADA PERBAIKAN, PLEASE CLOSED EMRO. JIKA BELUM PLEASE CLOSED DEFECT LAMA DAN REOPEN DEFECT BARU SESUAI HASIL INSPECT | Q5: CLOSED | R5: 46308 | S5: CGK
A6: 46261 | B6: WG 06 | C6: PK-BDF | D6: NBA007488 | E6: REF NSRDI NO.NBA007487 IFE AT SEAT NO.15ABC-29ABC, 7DEF-29DEF RDU OFFLINE | F6: CBM | K6: INVESTIGATE | L6: ID | M6: A320 | N6: CGK | O6: 46308 | P6: NEW FINDING. PLEASE INVESTIGATE | Q6: CLOSED | R6: 46308 | S6: CGK
A7: 46261 | B7: WG 07 | C7: PK-BKG | D7: NID014191 | E7: REFF FINDING QAA 19425 SEAT BELT NO.21BCDE TORN | F7: CBM | K7: INVESTIGATE | L7: ID | M7: A320 | N7: CGK | O7: 46308 | P7: NEW FINDING. PLEASE INVESTIGATE | Q7: CLOSED | R7: 46308 | S7: CGK
A8: 46261 | B8: WG 07 | C8: PK-BKL | D8: NID008262 | E8: BACKREST 30BF,26D,24D,23A,19D,16E,8CD,6D,31B BAD CONDITION | F8: CBM | K8: INVESTIGATE | L8: ID | M8: A320 | N8: CGK | O8: 46308 | P8: NEW FINDING. PLEASE INVESTIGATE | Q8: CLOSED | R8: 46308 | S8: CGK
A9: 46261 | B9: WG 07 | C9: PK-BKL | D9: NID008265 | E9: REFF NSRDIL NID014077 ALL BACKREST COVER Y-CLASS BAD CONDITION | F9: CBM | K9: INVESTIGATE | L9: ID | M9: A320 | N9: CGK | O9: 46308 | P9: NEW FINDING. PLEASE INVESTIGATE | Q9: CLOSED | R9: 46308 | S9: CGK
A10: 46261 | B10: WG 07 | C10: PK-BKM | D10: NBA051338 | E10: REFF NSRDIL NBA051310 ARMCAP ASSY 4D BROKEN | F10: CBM | G10: 46211 | H10: 46331 | K10: INVESTIGATE | L10: ID | M10: A320 | N10: CGK | O10: 46308 | P10: FACING OVERDUE. PLEASE INVESTIGATE/RE-INSPECT. JIKA SUDAH ADA PERBAIKAN, PLEASE CLOSED EMRO. JIKA BELUM PLEASE CLOSED DEFECT LAMA DAN REOPEN DEFECT BARU SESUAI HASIL INSPECT | Q10: CLOSED | R10: 46308 | S10: CGK
A11: 46276 | B11: WG 07 | C11: PK-BKM | D11: NID012421 | E11: AISLE CARPET FOUND BAD CONDITION | F11: CBM | G11: 46296 | H11: 46296 | K11: INVESTIGATE | L11: ID | M11: A320 | N11: CGK | O11: 46308 | P11: PLEASE INVESTIGATE FINDING OVERDUE. JIKA SUDAH ADA PERBAIKAN, PLEASE CLOSED EMRO. JIKA BELUM PLEASE CLOSED DEFECT LAMA DAN REOPEN DEFECT BARU SESUAI HASIL INSPECT | Q11: CLOSED | R11: 46308 | S11: CGK
A12: 46276 | B12: WG 07 | C12: PK-BKM | D12: NID012422 | E12: ARM CAP 25D FLACKING | F12: CBM | G12: 46296 | H12: 46296 | K12: INVESTIGATE | L12: ID | M12: A320 | N12: CGK | O12: 46308 | P12: PLEASE INVESTIGATE FINDING OVERDUE. JIKA SUDAH ADA PERBAIKAN, PLEASE CLOSED EMRO. JIKA BELUM PLEASE CLOSED DEFECT LAMA DAN REOPEN DEFECT BARU SESUAI HASIL INSPECT | Q12: CLOSED | R12: 46308 | S12: CGK
A13: 46276 | B13: WG 07 | C13: PK-BKM | D13: NID012424 | E13: COVER LIFEVEST AT SEAT 2DF BROKEN | F13: CBM | G13: 46296 | H13: 46296 | K13: INVESTIGATE | L13: ID | M13: A320 | N13: CGK | O13: 46308 | P13: PLEASE INVESTIGATE FINDING OVERDUE. JIKA SUDAH ADA PERBAIKAN, PLEASE CLOSED EMRO. JIKA BELUM PLEASE CLOSED DEFECT LAMA DAN REOPEN DEFECT BARU SESUAI HASIL INSPECT | Q13: CLOSED | R13: 46308 | S13: CGK
A14: 46261 | B14: WG 06 | C14: PK-BLC | D14: NBA048839 | E14: MIRROR LE FOUND FADDED | F14: CBM | G14: 46211 | H14: 46331 | K14: INVESTIGATE | L14: ID | M14: A320 | N14: CGK | O14: 46308 | P14: FACING OVERDUE. PLEASE INVESTIGATE/RE-INSPECT. JIKA SUDAH ADA PERBAIKAN, PLEASE CLOSED EMRO. JIKA BELUM PLEASE CLOSED DEFECT LAMA DAN REOPEN DEFECT BARU SESUAI HASIL INSPECT | Q14: CLOSED | R14: 46308 | S14: CGK
A15: 46261 | B15: WG 06 | C15: PK-BLC | D15: NBA048841 | E15: SEAT CUSHION AT NO.29A BAD CONDITION | F15: CBM | G15: 46216 | H15: 46336 | K15: INVESTIGATE | L15: ID | M15: A320 | N15: CGK | O15: 46308 | P15: FACING OVERDUE. PLEASE INVESTIGATE/RE-INSPECT. JIKA SUDAH ADA PERBAIKAN, PLEASE CLOSED EMRO. JIKA BELUM PLEASE CLOSED DEFECT LAMA DAN REOPEN DEFECT BARU SESUAI HASIL INSPECT | Q15: CLOSED | R15: 46308 | S15: CGK
A16: 46261 | B16: WG 07 | C16: PK-LAM | D16: NBA054876 | E16: REFF NBA048577 NET AFT CARGO BAD CONDITION | F16: CBM | G16: 46209 | H16: 46329 | I16: PN : AC40-0217000 | J16: NET DOOR TYPE A | K16: INVESTIGATE | L16: ID | M16: A320 | N16: CGK | O16: 46308 | P16: FACING OVERDUE. PLEASE INVESTIGATE/RE-INSPECT. JIKA SUDAH ADA PERBAIKAN, PLEASE CLOSED EMRO. JIKA BELUM PLEASE CLOSED DEFECT LAMA DAN REOPEN DEFECT BARU SESUAI HASIL INSPECT | Q16: CLOSED | R16: 46308 | S16: SOC
A17: 46261 | B17: WG 06 | C17: PK-LAW | D17: NBA051940 | E17: REFF NSRDI PAGE NBA051936, OVEN NO 104 FWD GALLEY INOP, AFTER REPLACE STEAM OVEN TROUBLE STILL EXIST, CANNOT CONTINOUSE TROUBLESHOOT D/T CANNOT REMOVE OVEN NO 103 SCREW STUCK | F17: CBM | K17: INVESTIGATE | L17: ID | M17: A320 | N17: CGK | O17: 46308 | P17: NEW FINDING. PLEASE INVESTIGATE | Q17: CLOSED | R17: 46308 | S17: CGK
A18: 46304 | B18: WG 07 | C18: PK-LAY | D18: NID006138 | E18: REF FINDING SRV10755 CARPET UNDER SEAT 18DE 22DF BAD CONDITION | F18: CBM | H18: 46420 | K18: INVESTIGATE | L18: ID | M18: A320 | N18: CGK | O18: 46308 | P18: NEW FINDING. PLEASE INVESTIGATE AND RECTIFICATION. IF NEED SPARE PARTS, PLEASE CREATE RQ IN EMRO | Q18: CLOSED | R18: 46308 | S18: CGK
A19: 46261 | B19: WG 07 | C19: PK-LAY | D19: NID006138 | E19: REF FINDING SRV10755 CARPET UNDER SEAT 18DE 22DF BAD CONDITION | F19: CBM | K19: INVESTIGATE | L19: ID | M19: A320 | N19: CGK | O19: 46308 | P19: NEW FINDING. PLEASE INVESTIGATE | Q19: CLOSED | R19: 46308 | S19: CGK
A20: 46261 | B20: WG 07 | C20: PK-LAY | D20: NID006143 | E20: FINDING SRV : 10755 CARPET UNDERSEAT NO 18DE & 22DF FOUND BAD CONDITION | F20: CBM | K20: INVESTIGATE | L20: ID | M20: A320 | N20: CGK | O20: 46308 | P20: NEW FINDING. PLEASE INVESTIGATE | Q20: CLOSED | R20: 46308 | S20: CGK
A21: 46261 | B21: WG 05 | C21: PK-LBS | D21: NID008054 | E21: REF ICT 18962 BACKREST SEAT 4-29 CD BAD CONDITION | F21: CBM | K21: INVESTIGATE | L21: ID | M21: B737 | N21: CGK | O21: 46308 | P21: NEW FINDING. PLEASE INVESTIGATE | Q21: CLOSED | R21: 46308 | S21: CGK
A22: 46261 | B22: WG 05 | C22: PK-LBS | D22: NID008055 | E22: REF ICT 18961 SEAT POCKET 12A 12C NOT PROPER | F22: CBM | K22: INVESTIGATE | L22: ID | M22: B737 | N22: CGK | O22: 46308 | P22: NEW FINDING. PLEASE INVESTIGATE | Q22: CLOSED | R22: 46308 | S22: CGK
A23: 46261 | B23: WG 05 | C23: PK-LBS | D23: NID008056 | E23: REF ICT 18960 BACKREST SEAT 28C 8C NOT PROPER | F23: CBM | K23: INVESTIGATE | L23: ID | M23: B737 | N23: CGK | O23: 46308 | P23: NEW FINDING. PLEASE INVESTIGATE | Q23: CLOSED | R23: 46308 | S23: CGK
A24: 46261 | B24: WG 05 | C24: PK-LBS | D24: NID008061 | E24: REF ICT 18953 HEADREST PILOT CO-PILOT BAD CONDITION | F24: CBM | K24: INVESTIGATE | L24: ID | M24: B737 | N24: CGK | O24: 46308 | P24: NEW FINDING. PLEASE INVESTIGATE | Q24: CLOSED | R24: 46308 | S24: CGK
A25: 46261 | B25: WG 05 | C25: PK-LBS | D25: NID014570 | E25: ARMCAP SEAT NO 11F, 12ABCDEF, 16BC, 17ABCDEF, 18ABCDEF, 19ABCDEF, 20ABCDEF, 21ABCDEF, 22ABCDEF, 23ABCDEF, 24ABCDEF, 25ABCDEF, 26ABCDEF, 27ABCDEF, 28ABCDEF, 29ABCDEF, 30ABCDEF | F25: CBM | G25: 46207 | H25: 46327 | K25: INVESTIGATE | L25: ID | M25: B737 | N25: CGK | O25: 46308 | P25: FACING OVERDUE. PLEASE INVESTIGATE/RE-INSPECT. JIKA SUDAH ADA PERBAIKAN, PLEASE CLOSED EMRO. JIKA BELUM PLEASE CLOSED DEFECT LAMA DAN REOPEN DEFECT BARU SESUAI HASIL INSPECT | Q25: CLOSED | R25: 46308 | S25: CGK
A26: 46261 | B26: WG 05 | C26: PK-LDK | D26: NID008314 | E26: FRAME WINDOW SEAT NO 30ABC CRACK | F26: CBM | K26: INVESTIGATE | L26: ID | M26: B737 | N26: CGK | O26: 46308 | P26: NEW FINDING. PLEASE INVESTIGATE | Q26: CLOSED | R26: 46308 | S26: CGK
A27: 46303 | B27: WG 01 | C27: PK-LFO | D27: NLA094712 | E27: REFF FINDING ICT19431 RECLINE NO38C 37C 29C 27D 22C 3CD 2C NOT FUNTION | F27: CBM | G27: 46303 | H27: 46423 | K27: INVESTIGATE | L27: JT | M27: B737 | N27: UPG | O27: 46308 | P27: NEW FINDING. PLEASE INVESTIGATE AND RECTIFICATION. IF NEED SPARE PARTS, PLEASE CREATE RQ IN EMRO | Q27: CLOSED | R27: 46308 | S27: UPG | T27: NLA094714
A28: 46304 | B28: WG 06 | C28: PK-LUV | D28: NID008808 | E28: REFF FINDING SRV14031,CARPET NTF AT FWD GALLEY BAD CONDITION | F28: CBM | G28: 46269 | H28: 46389 | I28: 500H6484 | J28: BATIFLEX AVM 282 OPUS MIAMI | K28: WAITING PERFORM | L28: ID | M28: A320 | N28: CGK | O28: 46308 | Q28: OPEN | S28: DJB | T28: A/C NOT RON AS PLAN_NO SPARE at DJB TO PERFORM | U28: IRR
A29: 46304 | B29: WG 07 | C29: PK-LUW | D29: NID021845 | E29: FINDING QAA 18784 THE SCRSCTED ON THE UPPERFUSLAGE PAINTING | F29: PAINTING | H29: 46390 | K29: WAITING PERFORM | L29: ID | M29: A320 | N29: CGK | O29: 46308 | Q29: CLOSED | S29: CGK
A30: 46261 | B30: WG 08 | C30: PK-SAA | D30: NSAJ016789 | E30: DAILY RON CHECK FAIRING SEAT NO. 2BF, 3AF, 4AF FOUND CRACK | F30: CBM | G30: 46304 | H30: 46424 | I30: F0432709 | J30: CENTRAL SPREADER FAIRING, NO RECLINE | K30: WAITING PERFORM | L30: IU | M30: A320 | N30: CGK | O30: 46308 | P30: AVAIL K1 | Q30: CLOSED | R30: 46308 | S30: CGK
A31: 46261 | B31: WG 08 | C31: PK-SAI | D31: NSAJ006021 | E31: REF FINDING ICT 19713 HEADTRACK PEEL OFF NO. 2 ABC | F31: PAINTING | G31: 46303 | H31: 46423 | K31: WAITING PERFORM | L31: IU | M31: A320 | N31: CGK | O31: 46308 | Q31: OPEN | S31: LOP | T31: AIRCRAFT NOT RON AS PLAN DJA | U31: IRR
A32: 46261 | B32: WG 09 | C32: PK-SJH | D32: NSAJ021413 | E32: TOILET SEAT LAV "A" CRACK | F32: CBM | I32: A425400461-600 | J32: SEAT ASSY | K32: WAITING PERFORM | L32: IU | M32: A320 | N32: SUB | O32: 46308 | P32: AVAIL AT S1 | Q32: CLOSED | R32: 46308 | S32: SUB
A33: 46304 | B33: WG 02 | C33: PK-LOQ | D33: NLA070784 | E33: INSPECTION NO 18905 FOUND WINDOW R/H SUNVISOR MISSING | F33: CBM | H33: 46418 | I33: 170-14460-990 | J33: SUNSHADE ASSY NO. 2 WINDOW R/H SIDE | K33: WAITING PERFORM | L33: JT | M33: B737 | N33: DPS | O33: 46308 | P33: AVAIL K5 | Q33: CLOSED | R33: 46308 | S33: DPS
A34: 46287 | B34: WG 02 | C34: PK-LOQ | D34: NLA070784 | E34: INSPECTION NO 18905 FOUND WINDOW R/H SUNVISOR MISSING | F34: CBM | G34: 46298 | H34: 46418 | I34: 170-14460-990 | J34: SUNSHADE ASSY NO. 2 WINDOW R/H SIDE | K34: WAITING PERFORM | L34: JT | M34: B737 | N34: DPS | O34: 46308 | P34: AVAIL K5 | Q34: CLOSED | R34: 46308 | S34: DPS
A35: 46261 | B35: WG 06 | C35: PK-LUP | D35: NID007366 | E35: WATER AND WASTE SYSTEM ERROR | F35: CBM | K35: INVESTIGATE | L35: ID | M35: A320 | N35: HLP | O35: 46308 | P35: NEW FINDING. PLEASE INVESTIGATE | Q35: CLOSED | R35: 46308 | S35: HLP
A36: 46287 | B36: WG 02 | C36: PK-LJI | D36: NLA081718 | E36: REFF NSRDIL NO NLA081718 ESCUTCHION ARMCAP AND SCREW S/N 38A AND 39DF FOUND MISSING | F36: CBM | G36: 46298 | H36: 46418 | I36: 1010206-301BHU | J36: ESCUTCHEON, BLANK | K36: WAITING PERFORM | L36: JT | M36: B737 | N36: SUB | O36: 46308 | P36: AVAIL S1 | Q36: OPEN | S36: KNO | T36: AC NOT RON AS PLAN DJA | U36: IRR
A37: 46287 | B37: WG 01 | C37: PK-LJQ | D37: NLA074512 | E37: DURING DAILY RON CHECK SEAT NUMBERING 1-3ABC, 3DEF FOUND BAD CONDITION | F37: CBM | G37: 46289 | H37: 46409 | I37: LT11-11-PLC-0307 | J37: SEAT NUMBERING NO. 2 ABC | K37: WAITING PERFORM | L37: JT | M37: B737 | N37: CGK | O37: 46308 | P37: AVAIL K22 | Q37: CLOSED | R37: 46308 | S37: CGK
A38: 46287 | B38: WG 01 | C38: PK-LJQ | D38: NLA074512 | E38: DURING DAILY RON CHECK SEAT NUMBERING 1-3ABC, 3DEF FOUND BAD CONDITION | F38: CBM | G38: 46289 | H38: 46409 | I38: LT11-11-PLC-0308 | J38: SEAT NUMBERING NO. 3 ABC | K38: WAITING PERFORM | L38: JT | M38: B737 | N38: CGK | O38: 46308 | P38: AVAIL S1 TO.2627002 K22 | Q38: CLOSED | R38: 46308 | S38: CGK
A39: 46287 | B39: WG 01 | C39: PK-LJQ | D39: NLA074512 | E39: DURING DAILY RON CHECK SEAT NUMBERING 1-3ABC, 3DEF FOUND BAD CONDITION | F39: CBM | G39: 46289 | H39: 46409 | I39: LT11-11-PLC-0371 | J39: SEAT NUMBERING NO. 3 DEF | K39: WAITING PERFORM | L39: JT | M39: B737 | N39: CGK | O39: 46308 | P39: AVAIL K22 | Q39: CLOSED | R39: 46308 | S39: CGK
A40: 46287 | B40: WG 01 | C40: PK-LJQ | D40: NLA074518 | E40: PLACARD ARROW DIRECTION STATION 4R BAD CONDITION | F40: CBM | G40: 46301 | H40: 46421 | I40: LT11-11-PLC-01421 | J40: PLACARD EMERGENCY USED ONLY (HANYA DIPAKAI DALAM KEADAAN DARURAT) | K40: WAITING PERFORM | L40: JT | M40: B737 | N40: CGK | O40: 46308 | P40: AVAIL K22 | Q40: OPEN | S40: CGK | T40: PLACARD NOT COMPLETED I NEED THIS TOO PN:LT11-11-PLC-01422 1EA | U40: WTP
...

Sheet ALL FINDING
A1: 46308 | D1: ALL GROUP LEADER CABIN MAINTENANCE PLEASE CANTUMKAN REFF DOC NUMBER DI KOLOM REMARKS
A2: DATE | B2: AOC | C2: REG | D2: DOC TYPE | E2: FINDING NO | F2: DEFECT DESCRIPTION | G2: ACTION TAKEN | H2: STATION | I2: STATUS FINDING | J2: STATUS DOC | K2: REMARKS REF NO CML/NSRDI/DMI/AFML | L2: PICTURES
A3: 46308 | B3: ID | C3: PK-LUK | D3: INSPECTION | E3: 19439 | F3: PK-LUK Seat Track Cover: 6F, 27F, 28C, 28D, Found missing. Inserted NSRDI No. NID016995 | I3: OPEN | J3: OPEN
A4: 46308 | B4: JT | C4: PK-LKQ | D4: QAA | E4: 18802 | F4: (A01-G) FO Aft window shade missing | I4: OPEN | J4: OPEN
A5: 46308 | B5: JT | C5: PK-LKQ | D5: QAA | E5: 18803 | F5: (A01-18) Capt side seat in poor condition | I5: OPEN | J5: OPEN
A6: 46308 | B6: JT | C6: PK-LHR | D6: QAA | E6: 18892 | F6: Ceilling cover by tape at row 28 | I6: OPEN | J6: OPEN
A7: 46308 | B7: JT | C7: PK-LHR | D7: QAA | E7: 18893 | F7: LD lavatory toilet seat crack. | I7: OPEN | J7: OPEN
A8: 46308 | B8: JT | C8: PK-LHR | D8: QAA | E8: 18894 | F8: Over head bin hydrolock inop | I8: OPEN | J8: OPEN
A9: 46308 | B9: JT | C9: PK-LKV | D9: INSPECTION | E9: 18845 | F9: PK-LKV FOUND FWD AND AFT LAVATORY SIGN NOT ILLUMINATE | I9: OPEN | J9: OPEN
A10: 46308 | B10: JT | C10: PK-LKV | D10: INSPECTION | E10: 18847 | F10: FOUND POT COFFE MAKER AT FWD GALEY NOT INSTALLED | I10: OPEN | J10: OPEN
A11: 46308 | B11: ID | C11: PK-BKF | D11: INSPECTION | E11: 18645 | F11: BACKREST COVER TORN AT OBSERVER SEAT | I11: OPEN | J11: OPEN
A12: 46308 | B12: ID | C12: PK-BKF | D12: INSPECTION | E12: 18647 | F12: PANEL COVER BROKEN AT SEAT NO 4C | I12: OPEN | J12: OPEN
A13: 46308 | B13: ID | C13: PK-BKF | D13: INSPECTION | E13: 18648 | F13: PANEL COVER SEAT UNPROPER AT SEAT NO 4D | I13: OPEN | J13: OPEN
A14: 46308 | B14: ID | C14: PK-BKF | D14: INSPECTION | E14: 18650 | F14: SEAT CANT RECLINE AT SEAT NO 26 C & D | I14: OPEN | J14: OPEN
... A29: 46308 | B29: JT | C29: PK-LHR | D29: QAA | E29: 18681 | F29: A/C EXTERIOR FOUND DIRTY | I29: OPEN | J29: OPEN
A30: 46308 | B30: ID | C30: PK-BKF | D30: INSPECTION | E30: 18656 | F30: HINGE TOILET SEAT BROKEN AT LAVATORY A | H30: CGK | I30: CLOSED | J30: CLOSED | K30: B141632/NID014243
A31: 46308 | B31: ID | C31: PK-BKF | D31: INSPECTION | E31: 18658 | F31: FILTER WASHBESIN MISSING AT LAVATORY D&E | H31: CGK | I31: CLOSED | J31: OPEN | K31: CLOSED LAV D B141628 / OPEN NSRDIL LAV E NID021496
A32: 46308 | B32: ID | C32: PK-BKF | D32: INSPECTION | E32: 18649 | F32: SPRING BUCKLE SEAT BROKEN AT SEAT NO 12E | H32: CGK | I32: CLOSED | J32: OPEN | K32: NID021497
A33: 46308 | B33: ID | C33: PK-BKF | D33: INSPECTION | E33: 18643 | F33: SEAT COVER BOTTOM BROKEN AT CAPTAIN SEAT | H33: CGK | I33: CLOSED | J33: OPEN | K33: NID021498
A34: 46308 | B34: ID | C34: PK-BKF | D34: INSPECTION | E34: 18644 | F34: SEAT COVER BOTTOM BROKEN AT OBSERVER SEAT | H34: CGK | I34: CLOSED | J34: OPEN | K34: NID021499
A35: 46308 | B35: ID | C35: PK-BKF | D35: INSPECTION | E35: 18646 | F35: BACKREST BROKEN AT SEAT NO 20E | H35: CGK | I35: CLOSED | J35: OPEN | K35: NID021500
A36: 46308 | B36: IU | C36: PK-STF | D36: QAA | E36: 19107 | F36: A01-18 (HARNESS FO SIDE WAS BAD CONDITION | H36: CGK | I36: CLOSED | J36: OPEN | K36: NSAJ016987
A37: 46308 | B37: IU | C37: PK-SJT | D37: INSPECTION | E37: 19254 | F37: LOWER MIRROR ERRODED IN LAVATORY D | H37: PKU | I37: CLOSED | J37: OPEN | K37: NSAJ017144
A38: 46308 | B38: IU | C38: PK-SJT | D38: INSPECTION | E38: 19253 | F38: COVER WATER FILTER WASH BASIN MISSING IN LAVATORY A | H38: PKU | I38: CLOSED | J38: OPEN | K38: NSAJ017145
A39: 46308 | B39: IU | C39: PK-SJT | D39: INSPECTION | E39: 19251 | F39: NO PLACARD "PLEASE SEAT & DON'T SQUAT ON TOILET BOWL IN TOILET D & E | H39: PKU | I39: CLOSED | J39: OPEN | K39: NSAJ017146
A40: 46308 | B40: IU | C40: PK-STF | D40: QAA | E40: 19084 | F40: A01-M-G FO aft window shade missing~~~~~~~~~~~~~~~~~ | H40: CGK | I40: CLOSED | J40: OPEN | K40: NSAJ024327
A41: 46308 | B41: IU | C41: PK-STF | D41: QAA | E41: 19085 | F41: A01-M-G (SUN VISOR CAPTAIN SIDE WAS BAD CONDITION) | H41: CGK | I41: CLOSED | J41: OPEN | K41: NSAJ024328
... A51: 46308 | B51: IU | C51: PK-SJT | D51: INSPECTION | E51: 19252 | F51: COVER SEAT TRACK MISSING AT ROW 31FED | H51: PKU | I51: CLOSED | J51: CLOSED | K51: S126555
A52: 46308 | B52: IU | C52: PK-SJI | D52: INSPECTION | E52: 18930 | F52: TAIL SECTION IS DIRTY | I52: OPEN | J52: OPEN

Sheet UNPLANNED WO
A1: 46307
A2: DATE | B2: AOC | C2: REG | D2: DOC TYPE | E2: NO. DOC | F2: DEFFECT DESCRIPTION | G2: STATUS MATERIAL | H2: STA | I2: STATUS | J2: REMARKS
A3: 46307 | B3: BATIK AIR | C3: PK-LUG | D3: WO | E3: 2347420 | F3: ALL BUSINESS SEAT DRESS COVER | H3: CGK | I3: CLOSED
A4: 46308 | B4: SUPER AIR JET | C4: PK-SAP | D4: WO | E4: 2353023 | F4: PLEASE REMOVE BALLAST UNIT PN 3250-81 QTY 1EA FOR SUPPORT PK-SJO DMI DUE C1 | H4: CGK | I4: CLOSED
A5: 46308 | B5: SUPER AIR JET | C5: PK-SAP | D5: WO | E5: 2353085 | F5: REMOVE PART LAMP | H5: CGK | I5: CLOSED
A6: 46308 | B6: BATIK AIR | C6: PK-LUG | D6: NSRDIL | E6: NBA032141 | F6: RE OPEN TO NSRDIL NID016227 | H6: HLP | I6: CLOSED
A7: 46308 | B7: BATIK AIR | C7: PK-LUP | D7: NSRDIL | E7: NID007366 | F7: WATER AND WASTE SYSTEM EROR | H7: HLP | I7: CLOSED
A8: 46308 | B8: BATIK AIR | C8: PK-BKF | D8: NSRDIL | E8: NID014243 | F8: DURING DAILY CHECK COVER TOILET AT LAV A FOUND CRACK | H8: CGK | I8: CLOSED
A9: 46308 | B9: BATIK AIR | C9: PK-LUG | D9: NSRDIL | E9: NID016225 | F9: PLACARD LAW STEATMENT AT 2F,3DF FOND MISSING | H9: HLP | I9: CLOSED
A10: 46307 | B10: LION AIR | C10: PK-LKQ | D10: NSRDIL | E10: NLA080275 | F10: PLEASE ADD SPARE SAFETY CARD AND PLACARD INOP | H10: UPG | I10: CLOSED
A11: 46307 | B11: LION AIR | C11: PK-LSO | D11: NSRDIL | E11: NLA085962 | F11: SPARE SAFETY CARD NEW REVISION NOT AVAILABLE | H11: UPG | I11: CLOSED
A12: 46308 | B12: LION AIR | C12: PK-LRI | D12: NSRDIL | E12: NLA094757 | F12: ONE OF O2 MASK FOR SAFETY DEMO WITH NO RESERVOIR BAG | H12: CGK | I12: CLOSED
A13: 46308 | B13: SUPER AIR JET | C13: PK-SJO | D13: NSRDIL | E13: NSAJ013064 | F13: ENTRY LIGHT AT AFT STATION ( 4R ) FOUND NOT ILLUMINATE | H13: CGK | I13: CLOSED
A14: 46308 | B14: SUPER AIR JET | C14: PK-SAO | D14: NSRDIL | E14: NSAJ021308 | F14: BEVERAGE MAKER AT G1 LOW WATER | H14: SUB | I14: CLOSED
A15: 46308 | B15: SUPER AIR JET | C15: PK-SAO | D15: NSRDIL | E15: NSAJ021310 | F15: SRV NO. 10234 DURING PERFORMED WO INTERIOR CABIN INSPECTION , ROLLER BLIND AT (AFT LH &RH) MISSING | H15: SUB | I15: CLOSED
A16: 46307 | B16: WINGS AIR | C16: PK-WJJ | D16: NSRDIL | E16: NWA 007750 | F16: HOT JUG NO.2 INOP | H16: UPG | I16: CLOSED
A17: 46307 | B17: WINGS AIR | C17: PK-WFU | D17: NSRDIL | E17: NWA008801 | F17: CONTROL COLUMN RUBBER GRIP CAPT SIDE (LH) AND FO SIDE (RH) MISSING. | H17: UPG | I17: CLOSED
A18: 46308 | B18: WINGS AIR | C18: PK-WFU | D18: NSRDIL | E18: NWA023500 | F18: ACCESS TO CARGO DOOR AT FWD IS LIKELY TO FALL WHENEVER IMPACT | H18: UPG | I18: CLOSED

Sheet UNPLANNED NSRDI
A1: REFRESH DATE | B1: WG | C1: AC REG | D1: NSRDI | E1: FINDING DESCRIPTION | F1: CATEGORY | G1: REPORT DATE | H1: DUE DATE | I1: PART NUMBER | J1: PART DESCRIPTION | K1: DEFER | L1: AOC | M1: TYPE | N1: PLAN STA | O1: PLAN DATE | P1: REMARKS | Q1: STATUS | R1: CLOSE DATE | S1: ACT STA | T1: REASON OPEN | U1: CODE OPEN
A2: 46296 | B2: WG 09 | C2: PK-SJZ | D2: NSAJ013298 | E2: ONE OF HANDLE PBE AT FWD STATION NOT AVAILABLE | F2: CBM | G2: 46227 | L2: IU | M2: A320 | N2: SOC | P2: REFF AMM 25-62-21 PERFOMED RECTIFIED ONE OF HANDLE PBE AT FWD STATION D/T NOT AVAILABLE HAS BEEN C/O, RESULT GOOD & SECURE | Q2: CLOSED | R2: 46296 | S2: SOC
A3: 46296 | C3: PK-SAW | D3: NSAJ006240 | E3: PLACARD LAW STATEMENT AT SEAT NO : 12ABC,DEF NOT AVAILABLE | F3: CBM | L3: IU | M3: A320 | N3: SUB | P3: PERFORMED INSTALL PLACARD LAW STATEMENT AT SEAT NO : 12ABC,DEF D/T NOT AVAILABLE | Q3: CLOSED | R3: 46296 | S3: SUB
A4: 46296 | C4: PK-LEU | D4: NLA090060 | E4: WATER HEATER FWD G1A NO.2 AND FWD GIF NO.2 CAN'T OPERATE AND WATER NOT HOT | F4: CBM | L4: JT | M4: A330 | N4: SUB | P4: PERFORMED REPLACED WATER HEATER FWD G1A NO.2 AND FWD GIF NO.2 D/T CAN'T OPERATE AND WATER NOT HOT , RESULT GOOD AND WATER HEATER G1F NO.1 ACTUAL ON GROUND NORMAL | Q4: CLOSED | R4: 46296 | S4: SUB
A5: 46296 | B5: WG 09 | C5: PK-STH | D5: NSAJ015475 | E5: EXTENSION SEAT BELT NOT MATCH WITH LOPA (-2EA) | F5: CBM | G5: 46273 | L5: IU | M5: A320 | N5: PLM | P5: I.A.W AMM ATA 25-21-00 PERFORM COMPLETED EXTENSION SEAT BELT DUE TO NOT MATCH WITH LOPA ( MINUS 2 EA ) | Q5: CLOSED | R5: 46296 | S5: PLM
A6: 46296 | B6: WG 09 | C6: PK-STH | D6: NSAJ015484 | E6: TOTAL QUANTITY OF EXTENSION SEAT BELT ON AIRCRAFT NOT MATCH ACCORDING TO THE LOPA 4EA ACTUAL 2EA | F6: CBM | G6: 46295 | L6: IU | M6: A320 | N6: PLM | P6: I.A.W AMM ATA 25-21-00 PERFORM COMPLETED EXTENSION SEAT BELT DUE TO NOT MATCH WITH LOPA ( MINUS 2 EA ) | Q6: CLOSED | R6: 46296 | S6: PLM
A7: O1-Oct-26 | C7: PK-LUG | D7: NLA016220 | E7: PLEASE ADDE PLACARD INOP | F7: CBM | L7: ID | M7: A320 | N7: UPG | P7: PERFORM ADDED PLACARD INOP AT BOOK CML QT,5EA | Q7: CLOSED | R7: 46296 | S7: UPG
A8: 46296 | C8: PK-WFS | D8: NWA026272 | E8: LOCK LATCH ASSY ACCES DOOR TO CARGO | F8: CBM | L8: IW | M8: ATR72 | N8: LOP | P8: PERFORMED RECTIFIED LOCK LATCH ASSY ACCES DOOR TO CARGO C/O OPS TEST RESULT GOOD | Q8: CLOSED | R8: 46296 | S8: LOP
A9: 46296 | C9: PK-WFS | D9: NWA008446 | E9: LOCK LATCH ASSY ACCES DOOR TO CARGO | F9: CBM | L9: IW | M9: ATR72 | N9: LOP | P9: PERFORMED RECTIFIED LOCK LATCH ASSY ACCES DOOR TO CARGO C/O OPS TEST RESULT GOOD | Q9: CLOSED | R9: 46296 | S9: LOP
A10: 46296 | C10: PK-WFS | D10: NWA026275 | E10: COVER BACKREST JUMPSEAT FA 1 BAD CONDITON | F10: CBM | L10: IW | M10: ATR72 | N10: LOP | P10: PERFORMED REPLACED COVER BACKREST JUMPSEAT FA 1 D/T BAD CONDITON C/O | Q10: CLOSED | R10: 46296 | S10: LOP
A11: 46296 | C11: PK-WGR | D11: NWA038896 | E11: CARGO NET AFT D/T BAD CONDITION ( DIRTY ) | F11: CBM | L11: IW | M11: ATR72 | N11: LOP | P11: PERFORMED CLEAN UP CARGO NET AFT D/T BAD CONDITION ( DIRTY ) HAS BEEN C/O | Q11: CLOSED | R11: 46296 | S11: LOP
A12: 46296 | C12: PK-LJI | D12: NLA081701 | E12: WINDOW SHUTER SEAT 20-21ABC D/T BAD CONDITION | F12: CBM | L12: JT | M12: B737NG | N12: LOP | P12: PERFORMED ADSJUSMENT AND CLEAN UP WINDOW SHUTER SEAT 20-21ABC D/T BAD CONDITION C/O RESULT GOOD AND NORMALY | Q12: CLOSED | R12: 46296 | S12: LOP
A13: 46296 | C13: PK-SAV | D13: NSAJ013166 | E13: BONDING CABLE AT RH & LH NLG D/T BROKEN | F13: CBM | L13: IU | M13: A320 | N13: LOP | P13: PERFORMED CHECK ACTUAL FOUND BONDING CABLE AT RH & LH NLG D/T BROKEN C/O RESULT NEWS AND GOOD CONDITION | Q13: CLOSED | R13: 46296 | S13: LOP
A14: 46296 | C14: PK-LFY | D14: NLA082613 | E14: PK-LSY SRV 12440 SEATER LE BAD CONDITION | F14: CBM | L14: JT | M14: B739 | P14: PERFORMED REPLACED SEATER LAVATORY LE D/T BAD CONDITION | Q14: CLOSED | R14: 46296 | S14: CGK
A15: 46296 | C15: PK-LOJ | D15: NLA084116 | E15: PERFROMED RECTIFIED SPRING AT LATCH COMPARTMENT NO406 AFT GALLEY DUE TO CANT LOCK HAS BEEN DONE | F15: CBM | L15: JT | M15: B738 | P15: PERFORMED RECTIFIED SPRING AT LATCH COMPARTMENT NO 406 AFT GALLEY D/T CANT LOCK | Q15: CLOSED | R15: 46296 | S15: CGK
A16: 46296 | C16: PK-SJT | D16: NSAJ017107 | E16: REFF TO NSDRIL NSAJ017106 LATCH WASTE COMPARTMENT AT G1 MISSING | F16: CBM | L16: IU | M16: A320 | P16: REOPEN TO PAGE NO NSAJ017142 | Q16: CLOSED | R16: 46296 | S16: CGK
A17: 46296 | C17: PK-SAS | D17: NSAJ007109 | E17: REF FINDING ICT 18258AND 18259 SEATER TOILET LAV AT LD LE FOUND CRACK | F17: CBM | L17: IU | M17: A320 | P17: PERFORMED REPLACED SEATER LAVATORY LD,LE DUE TO CRACK. RESULT GOOD CONDITION | Q17: CLOSED | R17: 46296 | S17: CGK
A18: 46296 | C18: PK-SAO | D18: NSAJ021351 | E18: OXYGEN MASK FOR DEMO KIT AT FWD CABIN FOUND BAD CONDITION | F18: CBM | L18: IU | M18: A320 | P18: PERFORMED REPLACED OXYGEN MASK FOR DEMO KIT AT FWD CABIN DUE TO BAD CONDITION. RESULT GOOD CONDITION | Q18: CLOSED | R18: 46296 | S18: CGK
A19: 46296 | C19: PK-SJI | D19: NSAJ037458 | E19: PERFORMED COMPLATED VACANT OCCUPIED SING AT LAVATORY LD HAS BEEN CLOSED RESULT GOOD | F19: CBM | L19: IU | M19: A320 | P19: PERFORMED REPLACED COVER ESCUTCHION VACANT/OCCUPIED AT LAVATORY LD | Q19: CLOSED | R19: 46296 | S19: CGK
A20: 46296 | C20: PK-WFT | D20: NWA 006459 | E20: REFF FINDING ICT NO. 15010 : HYD ACCUMULATOR SIGHT GLASS FOUND BLUR. | F20: CBM | L20: IW | M20: ATR72 | P20: REF AMM:25-00-00 RE OPEN NSRDIL NWA006478 HYD ACCUMULATOR SIGHT GLASS FOUND BLUR | Q20: CLOSED | R20: 46296 | S20: KNO
A21: 46297 | B21: WG 08 | C21: PK-SGC | D21: NSAJ008176 | E21: DURING DAILY CHECK AIRFI AT AFT STATION NOT AVAILABLE | F21: CBM | I21: DSD.IU.999.0819 | J21: AIRFI BOX FOR SUPER AIR JET | L21: IU | M21: A320 | N21: SOC | P21: PERFORMED COMPLETED AIRFI BOX AT AFT STATION HAS BEEN CARRIED OUT | Q21: CLOSED | R21: 46297 | S21: SOC
A22: 46297 | B22: WG 07 | C22: PK-LAO | D22: NBA047692 | E22: CARPET BATIFLEX AT LAV A & LAV E BAD CONDITION | F22: CBM | I22: 497B6490 | J22: CARPET BATIFLEX | L22: ID | M22: A320 | N22: SOC | P22: REOPEN TO NSRDI NID012356 | Q22: CLOSED | R22: 46297 | S22: SOC
A23: 46297 | B23: WG 07 | C23: PK-LAO | D23: NBA047695 | E23: PEEL OFF ON VERSTAB AND FUSELAGE (NEED PAINTING) | F23: CBM | L23: ID | M23: A320 | N23: SOC | P23: REOPEN TO NSRDI NID012357 | Q23: CLOSED | R23: 46297 | S23: SOC
A24: 46297 | B24: WG 07 | C24: PK-LAO | D24: NID012351 | E24: PLACARD CREW L/V FO FOUND MISSING | F24: CBM | I24: LT11-11-PLC-0078 | J24: PLACARD CREW LIFE VEST | L24: ID | M24: A320 | N24: SOC | P24: PERFORMED INSTALL PLACARD CREW LIFE VEST FO HAS BEEN CARRIED OUT | Q24: CLOSED | R24: 46297 | S24: SOC
A25: 46297 | C25: PK-LUP | D25: NID007357 | E25: 1 RED TAB LIFE VEST DEMO KIT NOT AVAIL | F25: CBM | L25: ID | M25: A320 | N25: HLP | P25: PERFORMED REPLACED DEMO LIFE VEST AT AFT HAS BEEN C/O | Q25: CLOSED | R25: 46297 | S25: HLP
A26: 46297 | B26: WG10 | C26: PK-WGH | D26: NWA023013 | E26: MIRROR AT LAVATORY FOUND BAD CONDITION | F26: CBM | L26: IW | M26: ATR72 | N26: AMQ | P26: PERFORMED REOPEN TO NSRDI PAGE NO.NWA023029 | Q26: CLOSED | R26: 46297 | S26: AMQ
A27: 46297 | B27: WG10 | C27: PK-WGH | D27: NWA023019 | E27: LATCH LOCK-UNLOCK LAVATORY DOOR IS MISSING AND HARD TO CLOSING AND OPENING THE DOOR | F27: CBM | G27: 46194 | L27: IW | M27: ATR72 | N27: AMQ | P27: PERFORMED RECTIFICATION LATCH LOCK-UNLOCK AND TRACK LAVATORY DOOR ,HAS BEEN C/O | Q27: CLOSED | R27: 46297 | S27: AMQ
A28: 46297 | B28: WG10 | C28: PK-WGH | D28: NWA023020 | E28: SMOKE BARIER CUTAIN VELCRO IN BAD CONDITION | F28: CBM | G28: 46194 | L28: IW | M28: ATR72 | N28: AMQ | P28: PERFORMED REPLACE VELCRO CURTAIN ANTI SMOKE D/T BAD CONDITION, HAS BEEN C/O | Q28: CLOSED | R28: 46297 | S28: AMQ
A29: 46297 | C29: PK-WFK | D29: NWA003363 | E29: HEADRACK SEAT NO. 10AC IS BROKEN | F29: CBM | L29: IW | M29: ATR72 | N29: UPG | P29: TRANSFER TO NSRDI NO NWA003381 | Q29: CLOSED | R29: 46297 | S29: =_xludf.IFNA(IFS(COUNTIFS('[1]List AC'!$A:$A,$C29)>0,'[1]List AC'!$A$2,COUNTIFS('[1]List AC'!$B:$B,$C29)>0,'[1]List AC'!$B$2,COUNTIFS('[1]List AC'!$C:$C,$C29)>0,'[1]List AC'!$C$2,COUNTIFS('[1]List AC'!$D:$D,$C29)>0,'[1]List AC'!$D$2,COUNTIFS('[1]List AC'!$E:$E,$C29)>0,'[1]List AC'!$E$2,COUNTIFS('[1]List AC'!$F:$F,$C29)>0,'[1]List AC'!$F$2,COUNTIFS('[1]List AC'!$G:$G,$C29)>0,'[1]List AC'!$G$2,COUNTIFS('[1]List AC'!$H:$H,$C29)>0,'[1]List AC'!$H$2,COUNTIFS('[1]List AC'!$I:$I,$C29)>0,'[1]List AC'!$I$2,COUNTIFS('[1]List AC'!$J:$J,$C29)>0,'[1]List AC'!$J$2,COUNTIFS('[1]List AC'!$K:$K,$C29)>0,'[1]List AC'!$K$2,COUNTIFS('[1]List AC'!$L:$L,$C29)>0,'[1]List AC'!$L$2,COUNTIFS('[1]List AC'!$Q:$Q,$C29)>0,'[1]List AC'!$Q$2,COUNTIFS('[1]List AC'!$M:$M,$C29)>0,'[1]List AC'!$M$2,COUNTIFS('[1]List AC'!$N:$N,$C29)>0,'[1]List AC'!$N$2,COUNTIFS('[1]List AC'!$O:$O,$C29)>0,'[1]List AC'!$O$2,COUNTIFS('[1]List AC'!$P:$P,$C29)>0,'[1]List AC'!$P$2,COUNTIFS('[1]List AC'!$R:$R,$C29)>0,'[1]List AC'!$R$2,COUNTIFS('[1]List AC'!$S:$S,$C29)>0,'[1]List AC'!$S$2,COUNTIFS('[1]List AC'!$T:$T,$C29)>0,'[1]List AC'!$T$2,COUNTIFS('[1]List AC'!$U:$U,$C29)>0,'[1]List AC'!$U$2,COUNTIFS('[1]List AC'!$V:$V,$C29)>0,'[1]List AC'!$V$2,COUNTIFS('[1]List AC'!$W:$W,$C29)>0,'[1]List AC'!$W$2,COUNTIFS('[1]List AC'!$X:$X,$C29)>0,'[1]List AC'!$X$2,COUNTIFS('[1]List AC'!$Y:$Y,$C29)>0,'[1]List AC'!$Y$2,COUNTIFS('[1]List AC'!$Z:$Z,$C29)>0,'[1]List AC'!$Z$2,COUNTIFS('[1]List AC'!$AA:$AA,$C29)>0,'[1]List AC'!$AA$2,COUNTIFS('[1]List AC'!$AB:$AB,$C29)>0,'[1]List AC'!$AB$2,COUNTIFS('[1]List AC'!$AC:$AC,$C29)>0,'[1]List AC'!$AC$2,COUNTIFS('[1]List AC'!$AD:$AD,$C29)>0,'[1]List AC'!$AD$2,COUNTIFS('[1]List AC'!$AE:$AE,$C29)>0,'[1]List AC'!$AE$2,COUNTIFS('[1]List AC'!$AF:$AF,$C29)>0,'[1]List AC'!$AF$2,COUNTIFS('[1]List AC'!$AG:$AG,$C29)>0,'[1]List AC'!$AG$2,COUNTIFS('[1]List AC'!$AH:$AH,$C29)>0,'[1]List AC'!$AH$2,COUNTIFS('[1]List AC'!$AI:$AI,$C29)>0,'[1]List AC'!$AI$2,COUNTIFS('[1]List AC'!$AJ:$AJ,$C29)>0,'[1]List AC'!$AJ$2,COUNTIFS('[1]List AC'!$AK:$AK,$C29)>0,'[1]List AC'!$AK$2,COUNTIFS('[1]List AC'!$AL:$AL,$C29)>0,'[1]List AC'!$AL$2,COUNTIFS('[1]List AC'!$AM:$AM,$C29)>0,'[1]List AC'!$AM$2,COUNTIFS('[1]List AC'!$AN:$AN,$C29)>0,'[1]List AC'!$AN$2,COUNTIFS('[1]List AC'!$AO:$AO,$C29)>0,'[1]List AC'!$AO$2,COUNTIFS('[1]List AC'!$AP:$AP,$C29)>0,'[1]List AC'!$AP$2,COUNTIFS('[1]List AC'!$AQ:$AQ,$C29)>0,'[1]List AC'!$AQ$2,COUNTIFS('[1]List AC'!$AR:$AR,$C29)>0,'[1]List AC'!$AR$2,COUNTIFS('[1]List AC'!$AS:$AS,$C29)>0,'[1]List AC'!$AS$2,COUNTIFS('[1]List AC'!$AT:$AT,$C29)>0,'[1]List AC'!$AT$2,COUNTIFS('[1]List AC'!$AU:$AU,$C29)>0,'[1]List AC'!$AU$2,COUNTIFS('[1]List AC'!$AV:$AV,$C29)>0,'[1]List AC'!$AV$2,COUNTIFS('[1]List AC'!$AW:$AW,$C29)>0,'[1]List AC'!$AW$2,COUNTIFS('[1]List AC'!$AX:$AX,$C29)>0,'[1]List AC'!$AX$2,COUNTIFS('[1]List AC'!$AY:$AY,$C29)>0,'[1]List AC'!$AY$2,COUNTIFS('[1]List AC'!$AZ:$AZ,$C29)>0,'[1]List AC'!$AZ$2,COUNTIFS('[1]List AC'!$BA:$BA,$C29)>0,'[1]List AC'!$BA$2,COUNTIFS('[1]List AC'!$BB:$BB,$C29)>0,'[1]List AC'!$BB$2,COUNTIFS('[1]List AC'!$BC:$BC,$C29)>0,'[1]List AC'!$BC$2,COUNTIFS('[1]List AC'!$BD:$BD,$C29)>0,'[1]List AC'!$BD$2),"") -> #NAME?
A30: 46297 | C30: PK-LET | D30: NLA089304 | E30: PART OF FA SEAT IR N 1L BROKEN | F30: CBM | L30: JT | M30: A330 | N30: UPG | P30: PERFORM REPAIR PART OF FA SEAT IR N 1L HAS BEEN DONE | Q30: CLOSED | R30: 46297 | S30: =_xludf.IFNA(IFS(COUNTIFS('[1]List AC'!$A:$A,$C30)>0,'[1]List AC'!$A$2,COUNTIFS('[1]List AC'!$B:$B,$C30)>0,'[1]List AC'!$B$2,COUNTIFS('[1]List AC'!$C:$C,$C30)>0,'[1]List AC'!$C$2,COUNTIFS('[1]List AC'!$D:$D,$C30)>0,'[1]List AC'!$D$2,COUNTIFS('[1]List AC'!$E:$E,$C30)>0,'[1]List AC'!$E$2,COUNTIFS('[1]List AC'!$F:$F,$C30)>0,'[1]List AC'!$F$2,COUNTIFS('[1]List AC'!$G:$G,$C30)>0,'[1]List AC'!$G$2,COUNTIFS('[1]List AC'!$H:$H,$C30)>0,'[1]List AC'!$H$2,COUNTIFS('[1]List AC'!$I:$I,$C30)>0,'[1]List AC'!$I$2,COUNTIFS('[1]List AC'!$J:$J,$C30)>0,'[1]List AC'!$J$2,COUNTIFS('[1]List AC'!$K:$K,$C30)>0,'[1]List AC'!$K$2,COUNTIFS('[1]List AC'!$L:$L,$C30)>0,'[1]List AC'!$L$2,COUNTIFS('[1]List AC'!$Q:$Q,$C30)>0,'[1]List AC'!$Q$2,COUNTIFS('[1]List AC'!$M:$M,$C30)>0,'[1]List AC'!$M$2,COUNTIFS('[1]List AC'!$N:$N,$C30)>0,'[1]List AC'!$N$2,COUNTIFS('[1]List AC'!$O:$O,$C30)>0,'[1]List AC'!$O$2,COUNTIFS('[1]List AC'!$P:$P,$C30)>0,'[1]List AC'!$P$2,COUNTIFS('[1]List AC'!$R:$R,$C30)>0,'[1]List AC'!$R$2,COUNTIFS('[1]List AC'!$S:$S,$C30)>0,'[1]List AC'!$S$2,COUNTIFS('[1]List AC'!$T:$T,$C30)>0,'[1]List AC'!$T$2,COUNTIFS('[1]List AC'!$U:$U,$C30)>0,'[1]List AC'!$U$2,COUNTIFS('[1]List AC'!$V:$V,$C30)>0,'[1]List AC'!$V$2,COUNTIFS('[1]List AC'!$W:$W,$C30)>0,'[1]List AC'!$W$2,COUNTIFS('[1]List AC'!$X:$X,$C30)>0,'[1]List AC'!$X$2,COUNTIFS('[1]List AC'!$Y:$Y,$C30)>0,'[1]List AC'!$Y$2,COUNTIFS('[1]List AC'!$Z:$Z,$C30)>0,'[1]List AC'!$Z$2,COUNTIFS('[1]List AC'!$AA:$AA,$C30)>0,'[1]List AC'!$AA$2,COUNTIFS('[1]List AC'!$AB:$AB,$C30)>0,'[1]List AC'!$AB$2,COUNTIFS('[1]List AC'!$AC:$AC,$C30)>0,'[1]List AC'!$AC$2,COUNTIFS('[1]List AC'!$AD:$AD,$C30)>0,'[1]List AC'!$AD$2,COUNTIFS('[1]List AC'!$AE:$AE,$C30)>0,'[1]List AC'!$AE$2,COUNTIFS('[1]List AC'!$AF:$AF,$C30)>0,'[1]List AC'!$AF$2,COUNTIFS('[1]List AC'!$AG:$AG,$C30)>0,'[1]List AC'!$AG$2,COUNTIFS('[1]List AC'!$AH:$AH,$C30)>0,'[1]List AC'!$AH$2,COUNTIFS('[1]List AC'!$AI:$AI,$C30)>0,'[1]List AC'!$AI$2,COUNTIFS('[1]List AC'!$AJ:$AJ,$C30)>0,'[1]List AC'!$AJ$2,COUNTIFS('[1]List AC'!$AK:$AK,$C30)>0,'[1]List AC'!$AK$2,COUNTIFS('[1]List AC'!$AL:$AL,$C30)>0,'[1]List AC'!$AL$2,COUNTIFS('[1]List AC'!$AM:$AM,$C30)>0,'[1]List AC'!$AM$2,COUNTIFS('[1]List AC'!$AN:$AN,$C30)>0,'[1]List AC'!$AN$2,COUNTIFS('[1]List AC'!$AO:$AO,$C30)>0,'[1]List AC'!$AO$2,COUNTIFS('[1]List AC'!$AP:$AP,$C30)>0,'[1]List AC'!$AP$2,COUNTIFS('[1]List AC'!$AQ:$AQ,$C30)>0,'[1]List AC'!$AQ$2,COUNTIFS('[1]List AC'!$AR:$AR,$C30)>0,'[1]List AC'!$AR$2,COUNTIFS('[1]List AC'!$AS:$AS,$C30)>0,'[1]List AC'!$AS$2,COUNTIFS('[1]List AC'!$AT:$AT,$C30)>0,'[1]List AC'!$AT$2,COUNTIFS('[1]List AC'!$AU:$AU,$C30)>0,'[1]List AC'!$AU$2,COUNTIFS('[1]List AC'!$AV:$AV,$C30)>0,'[1]List AC'!$AV$2,COUNTIFS('[1]List AC'!$AW:$AW,$C30)>0,'[1]List AC'!$AW$2,COUNTIFS('[1]List AC'!$AX:$AX,$C30)>0,'[1]List AC'!$AX$2,COUNTIFS('[1]List AC'!$AY:$AY,$C30)>0,'[1]List AC'!$AY$2,COUNTIFS('[1]List AC'!$AZ:$AZ,$C30)>0,'[1]List AC'!$AZ$2,COUNTIFS('[1]List AC'!$BA:$BA,$C30)>0,'[1]List AC'!$BA$2,COUNTIFS('[1]List AC'!$BB:$BB,$C30)>0,'[1]List AC'!$BB$2,COUNTIFS('[1]List AC'!$BC:$BC,$C30)>0,'[1]List AC'!$BC$2,COUNTIFS('[1]List AC'!$BD:$BD,$C30)>0,'[1]List AC'!$BD$2),"") -> #NAME?
A31: 46297 | B31: WG 03 | C31: PK-LQY | D31: NLA084197 | E31: FAUCET LAVATORY LD CONT FLOW | F31: CBM | L31: JT | M31: B737 | N31: UPG | P31: PERFORM RECTIFICATION FAUCET LAVATORY LD C/O, OPS TEST RESULT GOOD | Q31: CLOSED | R31: 46297 | S31: =_xludf.IFNA(IFS(COUNTIFS('[1]List AC'!$A:$A,$C31)>0,'[1]List AC'!$A$2,COUNTIFS('[1]List AC'!$B:$B,$C31)>0,'[1]List AC'!$B$2,COUNTIFS('[1]List AC'!$C:$C,$C31)>0,'[1]List AC'!$C$2,COUNTIFS('[1]List AC'!$D:$D,$C31)>0,'[1]List AC'!$D$2,COUNTIFS('[1]List AC'!$E:$E,$C31)>0,'[1]List AC'!$E$2,COUNTIFS('[1]List AC'!$F:$F,$C31)>0,'[1]List AC'!$F$2,COUNTIFS('[1]List AC'!$G:$G,$C31)>0,'[1]List AC'!$G$2,COUNTIFS('[1]List AC'!$H:$H,$C31)>0,'[1]List AC'!$H$2,COUNTIFS('[1]List AC'!$I:$I,$C31)>0,'[1]List AC'!$I$2,COUNTIFS('[1]List AC'!$J:$J,$C31)>0,'[1]List AC'!$J$2,COUNTIFS('[1]List AC'!$K:$K,$C31)>0,'[1]List AC'!$K$2,COUNTIFS('[1]List AC'!$L:$L,$C31)>0,'[1]List AC'!$L$2,COUNTIFS('[1]List AC'!$Q:$Q,$C31)>0,'[1]List AC'!$Q$2,COUNTIFS('[1]List AC'!$M:$M,$C31)>0,'[1]List AC'!$M$2,COUNTIFS('[1]List AC'!$N:$N,$C31)>0,'[1]List AC'!$N$2,COUNTIFS('[1]List AC'!$O:$O,$C31)>0,'[1]List AC'!$O$2,COUNTIFS('[1]List AC'!$P:$P,$C31)>0,'[1]List AC'!$P$2,COUNTIFS('[1]List AC'!$R:$R,$C31)>0,'[1]List AC'!$R$2,COUNTIFS('[1]List AC'!$S:$S,$C31)>0,'[1]List AC'!$S$2,COUNTIFS('[1]List AC'!$T:$T,$C31)>0,'[1]List AC'!$T$2,COUNTIFS('[1]List AC'!$U:$U,$C31)>0,'[1]List AC'!$U$2,COUNTIFS('[1]List AC'!$V:$V,$C31)>0,'[1]List AC'!$V$2,COUNTIFS('[1]List AC'!$W:$W,$C31)>0,'[1]List AC'!$W$2,COUNTIFS('[1]List AC'!$X:$X,$C31)>0,'[1]List AC'!$X$2,COUNTIFS('[1]List AC'!$Y:$Y,$C31)>0,'[1]List AC'!$Y$2,COUNTIFS('[1]List AC'!$Z:$Z,$C31)>0,'[1]List AC'!$Z$2,COUNTIFS('[1]List AC'!$AA:$AA,$C31)>0,'[1]List AC'!$AA$2,COUNTIFS('[1]List AC'!$AB:$AB,$C31)>0,'[1]List AC'!$AB$2,COUNTIFS('[1]List AC'!$AC:$AC,$C31)>0,'[1]List AC'!$AC$2,COUNTIFS('[1]List AC'!$AD:$AD,$C31)>0,'[1]List AC'!$AD$2,COUNTIFS('[1]List AC'!$AE:$AE,$C31)>0,'[1]List AC'!$AE$2,COUNTIFS('[1]List AC'!$AF:$AF,$C31)>0,'[1]List AC'!$AF$2,COUNTIFS('[1]List AC'!$AG:$AG,$C31)>0,'[1]List AC'!$AG$2,COUNTIFS('[1]List AC'!$AH:$AH,$C31)>0,'[1]List AC'!$AH$2,COUNTIFS('[1]List AC'!$AI:$AI,$C31)>0,'[1]List AC'!$AI$2,COUNTIFS('[1]List AC'!$AJ:$AJ,$C31)>0,'[1]List AC'!$AJ$2,COUNTIFS('[1]List AC'!$AK:$AK,$C31)>0,'[1]List AC'!$AK$2,COUNTIFS('[1]List AC'!$AL:$AL,$C31)>0,'[1]List AC'!$AL$2,COUNTIFS('[1]List AC'!$AM:$AM,$C31)>0,'[1]List AC'!$AM$2,COUNTIFS('[1]List AC'!$AN:$AN,$C31)>0,'[1]List AC'!$AN$2,COUNTIFS('[1]List AC'!$AO:$AO,$C31)>0,'[1]List AC'!$AO$2,COUNTIFS('[1]List AC'!$AP:$AP,$C31)>0,'[1]List AC'!$AP$2,COUNTIFS('[1]List AC'!$AQ:$AQ,$C31)>0,'[1]List AC'!$AQ$2,COUNTIFS('[1]List AC'!$AR:$AR,$C31)>0,'[1]List AC'!$AR$2,COUNTIFS('[1]List AC'!$AS:$AS,$C31)>0,'[1]List AC'!$AS$2,COUNTIFS('[1]List AC'!$AT:$AT,$C31)>0,'[1]List AC'!$AT$2,COUNTIFS('[1]List AC'!$AU:$AU,$C31)>0,'[1]List AC'!$AU$2,COUNTIFS('[1]List AC'!$AV:$AV,$C31)>0,'[1]List AC'!$AV$2,COUNTIFS('[1]List AC'!$AW:$AW,$C31)>0,'[1]List AC'!$AW$2,COUNTIFS('[1]List AC'!$AX:$AX,$C31)>0,'[1]List AC'!$AX$2,COUNTIFS('[1]List AC'!$AY:$AY,$C31)>0,'[1]List AC'!$AY$2,COUNTIFS('[1]List AC'!$AZ:$AZ,$C31)>0,'[1]List AC'!$AZ$2,COUNTIFS('[1]List AC'!$BA:$BA,$C31)>0,'[1]List AC'!$BA$2,COUNTIFS('[1]List AC'!$BB:$BB,$C31)>0,'[1]List AC'!$BB$2,COUNTIFS('[1]List AC'!$BC:$BC,$C31)>0,'[1]List AC'!$BC$2,COUNTIFS('[1]List AC'!$BD:$BD,$C31)>0,'[1]List AC'!$BD$2),"") -> #NAME?
A32: 46297 | C32: PK-SJD | D32: NSAJ022632 | E32: CAUTION ON FAP DRAINMAST FAIL, CHECK WASTE WATER OVER FLOW AFT | F32: CBM | L32: IU | M32: A320 | N32: SUB | P32: PERFORM THE CIDS 1 TEST DRAINMAST SYSTEM RESULT TEST NO FAULTS AND DRAINMAST SYSTEM OK | Q32: CLOSED | R32: 46297 | S32: SUB
A33: 46297 | C33: PK-WGP | D33: NWA020862 | E33: SEAT NO. 9F,17C AND 19C ALWAYS RECLINE. | F33: CBM | L33: IW | M33: ATR72 | N33: LOP | P33: AFTER ADJUSTMENT JACK RECLINE SEAT NO. 9F,17C,19C STILL ALWAYS RECLINE, TRANSFERRED TO NSRDI NO: NWA020869 | Q33: CLOSED | R33: 46297 | S33: LOP
A34: 46297 | C34: PK-WGP | D34: NWA020866 | E34: FOUND TRAYTABLE SEAT NO 6C BROKEN | F34: CBM | L34: IW | M34: ATR72 | N34: LOP | P34: AFTER ADJUSTMENT JACK RECLINE SEAT NO. 1C STILL ALWAYS RECLINE, TRANSFERRED TO NSRDI NO: NWA020869 | Q34: CLOSED | R34: 46297 | S34: LOP
A35: 46297 | C35: PK-LQZ | D35: NLA083796 | E35: LAMP MIRROR LIGHT LAVATORY LD NOT ILL | F35: CBM | L35: JT | M35: B737 | N35: UPG | P35: PERFORM CHECK REPOSITION TUBE LAMP MIRROR LIGHT LAVATORY LD IS DONE RESULT GOOD | Q35: CLOSED | R35: 46297 | S35: =_xludf.IFNA(IFS(COUNTIFS('[1]List AC'!$A:$A,$C35)>0,'[1]List AC'!$A$2,COUNTIFS('[1]List AC'!$B:$B,$C35)>0,'[1]List AC'!$B$2,COUNTIFS('[1]List AC'!$C:$C,$C35)>0,'[1]List AC'!$C$2,COUNTIFS('[1]List AC'!$D:$D,$C35)>0,'[1]List AC'!$D$2,COUNTIFS('[1]List AC'!$E:$E,$C35)>0,'[1]List AC'!$E$2,COUNTIFS('[1]List AC'!$F:$F,$C35)>0,'[1]List AC'!$F$2,COUNTIFS('[1]List AC'!$G:$G,$C35)>0,'[1]List AC'!$G$2,COUNTIFS('[1]List AC'!$H:$H,$C35)>0,'[1]List AC'!$H$2,COUNTIFS('[1]List AC'!$I:$I,$C35)>0,'[1]List AC'!$I$2,COUNTIFS('[1]List AC'!$J:$J,$C35)>0,'[1]List AC'!$J$2,COUNTIFS('[1]List AC'!$K:$K,$C35)>0,'[1]List AC'!$K$2,COUNTIFS('[1]List AC'!$L:$L,$C35)>0,'[1]List AC'!$L$2,COUNTIFS('[1]List AC'!$Q:$Q,$C35)>0,'[1]List AC'!$Q$2,COUNTIFS('[1]List AC'!$M:$M,$C35)>0,'[1]List AC'!$M$2,COUNTIFS('[1]List AC'!$N:$N,$C35)>0,'[1]List AC'!$N$2,COUNTIFS('[1]List AC'!$O:$O,$C35)>0,'[1]List AC'!$O$2,COUNTIFS('[1]List AC'!$P:$P,$C35)>0,'[1]List AC'!$P$2,COUNTIFS('[1]List AC'!$R:$R,$C35)>0,'[1]List AC'!$R$2,COUNTIFS('[1]List AC'!$S:$S,$C35)>0,'[1]List AC'!$S$2,COUNTIFS('[1]List AC'!$T:$T,$C35)>0,'[1]List AC'!$T$2,COUNTIFS('[1]List AC'!$U:$U,$C35)>0,'[1]List AC'!$U$2,COUNTIFS('[1]List AC'!$V:$V,$C35)>0,'[1]List AC'!$V$2,COUNTIFS('[1]List AC'!$W:$W,$C35)>0,'[1]List AC'!$W$2,COUNTIFS('[1]List AC'!$X:$X,$C35)>0,'[1]List AC'!$X$2,COUNTIFS('[1]List AC'!$Y:$Y,$C35)>0,'[1]List AC'!$Y$2,COUNTIFS('[1]List AC'!$Z:$Z,$C35)>0,'[1]List AC'!$Z$2,COUNTIFS('[1]List AC'!$AA:$AA,$C35)>0,'[1]List AC'!$AA$2,COUNTIFS('[1]List AC'!$AB:$AB,$C35)>0,'[1]List AC'!$AB$2,COUNTIFS('[1]List AC'!$AC:$AC,$C35)>0,'[1]List AC'!$AC$2,COUNTIFS('[1]List AC'!$AD:$AD,$C35)>0,'[1]List AC'!$AD$2,COUNTIFS('[1]List AC'!$AE:$AE,$C35)>0,'[1]List AC'!$AE$2,COUNTIFS('[1]List AC'!$AF:$AF,$C35)>0,'[1]List AC'!$AF$2,COUNTIFS('[1]List AC'!$AG:$AG,$C35)>0,'[1]List AC'!$AG$2,COUNTIFS('[1]List AC'!$AH:$AH,$C35)>0,'[1]List AC'!$AH$2,COUNTIFS('[1]List AC'!$AI:$AI,$C35)>0,'[1]List AC'!$AI$2,COUNTIFS('[1]List AC'!$AJ:$AJ,$C35)>0,'[1]List AC'!$AJ$2,COUNTIFS('[1]List AC'!$AK:$AK,$C35)>0,'[1]List AC'!$AK$2,COUNTIFS('[1]List AC'!$AL:$AL,$C35)>0,'[1]List AC'!$AL$2,COUNTIFS('[1]List AC'!$AM:$AM,$C35)>0,'[1]List AC'!$AM$2,COUNTIFS('[1]List AC'!$AN:$AN,$C35)>0,'[1]List AC'!$AN$2,COUNTIFS('[1]List AC'!$AO:$AO,$C35)>0,'[1]List AC'!$AO$2,COUNTIFS('[1]List AC'!$AP:$AP,$C35)>0,'[1]List AC'!$AP$2,COUNTIFS('[1]List AC'!$AQ:$AQ,$C35)>0,'[1]List AC'!$AQ$2,COUNTIFS('[1]List AC'!$AR:$AR,$C35)>0,'[1]List AC'!$AR$2,COUNTIFS('[1]List AC'!$AS:$AS,$C35)>0,'[1]List AC'!$AS$2,COUNTIFS('[1]List AC'!$AT:$AT,$C35)>0,'[1]List AC'!$AT$2,COUNTIFS('[1]List AC'!$AU:$AU,$C35)>0,'[1]List AC'!$AU$2,COUNTIFS('[1]List AC'!$AV:$AV,$C35)>0,'[1]List AC'!$AV$2,COUNTIFS('[1]List AC'!$AW:$AW,$C35)>0,'[1]List AC'!$AW$2,COUNTIFS('[1]List AC'!$AX:$AX,$C35)>0,'[1]List AC'!$AX$2,COUNTIFS('[1]List AC'!$AY:$AY,$C35)>0,'[1]List AC'!$AY$2,COUNTIFS('[1]List AC'!$AZ:$AZ,$C35)>0,'[1]List AC'!$AZ$2,COUNTIFS('[1]List AC'!$BA:$BA,$C35)>0,'[1]List AC'!$BA$2,COUNTIFS('[1]List AC'!$BB:$BB,$C35)>0,'[1]List AC'!$BB$2,COUNTIFS('[1]List AC'!$BC:$BC,$C35)>0,'[1]List AC'!$BC$2,COUNTIFS('[1]List AC'!$BD:$BD,$C35)>0,'[1]List AC'!$BD$2),"") -> #NAME?
A36: 46297 | C36: PK-LSK | D36: NLA075933 | E36: REF NSRDI NLA075933 PLEASE ADD SAFETY CARD DUE TO SPARE. PERFORMED COMPLETED SAFETY CARD QTY: 20EA FOR SPARE. C/O | F36: CBM | L36: JT | M36: B737 | N36: SUB | P36: REF NSRDI NLA075933 PLEASE ADD SAFETY CARD DUE TO SPARE. PERFORMED COMPLETED SAFETY CARD QTY: 20EA FOR SPARE. C/O | Q36: CLOSED | R36: 46297 | S36: SUB
A37: 46297 | C37: PK-LOI | D37: NLA071337 | E37: PERFORM RECTIFIED FAUCET LAVATORY LA, RESULT TEST GOOD NOT LEAKING | F37: CBM | L37: JT | M37: B737 | N37: SUB | P37: PERFORM RECTIFIED FAUCET LAVATORY LA, RESULT TEST GOOD NOT LEAKING | Q37: CLOSED | R37: 46297 | S37: SUB
A38: 46297 | C38: PK-SJH | D38: NSAJ013397 | E38: PERFORMED INSTALL PLACARD AT ENG #1 LH SIDE DUE TO MISSING | F38: CBM | L38: IU | M38: A320 | N38: SUB | P38: PERFORMED INSTALL PLACARD AT ENG #1 LH SIDE DUE TO MISSING | Q38: CLOSED | R38: 46297 | S38: SUB
A39: 46297 | C39: PK-LDK | D39: NID008309 | E39: PERFORMED REPLACEMENT SEAT BELT PAX NO.15ABC. DUE TO TORN. HASBEEN DONE | F39: CBM | L39: ID | M39: B738 | P39: PERFORMED REPLACEMENT SEAT BELT NO 15ABC D/T TORN ,RESULT GOOD | Q39: CLOSED | R39: 46297 | S39: CGK
A40: 46297 | C40: PK-BKT | D40: NBA032840 | E40: COVER PRESSURE GAUGE SLIDERAFT AT DOOR 4R IS MISSING | F40: CBM | L40: ID | M40: A320 | P40: REOPEN TO NSRDI NO NBA032843 | Q40: CLOSED | R40: 46297 | S40: CGK
...

Sheet DAILY REPORT
A1: DATE | B1: OPERATOR | C1: A/C TYPE | D1: A/C REG | E1: A/C Status | F1: STA | G1: SHIFT | H1: TASK TYPE | I1: DOC TYPE | J1: STATUS | K1: NO.DOC | L1: ACTION TAKEN / REASON | M1: START PERFORM | N1: FINISH PERFORM | O1: MP 1 | P1: MP 2 | Q1: MP 3 | R1: MP 4 | S1: MP 5 | T1: Total MP | U1: Individual MHRS | V1: Actual MHRS
A2: 46307 | B2: WINGS AIR | C2: ATR-72 | D2: PK-WHS | E2: RON | F2: KOE | G2: MALAM | H2: DBI | I2: CML | J2: CLOSED | K2: C036366 | L2: BEAUTIFICATION INSPECTION DAILY HAS BEEN PERFORMED | M2: 17.4 | N2: 18.4 | O2: TERA KANAF | P2: HAMSAH RIADI
A3: 46307 | B3: WINGS AIR | C3: ATR-72 | D3: PK-WHS | E3: RON | F3: KOE | G3: MALAM | H3: DBI | I3: CML | J3: CLOSED | K3: C036367 | L3: PERFORMED RECTIFICATION COVER SIDE SEAT 1C D/T BAD CONDITION,RESULT GOOD | M3: 18.5 | N3: 19.2 | O3: TERA KANAF | P3: HAMSAH RIADI
A4: 46307 | B4: WINGS AIR | C4: ATR-72 | D4: PK-WHS | E4: RON | F4: KOE | G4: MALAM | H4: DBI | I4: CML | J4: CLOSED | K4: C036368 | L4: PERFORMED INSTALL ODOUR HAS BEEN CO | M4: 19.3 | N4: 20 | O4: TERA KANAF | P4: HAMSAH RIADI
A5: 46307 | B5: WINGS AIR | C5: ATR-72 | D5: PK-WHS | E5: RON | F5: KOE | G5: MALAM | H5: DBI | I5: CML | J5: CLOSED | K5: C036369 | L5: PERFORMED RECTIFICATION LATCH AT COMPARTMENT GALLEY,OPT TEST RESULT GOOD | M5: 20.1 | N5: 21.1 | O5: TERA KANAF | P5: HAMSAH RIADI
A6: 46307 | B6: LION AIR | C6: BOIENG | D6: PK-LFY | E6: RON | F6: KOE | G6: MALAM | H6: DBI | I6: CML | J6: CLOSED | K6: E0428021 | L6: PERFORMED DAILY CHECK BEAUTIFICATION INSPECTION HAS BEEN PERFORMED | M6: 21.2 | N6: 22.2 | O6: TERA KANAF | P6: HAMSAH RIADI
