Workbook
Name RentangBernama1: #REF!

Sheet WO
A1: 46287 | E1: ALL GROUP LEADER CABIN MAINTENANCE PLEASE REMARKS JIKA OPEN ATAU CLOSE
A2: DATE | B2: WG | C2: AC REG | D2: WO | E2: WO CAT | F2: WO DESCRIPTION | G2: PN PICKLIST (NO. PICKLIST) | H2: MAN HOURS | I2: OPERATOR | J2: TYPE | K2: PLAN STA | L2: REMARKS PPC WG TO LM | M2: ACT STA | N2: STATUS | O2: REASON OPEN | P2: CODE OPEN
A3: 46287 | B3: WG 11 | C3: PK-WGM | D3: 2300075 | E3: CBMIC | F3: FULL DEEP CLEANING INTERIOR INCLUDE SHAMPOOING CARPET, AND SEAT POLISHING FOR ATR72 AIRCRAFT | G3: --- | I3: IW | J3: ATR72 | K3: AMQ | N3: CLOSED
A4: 46287 | B4: WG 11 | C4: PK-WGM | D4: 2301695 | E4: CBMEC | F4: DEEP CLEANING EXTERIOR ON ATR72 AIRCRAFT | G4: --- | I4: IW | J4: ATR72 | K4: AMQ | N4: CLOSED
A5: 46287 | B5: WG 12 | C5: PK-WFV | D5: 2319706 | E5: CBMEC | F5: DEEP CLEANING EXTERIOR ON ATR72 AIRCRAFT | G5: --- | I5: IW | J5: ATR72 | K5: BPN | N5: OPEN | O5: NOT AVAILABLE LIGHTING ON FRONT OF HANGGAR | P5: AUTHOR
A6: 46287 | B6: WG 04 | C6: PK-LRF | D6: 2041836 | E6: EO | F6: INSPECTION FOR INVENTORY EMERGENCY EQUIPMENT ON THE AIRCRAFT | G6: --- | H6: 2,00 | I6: JT | J6: B737 | K6: CGK | N6: CLOSED
A7: 46287 | B7: WG 08 | C7: PK-SAI | D7: 1920378 | E7: EO | F7: INTERIOR CABIN INSPECTION | G7: --- | H7: 8,50 | I7: IU | J7: A320 | K7: CGK | L7: PREPARE FOR RTS | N7: CLOSED
A8: 46287 | B8: WG 08 | C8: PK-SAI | D8: 2060674 | E8: EO | F8: AIRCRAFT PEST CONTROL APPLICATION GUIDE | G8: --- | H8: 1,00 | I8: IU | J8: A320 | K8: CGK | L8: PREPARE FOR RTS | N8: CLOSED
A9: 46287 | B9: WG 08 | C9: PK-SAI | D9: 2323107 | E9: HT | F9: CREW OXYGEN CYLINDER. REMOVE OXYGEN CYLINDER FOR IN SHOP HYDROSTATIC TEST | G9: PN: NSA835070-5C (590367) @ K1 PN: 891511-14 / SN: ST295417 (590366) @ K4 PN: NSA835070-5C (588384) @ K1 PN: NSA835070-5C (587706) @ BM32 | H9: 1,00 | I9: IU | J9: A320 | K9: CGK | L9: - PL 591532 with con | N9: OPEN | O9: LM SLIDE
A10: 46287 | B10: WG 08 | C10: PK-SAI | D10: 2336145 | E10: EO | F10: INSPECTION FOR INVENTORY EMERGENCY EQUIPMENT ON THE AIRCRAFT | G10: --- | H10: 3,00 | I10: IU | J10: A320 | K10: CGK | L10: PREPARE FOR RTS | N10: CLOSED
A11: 46287 | B11: WG 08 | C11: PK-SAQ | D11: 2295280 | E11: HT | F11: OFFWING ESCAPE SLIDE. REMOVE OFFWING ESCAPE SLIDE FOR IN SHOP OVERHAUL NOTE: PLANNING: - TASK IS NOT APPLICABLE FOR DEACTIVATED EMERGENCY EXITS. INTERVAL: - FOR INTERVAL SELECTED FOR THE VARIOUS PART NUMBERS REFER TO APPENDIX 3. - INTERVAL TO BE MANAGED AT COMPONENT LEVEL. REFER TO SYSTEM SECTION INTRODUCTION FOR ADDITIONAL GUIDANCE. | G11: --- | H11: 2,00 | I11: IU | J11: A320 | K11: CGK | L11: * K1/ SN: M11506 | N11: CLOSED
A12: 46287 | B12: WG 08 | C12: PK-SJG | D12: 2326570 | E12: OP | F12: VACUUM TOILET SYSTEM . CLEANING OF VACUUM CLEANING OF VACUUM WASTE LINES WITH CHEMICAL CLEANING AGENT. | G12: --- | H12: 1,00 | I12: IU | J12: A320 | K12: CGK | N12: OPEN | O12: BPN RON | P12: IRR
A13: 46287 | B13: WG 09 | C13: PK-STF | D13: 2329571 | E13: OP | F13: VACUUM TOILET SYSTEM . CLEANING OF VACUUM CLEANING OF VACUUM WASTE LINES WITH CHEMICAL CLEANING AGENT. | G13: --- | H13: 1,00 | I13: IU | J13: A320 | K13: CGK | N13: CLOSED
A14: 46287 | B14: WG 05 | C14: PK-LDK | D14: 1588265 | E14: EO | F14: PINNACLE庐 / INSPECTION OF SEAT BEAMS / GENERIC / ALL AIRCRAFT TYPES | G14: --- | H14: 2,00 | I14: ID | J14: B737 | K14: CGK | N14: OPEN | O14: AC CONTINUE DINIHARI
A15: 46287 | B15: WG 07 | C15: PK-BKT | D15: 2177271 | E15: HT | F15: PASSENGER OXYGEN SYSTEM (CHEMICAL) DISCARD CHEMICAL OXYGEN GENERATORSNOTE: PN: E63440-00 SN: BEBL-F017-223 POS: 15 LH | G15: --- | H15: 1,00 | I15: ID | J15: A320 | K15: CGK | N15: CLOSED
A16: 46287 | B16: WG 13 | C16: PK-LEJ | D16: 2223138 | E16: OP | F16: DISCARD LAVATORY AIR EXTRACTION FILTER ELEMENT | G16: --- | H16: 2,00 | I16: JT | J16: A330 | K16: CGK | L16: PN: A425400454-200 AVAIL AT K1 | N16: CLOSED
A17: 46287 | B17: WG 08 | C17: PK-SJT | D17: 1834654 | E17: DEFER | F17: VACUUM TOILET SYSTEM INSPECT WATER SEPARATOR AND ASSOCIATED FILTER ELEMENT, AND CLEAN AS NECESSARY NOTE: DEPENDING ON OPERATING ENVIRONMENT AND OPERATORS EXPERIENCE, A LESS FREQUENT OR MORE FREQUENT INITIAL INTERVAL MAY BE USED. | G17: --- | H17: 2,00 | I17: IU | J17: A320 | K17: CGK | L17: PL 591319 (K7) SEND K1 | N17: CLOSED
A18: 46287 | B18: WG 08 | C18: PK-SGD | D18: 2250836 | E18: OP | F18: POTABLE WATER SYSTEM DISINFECTION OF POTABLE WATER SYSTEM AND DISCARD OF WATER FILTER ELEMENTS, IF INSTALLED NOTE: INTERVAL: - DEPENDING ON OPERATING ENVIRONMENT AND OPERATORS EXPERIENCE, A LESS FREQUENT OR MORE FREQUENT INITIAL INTERVAL MAY BE USED. | G18: --- | H18: 2,00 | I18: IU | J18: A320 | K18: CGK | L18: ICT OVERDUE | N18: OPEN | O18: PN: 0344-01 GASKET NILL K1 | P18: NS
A19: 46287 | B19: WG 08 | C19: PK-SAQ | D19: 2290004 | E19: CBMS | F19: AIRCRAFT PEST CONTROL APPLICATION GUIDE | G19: --- | H19: 1,00 | I19: IU | J19: A320 | K19: CGK | N19: CLOSED
A20: 46287 | B20: WG 08 | C20: PK-SGD | D20: 2303792 | E20: CBMS | F20: AIRCRAFT PEST CONTROL APPLICATION GUIDE | G20: --- | H20: 1,00 | I20: IU | J20: A320 | K20: CGK | N20: CLOSED
A21: 46287 | B21: WG 09 | C21: PK-STF | D21: 2307007 | E21: CBMS | F21: AIRCRAFT PEST CONTROL APPLICATION GUIDE | G21: --- | H21: 1,00 | I21: IU | J21: A320 | K21: CGK | N21: CLOSED
A22: 46287 | B22: WG 06 | C22: PK-BKF | D22: 2270611 | E22: OP | F22: POTABLE WATER SYSTEM STERILIZATION OF POTABLE WATER SYSTEM AND DISCARD OF WATER FILTER ELEMENTS. | G22: --- | H22: 3,00 | I22: ID | J22: A320 | K22: CGK | L22: Fwd Galley PN: EV949000 Qty 1EA OVER DUE 770440 QTY 1 EA | N22: OPEN | O22: PN: 0344-01 GASKET NILL K1 | P22: NS
A23: 46287 | B23: WG 09 | C23: PK-STD | D23: 2308139 | E23: CBMS | F23: AIRCRAFT PEST CONTROL APPLICATION GUIDE | G23: --- | H23: 1,00 | I23: IU | J23: A320 | K23: CGK | N23: CLOSED
A24: 46287 | B24: WG 08 | C24: PK-SAS | D24: 2309867 | E24: CBMS | F24: AIRCRAFT PEST CONTROL APPLICATION GUIDE | G24: --- | H24: 1,00 | I24: IU | J24: A320 | K24: CGK | N24: CLOSED
A25: 46287 | B25: WG 09 | C25: PK-SJT | D25: 2309866 | E25: CBMS | F25: AIRCRAFT PEST CONTROL APPLICATION GUIDE | G25: --- | H25: 1,00 | I25: IU | J25: A320 | K25: CGK | N25: CLOSED
A26: 46287 | B26: WG 07 | C26: PK-BKT | D26: 1688802 | E26: OP | F26: POTABLE WATER SYSTEM STERILIZATION OF POTABLE WATER SYSTEM AND DISCARD OF WATER FILTER ELEMENTS. | G26: PN: EV949000 (589981) @ K1 | H26: 3,00 | I26: ID | J26: A320 | K26: CGK | L26: REQ PIC PL#589981 (CGK) PN: EV949000 Qty 2EA | N26: OPEN | O26: PN: 0344-01 GASKET NILL K1 | P26: NS
A27: 46287 | B27: WG 09 | C27: PK-STC | D27: 2315810 | E27: OP | F27: VACUUM TOILET SYSTEM . CLEANING OF VACUUM CLEANING OF VACUUM WASTE LINES WITH CHEMICAL CLEANING AGENT. | G27: --- | H27: 1,00 | I27: IU | J27: A320 | K27: CGK | N27: CLOSED
A28: 46287 | B28: WG 13 | C28: PK-LEJ | D28: 2283474 | E28: OP | F28: DISINFECTION OF POTABLE WATER SYSTEM | G28: --- | H28: 3,00 | I28: JT | J28: A330 | K28: CGK | N28: CLOSED
A29: 46287 | B29: WG 13 | C29: PK-LEQ | D29: 2283475 | E29: OP | F29: DISINFECTION OF POTABLE WATER SYSTEM | G29: --- | H29: 3,00 | I29: JT | J29: A330 | K29: CGK | N29: OPEN | O29: CANISTER PN: 770410 NILL K1 | P29: NS
A30: 46287 | B30: WG 09 | C30: PK-STC | D30: 2312065 | E30: CBMS | F30: AIRCRAFT PEST CONTROL APPLICATION GUIDE | G30: --- | H30: 1,00 | I30: IU | J30: A320 | K30: CGK | N30: CLOSED
A31: 46287 | B31: WG 13 | C31: PK-LEQ | D31: 2283481 | E31: OP | F31: POTABLE DISCARD WATER FILTER CARTRIDGE OF THE GALLEYS | G31: --- | H31: 1 | I31: JT | J31: A330 | K31: CGK | L31: PN: 770440 avail at K1 | N31: OPEN | O31: CANISTER PN: 770410 NILL K1 | P31: NS
A32: 46287 | B32: WG 05 | C32: PK-LBK | D32: 2336098 | E32: HT | F32: REPLACE PLACARD HEXA CODE ELT FIX PK-LBK | G32: --- | H32: 0,25 | I32: ID | J32: B737 | K32: CGK | N32: CLOSED
A33: 46287 | B33: WG 08 | C33: PK-SJG | D33: 2319590 | E33: CBMS | F33: AIRCRAFT PEST CONTROL APPLICATION GUIDE | G33: --- | H33: 1,00 | I33: IU | J33: A320 | K33: CGK | N33: OPEN | O33: BPN RON | P33: IRR
A34: 46287 | B34: WG 06 | C34: PK-BKQ | D34: 2290331 | E34: HT | F34: MEGAPHONE BATTERIES DISCARD MEGAPHONE BATTERIES NOTE: P/N: ACREM1A VENDOR: ACR ELECTRONICS QTY 2 | G34: --- | H34: 1,00 | I34: ID | J34: A320 | K34: CGK | L34: K22: 94EA | N34: CLOSED
A35: 46287 | B35: WG 08 | C35: PK-SAG | D35: 2327591 | E35: OP | F35: VACUUM TOILET SYSTEM . CLEANING OF VACUUM CLEANING OF VACUUM WASTE LINES WITH CHEMICAL CLEANING AGENT. | G35: --- | H35: 1,00 | I35: IU | J35: A320 | K35: DPS | N35: CLOSED
A36: 46287 | B36: WG 07 | C36: PK-LAJ | D36: 1983973 | E36: DEFER | F36: VACUUM TOILET SYSTEM INSPECT WATER SEPARATOR AND ASSOCIATED FILTER ELEMENT, AND CLEAN AS NECESSARY. INTERVAL NOTE: DEPENDING ON OPERATING ENVIRONMENT AND OPERATORS EXPERIENCE, A LESS FREQUENT OR MORE FREQUENT INITIAL INTERVAL MAY BE USED. | G36: --- | H36: 2,00 | I36: ID | J36: A320 | K36: HLP | N36: OPEN | O36: NIL SPARE FILTER PN : 14401-080 AT H3 | P36: NS
A37: 46287 | B37: WG 07 | C37: PK-LAJ | D37: 2311657 | E37: CBMS | F37: AIRCRAFT PEST CONTROL APPLICATION GUIDE | G37: --- | H37: 1,00 | I37: ID | J37: A320 | K37: HLP | N37: CLOSED
A38: 46287 | B38: WG 11 | C38: PK-WJT | D38: 2302695 | E38: CBMIC | F38: FULL DEEP CLEANING INTERIOR INCLUDE SHAMPOOING CARPET, AND SEAT POLISHING FOR ATR72 AIRCRAFT | G38: --- | I38: IW | J38: ATR72 | K38: KOE | N38: CLOSED
A39: 46287 | B39: WG 11 | C39: PK-WJT | D39: 2302708 | E39: CBMEC | F39: DEEP CLEANING EXTERIOR ON ATR72 AIRCRAFT | G39: --- | I39: IW | J39: ATR72 | K39: KOE | N39: CLOSED
A40: 46287 | B40: WG 08 | C40: PK-SJD | D40: 2329590 | E40: OP | F40: VACUUM TOILET SYSTEM . CLEANING OF VACUUM CLEANING OF VACUUM WASTE LINES WITH CHEMICAL CLEANING AGENT. | G40: --- | H40: 1,00 | I40: IU | J40: A320 | K40: SUB | N40: CLOSED
...

Sheet DMI CBM
A1: 46287 | C1: ALL GROUP LEADER CABIN MAINTENANCE PLEASE REMARKS JIKA OPEN ATAU CLOSE
A2: DATE | B2: REG | C2: DMI DESCRIPTION | D2: PN REQUIRED | E2: DMI NO | F2: DMI CAT | G2: PLAN STA | H2: CAT | I2: STATUS | J2: REMARK
A3: 46287 | B3: PK-STC | C3: REF CML NO: S128037 MOSTLY ALL FASTEN SEATBELT SIGN AT PSU NOT ILLUMINATE. (ROW1,3,12,15 & 32 ILLUMINATE) | D3: NEED TROUBLESHOOT | E3: SAJ-029556 | F3: C | G3: CGK | H3: DJA DMI R01 | I3: OPEN | J3: SLIDE LM
A4: 46287 | B4: PK-LJG | C4: WINDOW LT 4SN 12-15 DEF,32-33 DEF,35DEF,31DE.30DE NOT ILLUMINATE | D4: LED PN:9650-35-0005 (1EA) AVAIL K4 (2EA) PL NO 590733 LED PN: 9651-14-0004 ( 1EA) AVAIL K4 PL NO 590733 LED PN:9651-35-0005 (3EA) AVAIL K4 PL:591151 | E4: 028601 | F4: C | G4: MDC | H4: DJA DMI R01 | I4: CLOSED
A5: 46287 | B5: PK-LFO | C5: WINDOW LT SN 1 BC NOT ILL | D5: NEED LAMP PN: 5106CW AVAIL K1 PL. 591570 TP.2611496//k4 | E5: 018249 | F5: C | G5: UPG | H5: DJA DMI R01 | I5: OPEN | J5: A/C NOT RON UPG
A6: 46287 | B6: PK-SJA | C6: FLASHLIGHT FA6 NOT ILLUMINATE | D6: NEED PART BATTERY PN: BATTRY-A1 AVAIL AT K22 | E6: SAJ0172912 | F6: D | G6: SOC | H6: DJA DMI R01 | I6: CLOSED
A7: 46287 | B7: PK-STA AOG AT BTH | C7: CEILING LIGHT S/N 3ABC, 5DEF, 26DEF, 28ABC, 29DEF, 31DEF, AND 32ABC IS NOT ILL | D7: NEED PART LAMP PN : F30WT8-840 (7EA) AVAIL AT K1, PL#590253 | E7: SAJ014290 | F7: C1 | G7: BTH | H7: DJA DMI R01 | I7: OPEN | J7: NO PART
A8: 46287 | B8: PK-SJT APU INOP | C8: INTERPHONE HANDSET 4L INOP | D8: NEED HANDSET ASSY CABIN PN : 89-01-07152 AVAIL AT K1 | E8: SAJ033745 | F8: C | G8: CGK | H8: DJA DMI R01 | I8: OPEN | J8: PART NOT AVAIL AT K1
A9: 46287 | B9: PK-BLA | C9: PILOT SEAT (F/O SIDE) ELECTRICAL ADJUSTMENT INOP (HORIZONTAL CONTROL SWITCH LOOSE, UNABLE MOVE TO NEUTRAL) | E9: ID027096 | G9: CGK | H9: UNPLANNED DMI | I9: CLOSED
A10: 46287 | B10: PK-SJA | C10: FLASHLIGHT FA#6 NOT ILLUMINATE | E10: SAJ017292 | G10: SOC | H10: UNPLANNED DMI | I10: CLOSED
C34: -

Sheet DJA AOC NSRDIL R01
B1: 46287
A2: REFRESH DATE | B2: WG | C2: AC REG | D2: NSRDI | E2: FINDING DESCRIPTION | F2: CATEGORY | G2: REPORT DATE | H2: DUE DATE | I2: PART NUMBER | J2: PART DESCRIPTION | K2: DEFER | L2: AOC | M2: TYPE | N2: PLAN STA | O2: PLAN DATE | P2: REMARKS | Q2: STATUS | R2: CLOSE DATE | S2: ACT STA | T2: REASON OPEN | U2: CODE OPEN
A3: 46283 | B3: WG 03 | C3: PK-LOJ | D3: NLA084118 | E3: COVER CEILLING ROW 31 FOUND PEEL OFF | F3: PAINTING | G3: 46273 | H3: 46394 | K3: WAITING PERFORM | L3: JT | M3: B737 | N3: SUB | O3: 46287 | Q3: CLOSED | S3: =IFNA(IFS(COUNTIFS('List AC'!$A:$A,$C3)>0,'List AC'!$A$2,COUNTIFS('List AC'!$B:$B,$C3)>0,'List AC'!$B$2,COUNTIFS('List AC'!$C:$C,$C3)>0,'List AC'!$C$2,COUNTIFS('List AC'!$D:$D,$C3)>0,'List AC'!$D$2,COUNTIFS('List AC'!$E:$E,$C3)>0,'List AC'!$E$2,COUNTIFS('List AC'!$F:$F,$C3)>0,'List AC'!$F$2,COUNTIFS('List AC'!$G:$G,$C3)>0,'List AC'!$G$2,COUNTIFS('List AC'!$H:$H,$C3)>0,'List AC'!$H$2,COUNTIFS('List AC'!$I:$I,$C3)>0,'List AC'!$I$2,COUNTIFS('List AC'!$J:$J,$C3)>0,'List AC'!$J$2,COUNTIFS('List AC'!$K:$K,$C3)>0,'List AC'!$K$2,COUNTIFS('List AC'!$L:$L,$C3)>0,'List AC'!$L$2,COUNTIFS('List AC'!$Q:$Q,$C3)>0,'List AC'!$Q$2,COUNTIFS('List AC'!$M:$M,$C3)>0,'List AC'!$M$2,COUNTIFS('List AC'!$N:$N,$C3)>0,'List AC'!$N$2,COUNTIFS('List AC'!$O:$O,$C3)>0,'List AC'!$O$2,COUNTIFS('List AC'!$P:$P,$C3)>0,'List AC'!$P$2,COUNTIFS('List AC'!$R:$R,$C3)>0,'List AC'!$R$2,COUNTIFS('List AC'!$S:$S,$C3)>0,'List AC'!$S$2,COUNTIFS('List AC'!$T:$T,$C3)>0,'List AC'!$T$2,COUNTIFS('List AC'!$U:$U,$C3)>0,'List AC'!$U$2,COUNTIFS('List AC'!$V:$V,$C3)>0,'List AC'!$V$2,COUNTIFS('List AC'!$W:$W,$C3)>0,'List AC'!$W$2,COUNTIFS('List AC'!$X:$X,$C3)>0,'List AC'!$X$2,COUNTIFS('List AC'!$Y:$Y,$C3)>0,'List AC'!$Y$2,COUNTIFS('List AC'!$Z:$Z,$C3)>0,'List AC'!$Z$2,COUNTIFS('List AC'!$AA:$AA,$C3)>0,'List AC'!$AA$2,COUNTIFS('List AC'!$AB:$AB,$C3)>0,'List AC'!$AB$2,COUNTIFS('List AC'!$AC:$AC,$C3)>0,'List AC'!$AC$2,COUNTIFS('List AC'!$AD:$AD,$C3)>0,'List AC'!$AD$2,COUNTIFS('List AC'!$AE:$AE,$C3)>0,'List AC'!$AE$2,COUNTIFS('List AC'!$AF:$AF,$C3)>0,'List AC'!$AF$2,COUNTIFS('List AC'!$AG:$AG,$C3)>0,'List AC'!$AG$2,COUNTIFS('List AC'!$AH:$AH,$C3)>0,'List AC'!$AH$2,COUNTIFS('List AC'!$AI:$AI,$C3)>0,'List AC'!$AI$2,COUNTIFS('List AC'!$AJ:$AJ,$C3)>0,'List AC'!$AJ$2,COUNTIFS('List AC'!$AK:$AK,$C3)>0,'List AC'!$AK$2,COUNTIFS('List AC'!$AL:$AL,$C3)>0,'List AC'!$AL$2,COUNTIFS('List AC'!$AM:$AM,$C3)>0,'List AC'!$AM$2,COUNTIFS('List AC'!$AN:$AN,$C3)>0,'List AC'!$AN$2,COUNTIFS('List AC'!$AO:$AO,$C3)>0,'List AC'!$AO$2,COUNTIFS('List AC'!$AP:$AP,$C3)>0,'List AC'!$AP$2,COUNTIFS('List AC'!$AQ:$AQ,$C3)>0,'List AC'!$AQ$2,COUNTIFS('List AC'!$AR:$AR,$C3)>0,'List AC'!$AR$2,COUNTIFS('List AC'!$AS:$AS,$C3)>0,'List AC'!$AS$2,COUNTIFS('List AC'!$AT:$AT,$C3)>0,'List AC'!$AT$2,COUNTIFS('List AC'!$AU:$AU,$C3)>0,'List AC'!$AU$2,COUNTIFS('List AC'!$AV:$AV,$C3)>0,'List AC'!$AV$2,COUNTIFS('List AC'!$AW:$AW,$C3)>0,'List AC'!$AW$2,COUNTIFS('List AC'!$AX:$AX,$C3)>0,'List AC'!$AX$2,COUNTIFS('List AC'!$AY:$AY,$C3)>0,'List AC'!$AY$2,COUNTIFS('List AC'!$AZ:$AZ,$C3)>0,'List AC'!$AZ$2,COUNTIFS('List AC'!$BA:$BA,$C3)>0,'List AC'!$BA$2,COUNTIFS('List AC'!$BB:$BB,$C3)>0,'List AC'!$BB$2,COUNTIFS('List AC'!$BC:$BC,$C3)>0,'List AC'!$BC$2,COUNTIFS('List AC'!$BD:$BD,$C3)>0,'List AC'!$BD$2),"")
A4: 46283 | B4: WG 02 | C4: PK-LSJ | D4: NLA076868 | E4: DURING DBI FOUND ULTRA LOCK HEADTRACK 16 DEFM 27-28 ABC D/T LEAK (AUTO RECLINE) | F4: CBM | G4: 46218 | H4: 46338 | I4: SP23789L | J4: ULTRALOC SP23789L | K4: WAITING PERFORM | L4: JT | M4: B737 | N4: CGK | O4: 46287 | P4: AVAIL K1 : 14EA | Q4: CLOSED | R4: 46287 | S4: =IFNA(IFS(COUNTIFS('List AC'!$A:$A,$C4)>0,'List AC'!$A$2,COUNTIFS('List AC'!$B:$B,$C4)>0,'List AC'!$B$2,COUNTIFS('List AC'!$C:$C,$C4)>0,'List AC'!$C$2,COUNTIFS('List AC'!$D:$D,$C4)>0,'List AC'!$D$2,COUNTIFS('List AC'!$E:$E,$C4)>0,'List AC'!$E$2,COUNTIFS('List AC'!$F:$F,$C4)>0,'List AC'!$F$2,COUNTIFS('List AC'!$G:$G,$C4)>0,'List AC'!$G$2,COUNTIFS('List AC'!$H:$H,$C4)>0,'List AC'!$H$2,COUNTIFS('List AC'!$I:$I,$C4)>0,'List AC'!$I$2,COUNTIFS('List AC'!$J:$J,$C4)>0,'List AC'!$J$2,COUNTIFS('List AC'!$K:$K,$C4)>0,'List AC'!$K$2,COUNTIFS('List AC'!$L:$L,$C4)>0,'List AC'!$L$2,COUNTIFS('List AC'!$Q:$Q,$C4)>0,'List AC'!$Q$2,COUNTIFS('List AC'!$M:$M,$C4)>0,'List AC'!$M$2,COUNTIFS('List AC'!$N:$N,$C4)>0,'List AC'!$N$2,COUNTIFS('List AC'!$O:$O,$C4)>0,'List AC'!$O$2,COUNTIFS('List AC'!$P:$P,$C4)>0,'List AC'!$P$2,COUNTIFS('List AC'!$R:$R,$C4)>0,'List AC'!$R$2,COUNTIFS('List AC'!$S:$S,$C4)>0,'List AC'!$S$2,COUNTIFS('List AC'!$T:$T,$C4)>0,'List AC'!$T$2,COUNTIFS('List AC'!$U:$U,$C4)>0,'List AC'!$U$2,COUNTIFS('List AC'!$V:$V,$C4)>0,'List AC'!$V$2,COUNTIFS('List AC'!$W:$W,$C4)>0,'List AC'!$W$2,COUNTIFS('List AC'!$X:$X,$C4)>0,'List AC'!$X$2,COUNTIFS('List AC'!$Y:$Y,$C4)>0,'List AC'!$Y$2,COUNTIFS('List AC'!$Z:$Z,$C4)>0,'List AC'!$Z$2,COUNTIFS('List AC'!$AA:$AA,$C4)>0,'List AC'!$AA$2,COUNTIFS('List AC'!$AB:$AB,$C4)>0,'List AC'!$AB$2,COUNTIFS('List AC'!$AC:$AC,$C4)>0,'List AC'!$AC$2,COUNTIFS('List AC'!$AD:$AD,$C4)>0,'List AC'!$AD$2,COUNTIFS('List AC'!$AE:$AE,$C4)>0,'List AC'!$AE$2,COUNTIFS('List AC'!$AF:$AF,$C4)>0,'List AC'!$AF$2,COUNTIFS('List AC'!$AG:$AG,$C4)>0,'List AC'!$AG$2,COUNTIFS('List AC'!$AH:$AH,$C4)>0,'List AC'!$AH$2,COUNTIFS('List AC'!$AI:$AI,$C4)>0,'List AC'!$AI$2,COUNTIFS('List AC'!$AJ:$AJ,$C4)>0,'List AC'!$AJ$2,COUNTIFS('List AC'!$AK:$AK,$C4)>0,'List AC'!$AK$2,COUNTIFS('List AC'!$AL:$AL,$C4)>0,'List AC'!$AL$2,COUNTIFS('List AC'!$AM:$AM,$C4)>0,'List AC'!$AM$2,COUNTIFS('List AC'!$AN:$AN,$C4)>0,'List AC'!$AN$2,COUNTIFS('List AC'!$AO:$AO,$C4)>0,'List AC'!$AO$2,COUNTIFS('List AC'!$AP:$AP,$C4)>0,'List AC'!$AP$2,COUNTIFS('List AC'!$AQ:$AQ,$C4)>0,'List AC'!$AQ$2,COUNTIFS('List AC'!$AR:$AR,$C4)>0,'List AC'!$AR$2,COUNTIFS('List AC'!$AS:$AS,$C4)>0,'List AC'!$AS$2,COUNTIFS('List AC'!$AT:$AT,$C4)>0,'List AC'!$AT$2,COUNTIFS('List AC'!$AU:$AU,$C4)>0,'List AC'!$AU$2,COUNTIFS('List AC'!$AV:$AV,$C4)>0,'List AC'!$AV$2,COUNTIFS('List AC'!$AW:$AW,$C4)>0,'List AC'!$AW$2,COUNTIFS('List AC'!$AX:$AX,$C4)>0,'List AC'!$AX$2,COUNTIFS('List AC'!$AY:$AY,$C4)>0,'List AC'!$AY$2,COUNTIFS('List AC'!$AZ:$AZ,$C4)>0,'List AC'!$AZ$2,COUNTIFS('List AC'!$BA:$BA,$C4)>0,'List AC'!$BA$2,COUNTIFS('List AC'!$BB:$BB,$C4)>0,'List AC'!$BB$2,COUNTIFS('List AC'!$BC:$BC,$C4)>0,'List AC'!$BC$2,COUNTIFS('List AC'!$BD:$BD,$C4)>0,'List AC'!$BD$2),"")
A5: 46283 | B5: WG 07 | C5: PK-BKT | D5: NBA032836 | E5: REFFNSRDIL NBA049589 FOOT REST FO WORN OUT | F5: CBM | G5: 46281 | H5: 46401 | I5: D2721021120000 | J5: FOOT REST | K5: WAITING PERFORM | L5: ID | M5: A320 | N5: CGK | O5: 46287 | P5: AVAIL K1 : 7 EA | Q5: CLOSED | R5: 46287 | S5: =IFNA(IFS(COUNTIFS('List AC'!$A:$A,$C5)>0,'List AC'!$A$2,COUNTIFS('List AC'!$B:$B,$C5)>0,'List AC'!$B$2,COUNTIFS('List AC'!$C:$C,$C5)>0,'List AC'!$C$2,COUNTIFS('List AC'!$D:$D,$C5)>0,'List AC'!$D$2,COUNTIFS('List AC'!$E:$E,$C5)>0,'List AC'!$E$2,COUNTIFS('List AC'!$F:$F,$C5)>0,'List AC'!$F$2,COUNTIFS('List AC'!$G:$G,$C5)>0,'List AC'!$G$2,COUNTIFS('List AC'!$H:$H,$C5)>0,'List AC'!$H$2,COUNTIFS('List AC'!$I:$I,$C5)>0,'List AC'!$I$2,COUNTIFS('List AC'!$J:$J,$C5)>0,'List AC'!$J$2,COUNTIFS('List AC'!$K:$K,$C5)>0,'List AC'!$K$2,COUNTIFS('List AC'!$L:$L,$C5)>0,'List AC'!$L$2,COUNTIFS('List AC'!$Q:$Q,$C5)>0,'List AC'!$Q$2,COUNTIFS('List AC'!$M:$M,$C5)>0,'List AC'!$M$2,COUNTIFS('List AC'!$N:$N,$C5)>0,'List AC'!$N$2,COUNTIFS('List AC'!$O:$O,$C5)>0,'List AC'!$O$2,COUNTIFS('List AC'!$P:$P,$C5)>0,'List AC'!$P$2,COUNTIFS('List AC'!$R:$R,$C5)>0,'List AC'!$R$2,COUNTIFS('List AC'!$S:$S,$C5)>0,'List AC'!$S$2,COUNTIFS('List AC'!$T:$T,$C5)>0,'List AC'!$T$2,COUNTIFS('List AC'!$U:$U,$C5)>0,'List AC'!$U$2,COUNTIFS('List AC'!$V:$V,$C5)>0,'List AC'!$V$2,COUNTIFS('List AC'!$W:$W,$C5)>0,'List AC'!$W$2,COUNTIFS('List AC'!$X:$X,$C5)>0,'List AC'!$X$2,COUNTIFS('List AC'!$Y:$Y,$C5)>0,'List AC'!$Y$2,COUNTIFS('List AC'!$Z:$Z,$C5)>0,'List AC'!$Z$2,COUNTIFS('List AC'!$AA:$AA,$C5)>0,'List AC'!$AA$2,COUNTIFS('List AC'!$AB:$AB,$C5)>0,'List AC'!$AB$2,COUNTIFS('List AC'!$AC:$AC,$C5)>0,'List AC'!$AC$2,COUNTIFS('List AC'!$AD:$AD,$C5)>0,'List AC'!$AD$2,COUNTIFS('List AC'!$AE:$AE,$C5)>0,'List AC'!$AE$2,COUNTIFS('List AC'!$AF:$AF,$C5)>0,'List AC'!$AF$2,COUNTIFS('List AC'!$AG:$AG,$C5)>0,'List AC'!$AG$2,COUNTIFS('List AC'!$AH:$AH,$C5)>0,'List AC'!$AH$2,COUNTIFS('List AC'!$AI:$AI,$C5)>0,'List AC'!$AI$2,COUNTIFS('List AC'!$AJ:$AJ,$C5)>0,'List AC'!$AJ$2,COUNTIFS('List AC'!$AK:$AK,$C5)>0,'List AC'!$AK$2,COUNTIFS('List AC'!$AL:$AL,$C5)>0,'List AC'!$AL$2,COUNTIFS('List AC'!$AM:$AM,$C5)>0,'List AC'!$AM$2,COUNTIFS('List AC'!$AN:$AN,$C5)>0,'List AC'!$AN$2,COUNTIFS('List AC'!$AO:$AO,$C5)>0,'List AC'!$AO$2,COUNTIFS('List AC'!$AP:$AP,$C5)>0,'List AC'!$AP$2,COUNTIFS('List AC'!$AQ:$AQ,$C5)>0,'List AC'!$AQ$2,COUNTIFS('List AC'!$AR:$AR,$C5)>0,'List AC'!$AR$2,COUNTIFS('List AC'!$AS:$AS,$C5)>0,'List AC'!$AS$2,COUNTIFS('List AC'!$AT:$AT,$C5)>0,'List AC'!$AT$2,COUNTIFS('List AC'!$AU:$AU,$C5)>0,'List AC'!$AU$2,COUNTIFS('List AC'!$AV:$AV,$C5)>0,'List AC'!$AV$2,COUNTIFS('List AC'!$AW:$AW,$C5)>0,'List AC'!$AW$2,COUNTIFS('List AC'!$AX:$AX,$C5)>0,'List AC'!$AX$2,COUNTIFS('List AC'!$AY:$AY,$C5)>0,'List AC'!$AY$2,COUNTIFS('List AC'!$AZ:$AZ,$C5)>0,'List AC'!$AZ$2,COUNTIFS('List AC'!$BA:$BA,$C5)>0,'List AC'!$BA$2,COUNTIFS('List AC'!$BB:$BB,$C5)>0,'List AC'!$BB$2,COUNTIFS('List AC'!$BC:$BC,$C5)>0,'List AC'!$BC$2,COUNTIFS('List AC'!$BD:$BD,$C5)>0,'List AC'!$BD$2),"")
A6: 46283 | B6: WG 06 | C6: PK-BKQ | D6: NBA037532 | E6: REFF FINDING SRV 7365 CARPET UNDER SEAT 1 DF BAD CONDITION | F6: CBM | G6: 46279 | H6: 46399 | K6: INVESTIGATE | L6: ID | M6: A320 | N6: CGK | O6: 46287 | P6: PLEASE INVESTIGATE AND RECTIFICATION. IF NEED SPARE PARTS, PLEASE CREATE RQ IN EMRO | Q6: CLOSED | R6: 46287 | S6: =IFNA(IFS(COUNTIFS('List AC'!$A:$A,$C6)>0,'List AC'!$A$2,COUNTIFS('List AC'!$B:$B,$C6)>0,'List AC'!$B$2,COUNTIFS('List AC'!$C:$C,$C6)>0,'List AC'!$C$2,COUNTIFS('List AC'!$D:$D,$C6)>0,'List AC'!$D$2,COUNTIFS('List AC'!$E:$E,$C6)>0,'List AC'!$E$2,COUNTIFS('List AC'!$F:$F,$C6)>0,'List AC'!$F$2,COUNTIFS('List AC'!$G:$G,$C6)>0,'List AC'!$G$2,COUNTIFS('List AC'!$H:$H,$C6)>0,'List AC'!$H$2,COUNTIFS('List AC'!$I:$I,$C6)>0,'List AC'!$I$2,COUNTIFS('List AC'!$J:$J,$C6)>0,'List AC'!$J$2,COUNTIFS('List AC'!$K:$K,$C6)>0,'List AC'!$K$2,COUNTIFS('List AC'!$L:$L,$C6)>0,'List AC'!$L$2,COUNTIFS('List AC'!$Q:$Q,$C6)>0,'List AC'!$Q$2,COUNTIFS('List AC'!$M:$M,$C6)>0,'List AC'!$M$2,COUNTIFS('List AC'!$N:$N,$C6)>0,'List AC'!$N$2,COUNTIFS('List AC'!$O:$O,$C6)>0,'List AC'!$O$2,COUNTIFS('List AC'!$P:$P,$C6)>0,'List AC'!$P$2,COUNTIFS('List AC'!$R:$R,$C6)>0,'List AC'!$R$2,COUNTIFS('List AC'!$S:$S,$C6)>0,'List AC'!$S$2,COUNTIFS('List AC'!$T:$T,$C6)>0,'List AC'!$T$2,COUNTIFS('List AC'!$U:$U,$C6)>0,'List AC'!$U$2,COUNTIFS('List AC'!$V:$V,$C6)>0,'List AC'!$V$2,COUNTIFS('List AC'!$W:$W,$C6)>0,'List AC'!$W$2,COUNTIFS('List AC'!$X:$X,$C6)>0,'List AC'!$X$2,COUNTIFS('List AC'!$Y:$Y,$C6)>0,'List AC'!$Y$2,COUNTIFS('List AC'!$Z:$Z,$C6)>0,'List AC'!$Z$2,COUNTIFS('List AC'!$AA:$AA,$C6)>0,'List AC'!$AA$2,COUNTIFS('List AC'!$AB:$AB,$C6)>0,'List AC'!$AB$2,COUNTIFS('List AC'!$AC:$AC,$C6)>0,'List AC'!$AC$2,COUNTIFS('List AC'!$AD:$AD,$C6)>0,'List AC'!$AD$2,COUNTIFS('List AC'!$AE:$AE,$C6)>0,'List AC'!$AE$2,COUNTIFS('List AC'!$AF:$AF,$C6)>0,'List AC'!$AF$2,COUNTIFS('List AC'!$AG:$AG,$C6)>0,'List AC'!$AG$2,COUNTIFS('List AC'!$AH:$AH,$C6)>0,'List AC'!$AH$2,COUNTIFS('List AC'!$AI:$AI,$C6)>0,'List AC'!$AI$2,COUNTIFS('List AC'!$AJ:$AJ,$C6)>0,'List AC'!$AJ$2,COUNTIFS('List AC'!$AK:$AK,$C6)>0,'List AC'!$AK$2,COUNTIFS('List AC'!$AL:$AL,$C6)>0,'List AC'!$AL$2,COUNTIFS('List AC'!$AM:$AM,$C6)>0,'List AC'!$AM$2,COUNTIFS('List AC'!$AN:$AN,$C6)>0,'List AC'!$AN$2,COUNTIFS('List AC'!$AO:$AO,$C6)>0,'List AC'!$AO$2,COUNTIFS('List AC'!$AP:$AP,$C6)>0,'List AC'!$AP$2,COUNTIFS('List AC'!$AQ:$AQ,$C6)>0,'List AC'!$AQ$2,COUNTIFS('List AC'!$AR:$AR,$C6)>0,'List AC'!$AR$2,COUNTIFS('List AC'!$AS:$AS,$C6)>0,'List AC'!$AS$2,COUNTIFS('List AC'!$AT:$AT,$C6)>0,'List AC'!$AT$2,COUNTIFS('List AC'!$AU:$AU,$C6)>0,'List AC'!$AU$2,COUNTIFS('List AC'!$AV:$AV,$C6)>0,'List AC'!$AV$2,COUNTIFS('List AC'!$AW:$AW,$C6)>0,'List AC'!$AW$2,COUNTIFS('List AC'!$AX:$AX,$C6)>0,'List AC'!$AX$2,COUNTIFS('List AC'!$AY:$AY,$C6)>0,'List AC'!$AY$2,COUNTIFS('List AC'!$AZ:$AZ,$C6)>0,'List AC'!$AZ$2,COUNTIFS('List AC'!$BA:$BA,$C6)>0,'List AC'!$BA$2,COUNTIFS('List AC'!$BB:$BB,$C6)>0,'List AC'!$BB$2,COUNTIFS('List AC'!$BC:$BC,$C6)>0,'List AC'!$BC$2,COUNTIFS('List AC'!$BD:$BD,$C6)>0,'List AC'!$BD$2),"")
A7: 46283 | B7: WG 05 | C7: PK-LBW | D7: NID008516 | E7: FOUND COVER AT UPPER FLOOD PANEL P8-50 (LEFT) PAINT PEEL OFF | F7: PAINTING | G7: 46266 | K7: INVESTIGATE | L7: ID | M7: B737 | N7: CGK | O7: 46287 | Q7: OPEN | S7: =IFNA(IFS(COUNTIFS('List AC'!$A:$A,$C7)>0,'List AC'!$A$2,COUNTIFS('List AC'!$B:$B,$C7)>0,'List AC'!$B$2,COUNTIFS('List AC'!$C:$C,$C7)>0,'List AC'!$C$2,COUNTIFS('List AC'!$D:$D,$C7)>0,'List AC'!$D$2,COUNTIFS('List AC'!$E:$E,$C7)>0,'List AC'!$E$2,COUNTIFS('List AC'!$F:$F,$C7)>0,'List AC'!$F$2,COUNTIFS('List AC'!$G:$G,$C7)>0,'List AC'!$G$2,COUNTIFS('List AC'!$H:$H,$C7)>0,'List AC'!$H$2,COUNTIFS('List AC'!$I:$I,$C7)>0,'List AC'!$I$2,COUNTIFS('List AC'!$J:$J,$C7)>0,'List AC'!$J$2,COUNTIFS('List AC'!$K:$K,$C7)>0,'List AC'!$K$2,COUNTIFS('List AC'!$L:$L,$C7)>0,'List AC'!$L$2,COUNTIFS('List AC'!$Q:$Q,$C7)>0,'List AC'!$Q$2,COUNTIFS('List AC'!$M:$M,$C7)>0,'List AC'!$M$2,COUNTIFS('List AC'!$N:$N,$C7)>0,'List AC'!$N$2,COUNTIFS('List AC'!$O:$O,$C7)>0,'List AC'!$O$2,COUNTIFS('List AC'!$P:$P,$C7)>0,'List AC'!$P$2,COUNTIFS('List AC'!$R:$R,$C7)>0,'List AC'!$R$2,COUNTIFS('List AC'!$S:$S,$C7)>0,'List AC'!$S$2,COUNTIFS('List AC'!$T:$T,$C7)>0,'List AC'!$T$2,COUNTIFS('List AC'!$U:$U,$C7)>0,'List AC'!$U$2,COUNTIFS('List AC'!$V:$V,$C7)>0,'List AC'!$V$2,COUNTIFS('List AC'!$W:$W,$C7)>0,'List AC'!$W$2,COUNTIFS('List AC'!$X:$X,$C7)>0,'List AC'!$X$2,COUNTIFS('List AC'!$Y:$Y,$C7)>0,'List AC'!$Y$2,COUNTIFS('List AC'!$Z:$Z,$C7)>0,'List AC'!$Z$2,COUNTIFS('List AC'!$AA:$AA,$C7)>0,'List AC'!$AA$2,COUNTIFS('List AC'!$AB:$AB,$C7)>0,'List AC'!$AB$2,COUNTIFS('List AC'!$AC:$AC,$C7)>0,'List AC'!$AC$2,COUNTIFS('List AC'!$AD:$AD,$C7)>0,'List AC'!$AD$2,COUNTIFS('List AC'!$AE:$AE,$C7)>0,'List AC'!$AE$2,COUNTIFS('List AC'!$AF:$AF,$C7)>0,'List AC'!$AF$2,COUNTIFS('List AC'!$AG:$AG,$C7)>0,'List AC'!$AG$2,COUNTIFS('List AC'!$AH:$AH,$C7)>0,'List AC'!$AH$2,COUNTIFS('List AC'!$AI:$AI,$C7)>0,'List AC'!$AI$2,COUNTIFS('List AC'!$AJ:$AJ,$C7)>0,'List AC'!$AJ$2,COUNTIFS('List AC'!$AK:$AK,$C7)>0,'List AC'!$AK$2,COUNTIFS('List AC'!$AL:$AL,$C7)>0,'List AC'!$AL$2,COUNTIFS('List AC'!$AM:$AM,$C7)>0,'List AC'!$AM$2,COUNTIFS('List AC'!$AN:$AN,$C7)>0,'List AC'!$AN$2,COUNTIFS('List AC'!$AO:$AO,$C7)>0,'List AC'!$AO$2,COUNTIFS('List AC'!$AP:$AP,$C7)>0,'List AC'!$AP$2,COUNTIFS('List AC'!$AQ:$AQ,$C7)>0,'List AC'!$AQ$2,COUNTIFS('List AC'!$AR:$AR,$C7)>0,'List AC'!$AR$2,COUNTIFS('List AC'!$AS:$AS,$C7)>0,'List AC'!$AS$2,COUNTIFS('List AC'!$AT:$AT,$C7)>0,'List AC'!$AT$2,COUNTIFS('List AC'!$AU:$AU,$C7)>0,'List AC'!$AU$2,COUNTIFS('List AC'!$AV:$AV,$C7)>0,'List AC'!$AV$2,COUNTIFS('List AC'!$AW:$AW,$C7)>0,'List AC'!$AW$2,COUNTIFS('List AC'!$AX:$AX,$C7)>0,'List AC'!$AX$2,COUNTIFS('List AC'!$AY:$AY,$C7)>0,'List AC'!$AY$2,COUNTIFS('List AC'!$AZ:$AZ,$C7)>0,'List AC'!$AZ$2,COUNTIFS('List AC'!$BA:$BA,$C7)>0,'List AC'!$BA$2,COUNTIFS('List AC'!$BB:$BB,$C7)>0,'List AC'!$BB$2,COUNTIFS('List AC'!$BC:$BC,$C7)>0,'List AC'!$BC$2,COUNTIFS('List AC'!$BD:$BD,$C7)>0,'List AC'!$BD$2),"") | T7: PANEL COCKPIT SHOP SIDE | U7: TC
A8: 46283 | B8: WG 02 | C8: PK-LFK | D8: 91050 | E8: RECLINE SEAT BUTTON 10 D BROKEN | F8: CBM | G8: 46273 | H8: 46273 | K8: INVESTIGATE | L8: JT | M8: B737 | N8: UPG | O8: 46287 | P8: PLEASE INVESTIGATE AND RECTIFICATION. IF NEED SPARE PARTS, PLEASE CREATE RQ IN EMRO | Q8: CLOSED | S8: =IFNA(IFS(COUNTIFS('List AC'!$A:$A,$C8)>0,'List AC'!$A$2,COUNTIFS('List AC'!$B:$B,$C8)>0,'List AC'!$B$2,COUNTIFS('List AC'!$C:$C,$C8)>0,'List AC'!$C$2,COUNTIFS('List AC'!$D:$D,$C8)>0,'List AC'!$D$2,COUNTIFS('List AC'!$E:$E,$C8)>0,'List AC'!$E$2,COUNTIFS('List AC'!$F:$F,$C8)>0,'List AC'!$F$2,COUNTIFS('List AC'!$G:$G,$C8)>0,'List AC'!$G$2,COUNTIFS('List AC'!$H:$H,$C8)>0,'List AC'!$H$2,COUNTIFS('List AC'!$I:$I,$C8)>0,'List AC'!$I$2,COUNTIFS('List AC'!$J:$J,$C8)>0,'List AC'!$J$2,COUNTIFS('List AC'!$K:$K,$C8)>0,'List AC'!$K$2,COUNTIFS('List AC'!$L:$L,$C8)>0,'List AC'!$L$2,COUNTIFS('List AC'!$Q:$Q,$C8)>0,'List AC'!$Q$2,COUNTIFS('List AC'!$M:$M,$C8)>0,'List AC'!$M$2,COUNTIFS('List AC'!$N:$N,$C8)>0,'List AC'!$N$2,COUNTIFS('List AC'!$O:$O,$C8)>0,'List AC'!$O$2,COUNTIFS('List AC'!$P:$P,$C8)>0,'List AC'!$P$2,COUNTIFS('List AC'!$R:$R,$C8)>0,'List AC'!$R$2,COUNTIFS('List AC'!$S:$S,$C8)>0,'List AC'!$S$2,COUNTIFS('List AC'!$T:$T,$C8)>0,'List AC'!$T$2,COUNTIFS('List AC'!$U:$U,$C8)>0,'List AC'!$U$2,COUNTIFS('List AC'!$V:$V,$C8)>0,'List AC'!$V$2,COUNTIFS('List AC'!$W:$W,$C8)>0,'List AC'!$W$2,COUNTIFS('List AC'!$X:$X,$C8)>0,'List AC'!$X$2,COUNTIFS('List AC'!$Y:$Y,$C8)>0,'List AC'!$Y$2,COUNTIFS('List AC'!$Z:$Z,$C8)>0,'List AC'!$Z$2,COUNTIFS('List AC'!$AA:$AA,$C8)>0,'List AC'!$AA$2,COUNTIFS('List AC'!$AB:$AB,$C8)>0,'List AC'!$AB$2,COUNTIFS('List AC'!$AC:$AC,$C8)>0,'List AC'!$AC$2,COUNTIFS('List AC'!$AD:$AD,$C8)>0,'List AC'!$AD$2,COUNTIFS('List AC'!$AE:$AE,$C8)>0,'List AC'!$AE$2,COUNTIFS('List AC'!$AF:$AF,$C8)>0,'List AC'!$AF$2,COUNTIFS('List AC'!$AG:$AG,$C8)>0,'List AC'!$AG$2,COUNTIFS('List AC'!$AH:$AH,$C8)>0,'List AC'!$AH$2,COUNTIFS('List AC'!$AI:$AI,$C8)>0,'List AC'!$AI$2,COUNTIFS('List AC'!$AJ:$AJ,$C8)>0,'List AC'!$AJ$2,COUNTIFS('List AC'!$AK:$AK,$C8)>0,'List AC'!$AK$2,COUNTIFS('List AC'!$AL:$AL,$C8)>0,'List AC'!$AL$2,COUNTIFS('List AC'!$AM:$AM,$C8)>0,'List AC'!$AM$2,COUNTIFS('List AC'!$AN:$AN,$C8)>0,'List AC'!$AN$2,COUNTIFS('List AC'!$AO:$AO,$C8)>0,'List AC'!$AO$2,COUNTIFS('List AC'!$AP:$AP,$C8)>0,'List AC'!$AP$2,COUNTIFS('List AC'!$AQ:$AQ,$C8)>0,'List AC'!$AQ$2,COUNTIFS('List AC'!$AR:$AR,$C8)>0,'List AC'!$AR$2,COUNTIFS('List AC'!$AS:$AS,$C8)>0,'List AC'!$AS$2,COUNTIFS('List AC'!$AT:$AT,$C8)>0,'List AC'!$AT$2,COUNTIFS('List AC'!$AU:$AU,$C8)>0,'List AC'!$AU$2,COUNTIFS('List AC'!$AV:$AV,$C8)>0,'List AC'!$AV$2,COUNTIFS('List AC'!$AW:$AW,$C8)>0,'List AC'!$AW$2,COUNTIFS('List AC'!$AX:$AX,$C8)>0,'List AC'!$AX$2,COUNTIFS('List AC'!$AY:$AY,$C8)>0,'List AC'!$AY$2,COUNTIFS('List AC'!$AZ:$AZ,$C8)>0,'List AC'!$AZ$2,COUNTIFS('List AC'!$BA:$BA,$C8)>0,'List AC'!$BA$2,COUNTIFS('List AC'!$BB:$BB,$C8)>0,'List AC'!$BB$2,COUNTIFS('List AC'!$BC:$BC,$C8)>0,'List AC'!$BC$2,COUNTIFS('List AC'!$BD:$BD,$C8)>0,'List AC'!$BD$2),"")
A9: 46283 | B9: WG 02 | C9: PK-LFK | D9: NLA091551 | E9: REFF NSRDIL PAGE NO.NLA091050 RECLINE SEAT BUTTON NO.10D IS BROKEN | F9: CBM | G9: 46278 | I9: SP23996B | J9: RECLINE BUTTON | K9: WAITING PERFORM | L9: JT | M9: B737 | N9: UPG | O9: 46287 | P9: AVAIL K4 : 89 EA | Q9: CLOSED | S9: =IFNA(IFS(COUNTIFS('List AC'!$A:$A,$C9)>0,'List AC'!$A$2,COUNTIFS('List AC'!$B:$B,$C9)>0,'List AC'!$B$2,COUNTIFS('List AC'!$C:$C,$C9)>0,'List AC'!$C$2,COUNTIFS('List AC'!$D:$D,$C9)>0,'List AC'!$D$2,COUNTIFS('List AC'!$E:$E,$C9)>0,'List AC'!$E$2,COUNTIFS('List AC'!$F:$F,$C9)>0,'List AC'!$F$2,COUNTIFS('List AC'!$G:$G,$C9)>0,'List AC'!$G$2,COUNTIFS('List AC'!$H:$H,$C9)>0,'List AC'!$H$2,COUNTIFS('List AC'!$I:$I,$C9)>0,'List AC'!$I$2,COUNTIFS('List AC'!$J:$J,$C9)>0,'List AC'!$J$2,COUNTIFS('List AC'!$K:$K,$C9)>0,'List AC'!$K$2,COUNTIFS('List AC'!$L:$L,$C9)>0,'List AC'!$L$2,COUNTIFS('List AC'!$Q:$Q,$C9)>0,'List AC'!$Q$2,COUNTIFS('List AC'!$M:$M,$C9)>0,'List AC'!$M$2,COUNTIFS('List AC'!$N:$N,$C9)>0,'List AC'!$N$2,COUNTIFS('List AC'!$O:$O,$C9)>0,'List AC'!$O$2,COUNTIFS('List AC'!$P:$P,$C9)>0,'List AC'!$P$2,COUNTIFS('List AC'!$R:$R,$C9)>0,'List AC'!$R$2,COUNTIFS('List AC'!$S:$S,$C9)>0,'List AC'!$S$2,COUNTIFS('List AC'!$T:$T,$C9)>0,'List AC'!$T$2,COUNTIFS('List AC'!$U:$U,$C9)>0,'List AC'!$U$2,COUNTIFS('List AC'!$V:$V,$C9)>0,'List AC'!$V$2,COUNTIFS('List AC'!$W:$W,$C9)>0,'List AC'!$W$2,COUNTIFS('List AC'!$X:$X,$C9)>0,'List AC'!$X$2,COUNTIFS('List AC'!$Y:$Y,$C9)>0,'List AC'!$Y$2,COUNTIFS('List AC'!$Z:$Z,$C9)>0,'List AC'!$Z$2,COUNTIFS('List AC'!$AA:$AA,$C9)>0,'List AC'!$AA$2,COUNTIFS('List AC'!$AB:$AB,$C9)>0,'List AC'!$AB$2,COUNTIFS('List AC'!$AC:$AC,$C9)>0,'List AC'!$AC$2,COUNTIFS('List AC'!$AD:$AD,$C9)>0,'List AC'!$AD$2,COUNTIFS('List AC'!$AE:$AE,$C9)>0,'List AC'!$AE$2,COUNTIFS('List AC'!$AF:$AF,$C9)>0,'List AC'!$AF$2,COUNTIFS('List AC'!$AG:$AG,$C9)>0,'List AC'!$AG$2,COUNTIFS('List AC'!$AH:$AH,$C9)>0,'List AC'!$AH$2,COUNTIFS('List AC'!$AI:$AI,$C9)>0,'List AC'!$AI$2,COUNTIFS('List AC'!$AJ:$AJ,$C9)>0,'List AC'!$AJ$2,COUNTIFS('List AC'!$AK:$AK,$C9)>0,'List AC'!$AK$2,COUNTIFS('List AC'!$AL:$AL,$C9)>0,'List AC'!$AL$2,COUNTIFS('List AC'!$AM:$AM,$C9)>0,'List AC'!$AM$2,COUNTIFS('List AC'!$AN:$AN,$C9)>0,'List AC'!$AN$2,COUNTIFS('List AC'!$AO:$AO,$C9)>0,'List AC'!$AO$2,COUNTIFS('List AC'!$AP:$AP,$C9)>0,'List AC'!$AP$2,COUNTIFS('List AC'!$AQ:$AQ,$C9)>0,'List AC'!$AQ$2,COUNTIFS('List AC'!$AR:$AR,$C9)>0,'List AC'!$AR$2,COUNTIFS('List AC'!$AS:$AS,$C9)>0,'List AC'!$AS$2,COUNTIFS('List AC'!$AT:$AT,$C9)>0,'List AC'!$AT$2,COUNTIFS('List AC'!$AU:$AU,$C9)>0,'List AC'!$AU$2,COUNTIFS('List AC'!$AV:$AV,$C9)>0,'List AC'!$AV$2,COUNTIFS('List AC'!$AW:$AW,$C9)>0,'List AC'!$AW$2,COUNTIFS('List AC'!$AX:$AX,$C9)>0,'List AC'!$AX$2,COUNTIFS('List AC'!$AY:$AY,$C9)>0,'List AC'!$AY$2,COUNTIFS('List AC'!$AZ:$AZ,$C9)>0,'List AC'!$AZ$2,COUNTIFS('List AC'!$BA:$BA,$C9)>0,'List AC'!$BA$2,COUNTIFS('List AC'!$BB:$BB,$C9)>0,'List AC'!$BB$2,COUNTIFS('List AC'!$BC:$BC,$C9)>0,'List AC'!$BC$2,COUNTIFS('List AC'!$BD:$BD,$C9)>0,'List AC'!$BD$2),"")
A10: 46283 | B10: WG 02 | C10: PK-LFK | D10: NLA091552 | E10: RECLINE BUTTON 36C,38D MISSING | F10: CBM | G10: 46279 | H10: 46399 | I10: SP23996B | J10: RECLINE BUTTON | K10: WAITING PERFORM | L10: JT | M10: B737 | N10: UPG | O10: 46287 | P10: AVAIL K4 : 89 EA | Q10: CLOSED | S10: =IFNA(IFS(COUNTIFS('List AC'!$A:$A,$C10)>0,'List AC'!$A$2,COUNTIFS('List AC'!$B:$B,$C10)>0,'List AC'!$B$2,COUNTIFS('List AC'!$C:$C,$C10)>0,'List AC'!$C$2,COUNTIFS('List AC'!$D:$D,$C10)>0,'List AC'!$D$2,COUNTIFS('List AC'!$E:$E,$C10)>0,'List AC'!$E$2,COUNTIFS('List AC'!$F:$F,$C10)>0,'List AC'!$F$2,COUNTIFS('List AC'!$G:$G,$C10)>0,'List AC'!$G$2,COUNTIFS('List AC'!$H:$H,$C10)>0,'List AC'!$H$2,COUNTIFS('List AC'!$I:$I,$C10)>0,'List AC'!$I$2,COUNTIFS('List AC'!$J:$J,$C10)>0,'List AC'!$J$2,COUNTIFS('List AC'!$K:$K,$C10)>0,'List AC'!$K$2,COUNTIFS('List AC'!$L:$L,$C10)>0,'List AC'!$L$2,COUNTIFS('List AC'!$Q:$Q,$C10)>0,'List AC'!$Q$2,COUNTIFS('List AC'!$M:$M,$C10)>0,'List AC'!$M$2,COUNTIFS('List AC'!$N:$N,$C10)>0,'List AC'!$N$2,COUNTIFS('List AC'!$O:$O,$C10)>0,'List AC'!$O$2,COUNTIFS('List AC'!$P:$P,$C10)>0,'List AC'!$P$2,COUNTIFS('List AC'!$R:$R,$C10)>0,'List AC'!$R$2,COUNTIFS('List AC'!$S:$S,$C10)>0,'List AC'!$S$2,COUNTIFS('List AC'!$T:$T,$C10)>0,'List AC'!$T$2,COUNTIFS('List AC'!$U:$U,$C10)>0,'List AC'!$U$2,COUNTIFS('List AC'!$V:$V,$C10)>0,'List AC'!$V$2,COUNTIFS('List AC'!$W:$W,$C10)>0,'List AC'!$W$2,COUNTIFS('List AC'!$X:$X,$C10)>0,'List AC'!$X$2,COUNTIFS('List AC'!$Y:$Y,$C10)>0,'List AC'!$Y$2,COUNTIFS('List AC'!$Z:$Z,$C10)>0,'List AC'!$Z$2,COUNTIFS('List AC'!$AA:$AA,$C10)>0,'List AC'!$AA$2,COUNTIFS('List AC'!$AB:$AB,$C10)>0,'List AC'!$AB$2,COUNTIFS('List AC'!$AC:$AC,$C10)>0,'List AC'!$AC$2,COUNTIFS('List AC'!$AD:$AD,$C10)>0,'List AC'!$AD$2,COUNTIFS('List AC'!$AE:$AE,$C10)>0,'List AC'!$AE$2,COUNTIFS('List AC'!$AF:$AF,$C10)>0,'List AC'!$AF$2,COUNTIFS('List AC'!$AG:$AG,$C10)>0,'List AC'!$AG$2,COUNTIFS('List AC'!$AH:$AH,$C10)>0,'List AC'!$AH$2,COUNTIFS('List AC'!$AI:$AI,$C10)>0,'List AC'!$AI$2,COUNTIFS('List AC'!$AJ:$AJ,$C10)>0,'List AC'!$AJ$2,COUNTIFS('List AC'!$AK:$AK,$C10)>0,'List AC'!$AK$2,COUNTIFS('List AC'!$AL:$AL,$C10)>0,'List AC'!$AL$2,COUNTIFS('List AC'!$AM:$AM,$C10)>0,'List AC'!$AM$2,COUNTIFS('List AC'!$AN:$AN,$C10)>0,'List AC'!$AN$2,COUNTIFS('List AC'!$AO:$AO,$C10)>0,'List AC'!$AO$2,COUNTIFS('List AC'!$AP:$AP,$C10)>0,'List AC'!$AP$2,COUNTIFS('List AC'!$AQ:$AQ,$C10)>0,'List AC'!$AQ$2,COUNTIFS('List AC'!$AR:$AR,$C10)>0,'List AC'!$AR$2,COUNTIFS('List AC'!$AS:$AS,$C10)>0,'List AC'!$AS$2,COUNTIFS('List AC'!$AT:$AT,$C10)>0,'List AC'!$AT$2,COUNTIFS('List AC'!$AU:$AU,$C10)>0,'List AC'!$AU$2,COUNTIFS('List AC'!$AV:$AV,$C10)>0,'List AC'!$AV$2,COUNTIFS('List AC'!$AW:$AW,$C10)>0,'List AC'!$AW$2,COUNTIFS('List AC'!$AX:$AX,$C10)>0,'List AC'!$AX$2,COUNTIFS('List AC'!$AY:$AY,$C10)>0,'List AC'!$AY$2,COUNTIFS('List AC'!$AZ:$AZ,$C10)>0,'List AC'!$AZ$2,COUNTIFS('List AC'!$BA:$BA,$C10)>0,'List AC'!$BA$2,COUNTIFS('List AC'!$BB:$BB,$C10)>0,'List AC'!$BB$2,COUNTIFS('List AC'!$BC:$BC,$C10)>0,'List AC'!$BC$2,COUNTIFS('List AC'!$BD:$BD,$C10)>0,'List AC'!$BD$2),"")
A11: 46280 | B11: WG 03 | C11: PK-LPK | D11: NLA070994 | E11: REF FINDING SRV 12154 ESCUTCHEON SEAT 4AB, 4 D, 10E, 20D,24F,27A,27E,29B,30B FOUND CRACK | F11: CBM | G11: 46241 | H11: 46361 | I11: 1010206-301BHU | J11: ESCUTCHEON, BLANK | K11: WAITING PERFORM | L11: JT | M11: B737 | N11: DPS | O11: 46287 | P11: TP 2611703 | Q11: CLOSED | R11: 46287 | S11: =IFNA(IFS(COUNTIFS('List AC'!$A:$A,$C11)>0,'List AC'!$A$2,COUNTIFS('List AC'!$B:$B,$C11)>0,'List AC'!$B$2,COUNTIFS('List AC'!$C:$C,$C11)>0,'List AC'!$C$2,COUNTIFS('List AC'!$D:$D,$C11)>0,'List AC'!$D$2,COUNTIFS('List AC'!$E:$E,$C11)>0,'List AC'!$E$2,COUNTIFS('List AC'!$F:$F,$C11)>0,'List AC'!$F$2,COUNTIFS('List AC'!$G:$G,$C11)>0,'List AC'!$G$2,COUNTIFS('List AC'!$H:$H,$C11)>0,'List AC'!$H$2,COUNTIFS('List AC'!$I:$I,$C11)>0,'List AC'!$I$2,COUNTIFS('List AC'!$J:$J,$C11)>0,'List AC'!$J$2,COUNTIFS('List AC'!$K:$K,$C11)>0,'List AC'!$K$2,COUNTIFS('List AC'!$L:$L,$C11)>0,'List AC'!$L$2,COUNTIFS('List AC'!$Q:$Q,$C11)>0,'List AC'!$Q$2,COUNTIFS('List AC'!$M:$M,$C11)>0,'List AC'!$M$2,COUNTIFS('List AC'!$N:$N,$C11)>0,'List AC'!$N$2,COUNTIFS('List AC'!$O:$O,$C11)>0,'List AC'!$O$2,COUNTIFS('List AC'!$P:$P,$C11)>0,'List AC'!$P$2,COUNTIFS('List AC'!$R:$R,$C11)>0,'List AC'!$R$2,COUNTIFS('List AC'!$S:$S,$C11)>0,'List AC'!$S$2,COUNTIFS('List AC'!$T:$T,$C11)>0,'List AC'!$T$2,COUNTIFS('List AC'!$U:$U,$C11)>0,'List AC'!$U$2,COUNTIFS('List AC'!$V:$V,$C11)>0,'List AC'!$V$2,COUNTIFS('List AC'!$W:$W,$C11)>0,'List AC'!$W$2,COUNTIFS('List AC'!$X:$X,$C11)>0,'List AC'!$X$2,COUNTIFS('List AC'!$Y:$Y,$C11)>0,'List AC'!$Y$2,COUNTIFS('List AC'!$Z:$Z,$C11)>0,'List AC'!$Z$2,COUNTIFS('List AC'!$AA:$AA,$C11)>0,'List AC'!$AA$2,COUNTIFS('List AC'!$AB:$AB,$C11)>0,'List AC'!$AB$2,COUNTIFS('List AC'!$AC:$AC,$C11)>0,'List AC'!$AC$2,COUNTIFS('List AC'!$AD:$AD,$C11)>0,'List AC'!$AD$2,COUNTIFS('List AC'!$AE:$AE,$C11)>0,'List AC'!$AE$2,COUNTIFS('List AC'!$AF:$AF,$C11)>0,'List AC'!$AF$2,COUNTIFS('List AC'!$AG:$AG,$C11)>0,'List AC'!$AG$2,COUNTIFS('List AC'!$AH:$AH,$C11)>0,'List AC'!$AH$2,COUNTIFS('List AC'!$AI:$AI,$C11)>0,'List AC'!$AI$2,COUNTIFS('List AC'!$AJ:$AJ,$C11)>0,'List AC'!$AJ$2,COUNTIFS('List AC'!$AK:$AK,$C11)>0,'List AC'!$AK$2,COUNTIFS('List AC'!$AL:$AL,$C11)>0,'List AC'!$AL$2,COUNTIFS('List AC'!$AM:$AM,$C11)>0,'List AC'!$AM$2,COUNTIFS('List AC'!$AN:$AN,$C11)>0,'List AC'!$AN$2,COUNTIFS('List AC'!$AO:$AO,$C11)>0,'List AC'!$AO$2,COUNTIFS('List AC'!$AP:$AP,$C11)>0,'List AC'!$AP$2,COUNTIFS('List AC'!$AQ:$AQ,$C11)>0,'List AC'!$AQ$2,COUNTIFS('List AC'!$AR:$AR,$C11)>0,'List AC'!$AR$2,COUNTIFS('List AC'!$AS:$AS,$C11)>0,'List AC'!$AS$2,COUNTIFS('List AC'!$AT:$AT,$C11)>0,'List AC'!$AT$2,COUNTIFS('List AC'!$AU:$AU,$C11)>0,'List AC'!$AU$2,COUNTIFS('List AC'!$AV:$AV,$C11)>0,'List AC'!$AV$2,COUNTIFS('List AC'!$AW:$AW,$C11)>0,'List AC'!$AW$2,COUNTIFS('List AC'!$AX:$AX,$C11)>0,'List AC'!$AX$2,COUNTIFS('List AC'!$AY:$AY,$C11)>0,'List AC'!$AY$2,COUNTIFS('List AC'!$AZ:$AZ,$C11)>0,'List AC'!$AZ$2,COUNTIFS('List AC'!$BA:$BA,$C11)>0,'List AC'!$BA$2,COUNTIFS('List AC'!$BB:$BB,$C11)>0,'List AC'!$BB$2,COUNTIFS('List AC'!$BC:$BC,$C11)>0,'List AC'!$BC$2,COUNTIFS('List AC'!$BD:$BD,$C11)>0,'List AC'!$BD$2),"")
A12: 46280 | B12: WG 03 | C12: PK-LPK | D12: NLA070996 | E12: REF FINDING SRV 12164 ESCUTCHEON 19E MISSING | F12: CBM | G12: 46241 | H12: 46361 | I12: 1010206-301BHU | J12: ESCUTCHEON, BLANK | K12: WAITING PERFORM | L12: JT | M12: B737 | N12: DPS | O12: 46287 | P12: TP 2611703 | Q12: CLOSED | R12: 46287 | S12: =IFNA(IFS(COUNTIFS('List AC'!$A:$A,$C12)>0,'List AC'!$A$2,COUNTIFS('List AC'!$B:$B,$C12)>0,'List AC'!$B$2,COUNTIFS('List AC'!$C:$C,$C12)>0,'List AC'!$C$2,COUNTIFS('List AC'!$D:$D,$C12)>0,'List AC'!$D$2,COUNTIFS('List AC'!$E:$E,$C12)>0,'List AC'!$E$2,COUNTIFS('List AC'!$F:$F,$C12)>0,'List AC'!$F$2,COUNTIFS('List AC'!$G:$G,$C12)>0,'List AC'!$G$2,COUNTIFS('List AC'!$H:$H,$C12)>0,'List AC'!$H$2,COUNTIFS('List AC'!$I:$I,$C12)>0,'List AC'!$I$2,COUNTIFS('List AC'!$J:$J,$C12)>0,'List AC'!$J$2,COUNTIFS('List AC'!$K:$K,$C12)>0,'List AC'!$K$2,COUNTIFS('List AC'!$L:$L,$C12)>0,'List AC'!$L$2,COUNTIFS('List AC'!$Q:$Q,$C12)>0,'List AC'!$Q$2,COUNTIFS('List AC'!$M:$M,$C12)>0,'List AC'!$M$2,COUNTIFS('List AC'!$N:$N,$C12)>0,'List AC'!$N$2,COUNTIFS('List AC'!$O:$O,$C12)>0,'List AC'!$O$2,COUNTIFS('List AC'!$P:$P,$C12)>0,'List AC'!$P$2,COUNTIFS('List AC'!$R:$R,$C12)>0,'List AC'!$R$2,COUNTIFS('List AC'!$S:$S,$C12)>0,'List AC'!$S$2,COUNTIFS('List AC'!$T:$T,$C12)>0,'List AC'!$T$2,COUNTIFS('List AC'!$U:$U,$C12)>0,'List AC'!$U$2,COUNTIFS('List AC'!$V:$V,$C12)>0,'List AC'!$V$2,COUNTIFS('List AC'!$W:$W,$C12)>0,'List AC'!$W$2,COUNTIFS('List AC'!$X:$X,$C12)>0,'List AC'!$X$2,COUNTIFS('List AC'!$Y:$Y,$C12)>0,'List AC'!$Y$2,COUNTIFS('List AC'!$Z:$Z,$C12)>0,'List AC'!$Z$2,COUNTIFS('List AC'!$AA:$AA,$C12)>0,'List AC'!$AA$2,COUNTIFS('List AC'!$AB:$AB,$C12)>0,'List AC'!$AB$2,COUNTIFS('List AC'!$AC:$AC,$C12)>0,'List AC'!$AC$2,COUNTIFS('List AC'!$AD:$AD,$C12)>0,'List AC'!$AD$2,COUNTIFS('List AC'!$AE:$AE,$C12)>0,'List AC'!$AE$2,COUNTIFS('List AC'!$AF:$AF,$C12)>0,'List AC'!$AF$2,COUNTIFS('List AC'!$AG:$AG,$C12)>0,'List AC'!$AG$2,COUNTIFS('List AC'!$AH:$AH,$C12)>0,'List AC'!$AH$2,COUNTIFS('List AC'!$AI:$AI,$C12)>0,'List AC'!$AI$2,COUNTIFS('List AC'!$AJ:$AJ,$C12)>0,'List AC'!$AJ$2,COUNTIFS('List AC'!$AK:$AK,$C12)>0,'List AC'!$AK$2,COUNTIFS('List AC'!$AL:$AL,$C12)>0,'List AC'!$AL$2,COUNTIFS('List AC'!$AM:$AM,$C12)>0,'List AC'!$AM$2,COUNTIFS('List AC'!$AN:$AN,$C12)>0,'List AC'!$AN$2,COUNTIFS('List AC'!$AO:$AO,$C12)>0,'List AC'!$AO$2,COUNTIFS('List AC'!$AP:$AP,$C12)>0,'List AC'!$AP$2,COUNTIFS('List AC'!$AQ:$AQ,$C12)>0,'List AC'!$AQ$2,COUNTIFS('List AC'!$AR:$AR,$C12)>0,'List AC'!$AR$2,COUNTIFS('List AC'!$AS:$AS,$C12)>0,'List AC'!$AS$2,COUNTIFS('List AC'!$AT:$AT,$C12)>0,'List AC'!$AT$2,COUNTIFS('List AC'!$AU:$AU,$C12)>0,'List AC'!$AU$2,COUNTIFS('List AC'!$AV:$AV,$C12)>0,'List AC'!$AV$2,COUNTIFS('List AC'!$AW:$AW,$C12)>0,'List AC'!$AW$2,COUNTIFS('List AC'!$AX:$AX,$C12)>0,'List AC'!$AX$2,COUNTIFS('List AC'!$AY:$AY,$C12)>0,'List AC'!$AY$2,COUNTIFS('List AC'!$AZ:$AZ,$C12)>0,'List AC'!$AZ$2,COUNTIFS('List AC'!$BA:$BA,$C12)>0,'List AC'!$BA$2,COUNTIFS('List AC'!$BB:$BB,$C12)>0,'List AC'!$BB$2,COUNTIFS('List AC'!$BC:$BC,$C12)>0,'List AC'!$BC$2,COUNTIFS('List AC'!$BD:$BD,$C12)>0,'List AC'!$BD$2),"")
A13: 46283 | B13: WG 07 | C13: PK-LUG | D13: NID016210 | E13: REF FINDING NO FND 17644 FOUND DENT AT VHF #2 ANTENA | F13: PAINTING | G13: 46274 | H13: 46394 | K13: WAITING PERFORM | L13: ID | M13: A320 | N13: CGK | O13: 46287 | Q13: OPEN | S13: =IFNA(IFS(COUNTIFS('List AC'!$A:$A,$C13)>0,'List AC'!$A$2,COUNTIFS('List AC'!$B:$B,$C13)>0,'List AC'!$B$2,COUNTIFS('List AC'!$C:$C,$C13)>0,'List AC'!$C$2,COUNTIFS('List AC'!$D:$D,$C13)>0,'List AC'!$D$2,COUNTIFS('List AC'!$E:$E,$C13)>0,'List AC'!$E$2,COUNTIFS('List AC'!$F:$F,$C13)>0,'List AC'!$F$2,COUNTIFS('List AC'!$G:$G,$C13)>0,'List AC'!$G$2,COUNTIFS('List AC'!$H:$H,$C13)>0,'List AC'!$H$2,COUNTIFS('List AC'!$I:$I,$C13)>0,'List AC'!$I$2,COUNTIFS('List AC'!$J:$J,$C13)>0,'List AC'!$J$2,COUNTIFS('List AC'!$K:$K,$C13)>0,'List AC'!$K$2,COUNTIFS('List AC'!$L:$L,$C13)>0,'List AC'!$L$2,COUNTIFS('List AC'!$Q:$Q,$C13)>0,'List AC'!$Q$2,COUNTIFS('List AC'!$M:$M,$C13)>0,'List AC'!$M$2,COUNTIFS('List AC'!$N:$N,$C13)>0,'List AC'!$N$2,COUNTIFS('List AC'!$O:$O,$C13)>0,'List AC'!$O$2,COUNTIFS('List AC'!$P:$P,$C13)>0,'List AC'!$P$2,COUNTIFS('List AC'!$R:$R,$C13)>0,'List AC'!$R$2,COUNTIFS('List AC'!$S:$S,$C13)>0,'List AC'!$S$2,COUNTIFS('List AC'!$T:$T,$C13)>0,'List AC'!$T$2,COUNTIFS('List AC'!$U:$U,$C13)>0,'List AC'!$U$2,COUNTIFS('List AC'!$V:$V,$C13)>0,'List AC'!$V$2,COUNTIFS('List AC'!$W:$W,$C13)>0,'List AC'!$W$2,COUNTIFS('List AC'!$X:$X,$C13)>0,'List AC'!$X$2,COUNTIFS('List AC'!$Y:$Y,$C13)>0,'List AC'!$Y$2,COUNTIFS('List AC'!$Z:$Z,$C13)>0,'List AC'!$Z$2,COUNTIFS('List AC'!$AA:$AA,$C13)>0,'List AC'!$AA$2,COUNTIFS('List AC'!$AB:$AB,$C13)>0,'List AC'!$AB$2,COUNTIFS('List AC'!$AC:$AC,$C13)>0,'List AC'!$AC$2,COUNTIFS('List AC'!$AD:$AD,$C13)>0,'List AC'!$AD$2,COUNTIFS('List AC'!$AE:$AE,$C13)>0,'List AC'!$AE$2,COUNTIFS('List AC'!$AF:$AF,$C13)>0,'List AC'!$AF$2,COUNTIFS('List AC'!$AG:$AG,$C13)>0,'List AC'!$AG$2,COUNTIFS('List AC'!$AH:$AH,$C13)>0,'List AC'!$AH$2,COUNTIFS('List AC'!$AI:$AI,$C13)>0,'List AC'!$AI$2,COUNTIFS('List AC'!$AJ:$AJ,$C13)>0,'List AC'!$AJ$2,COUNTIFS('List AC'!$AK:$AK,$C13)>0,'List AC'!$AK$2,COUNTIFS('List AC'!$AL:$AL,$C13)>0,'List AC'!$AL$2,COUNTIFS('List AC'!$AM:$AM,$C13)>0,'List AC'!$AM$2,COUNTIFS('List AC'!$AN:$AN,$C13)>0,'List AC'!$AN$2,COUNTIFS('List AC'!$AO:$AO,$C13)>0,'List AC'!$AO$2,COUNTIFS('List AC'!$AP:$AP,$C13)>0,'List AC'!$AP$2,COUNTIFS('List AC'!$AQ:$AQ,$C13)>0,'List AC'!$AQ$2,COUNTIFS('List AC'!$AR:$AR,$C13)>0,'List AC'!$AR$2,COUNTIFS('List AC'!$AS:$AS,$C13)>0,'List AC'!$AS$2,COUNTIFS('List AC'!$AT:$AT,$C13)>0,'List AC'!$AT$2,COUNTIFS('List AC'!$AU:$AU,$C13)>0,'List AC'!$AU$2,COUNTIFS('List AC'!$AV:$AV,$C13)>0,'List AC'!$AV$2,COUNTIFS('List AC'!$AW:$AW,$C13)>0,'List AC'!$AW$2,COUNTIFS('List AC'!$AX:$AX,$C13)>0,'List AC'!$AX$2,COUNTIFS('List AC'!$AY:$AY,$C13)>0,'List AC'!$AY$2,COUNTIFS('List AC'!$AZ:$AZ,$C13)>0,'List AC'!$AZ$2,COUNTIFS('List AC'!$BA:$BA,$C13)>0,'List AC'!$BA$2,COUNTIFS('List AC'!$BB:$BB,$C13)>0,'List AC'!$BB$2,COUNTIFS('List AC'!$BC:$BC,$C13)>0,'List AC'!$BC$2,COUNTIFS('List AC'!$BD:$BD,$C13)>0,'List AC'!$BD$2),"") | T13: DENT LM SIDE | U13: TC
A14: 46283 | B14: WG 06 | C14: PK-LUR | D14: NID008797 | E14: DURING DAILY CHECK PERFORM W/O CABIN INSPECTION COVER AND PRAME FLASH ELECTRICAL SWITCH LD & LE FOUND BAD CONDITION | F14: CBM | G14: 46281 | K14: INVESTIGATE | L14: ID | M14: A320 | N14: SRG | O14: 46287 | P14: PLEASE INVESTIGATE AND RECTIFICATION. IF NEED SPARE PARTS, PLEASE CREATE RQ IN EMRO | Q14: CLOSED | R14: 46287 | S14: =IFNA(IFS(COUNTIFS('List AC'!$A:$A,$C14)>0,'List AC'!$A$2,COUNTIFS('List AC'!$B:$B,$C14)>0,'List AC'!$B$2,COUNTIFS('List AC'!$C:$C,$C14)>0,'List AC'!$C$2,COUNTIFS('List AC'!$D:$D,$C14)>0,'List AC'!$D$2,COUNTIFS('List AC'!$E:$E,$C14)>0,'List AC'!$E$2,COUNTIFS('List AC'!$F:$F,$C14)>0,'List AC'!$F$2,COUNTIFS('List AC'!$G:$G,$C14)>0,'List AC'!$G$2,COUNTIFS('List AC'!$H:$H,$C14)>0,'List AC'!$H$2,COUNTIFS('List AC'!$I:$I,$C14)>0,'List AC'!$I$2,COUNTIFS('List AC'!$J:$J,$C14)>0,'List AC'!$J$2,COUNTIFS('List AC'!$K:$K,$C14)>0,'List AC'!$K$2,COUNTIFS('List AC'!$L:$L,$C14)>0,'List AC'!$L$2,COUNTIFS('List AC'!$Q:$Q,$C14)>0,'List AC'!$Q$2,COUNTIFS('List AC'!$M:$M,$C14)>0,'List AC'!$M$2,COUNTIFS('List AC'!$N:$N,$C14)>0,'List AC'!$N$2,COUNTIFS('List AC'!$O:$O,$C14)>0,'List AC'!$O$2,COUNTIFS('List AC'!$P:$P,$C14)>0,'List AC'!$P$2,COUNTIFS('List AC'!$R:$R,$C14)>0,'List AC'!$R$2,COUNTIFS('List AC'!$S:$S,$C14)>0,'List AC'!$S$2,COUNTIFS('List AC'!$T:$T,$C14)>0,'List AC'!$T$2,COUNTIFS('List AC'!$U:$U,$C14)>0,'List AC'!$U$2,COUNTIFS('List AC'!$V:$V,$C14)>0,'List AC'!$V$2,COUNTIFS('List AC'!$W:$W,$C14)>0,'List AC'!$W$2,COUNTIFS('List AC'!$X:$X,$C14)>0,'List AC'!$X$2,COUNTIFS('List AC'!$Y:$Y,$C14)>0,'List AC'!$Y$2,COUNTIFS('List AC'!$Z:$Z,$C14)>0,'List AC'!$Z$2,COUNTIFS('List AC'!$AA:$AA,$C14)>0,'List AC'!$AA$2,COUNTIFS('List AC'!$AB:$AB,$C14)>0,'List AC'!$AB$2,COUNTIFS('List AC'!$AC:$AC,$C14)>0,'List AC'!$AC$2,COUNTIFS('List AC'!$AD:$AD,$C14)>0,'List AC'!$AD$2,COUNTIFS('List AC'!$AE:$AE,$C14)>0,'List AC'!$AE$2,COUNTIFS('List AC'!$AF:$AF,$C14)>0,'List AC'!$AF$2,COUNTIFS('List AC'!$AG:$AG,$C14)>0,'List AC'!$AG$2,COUNTIFS('List AC'!$AH:$AH,$C14)>0,'List AC'!$AH$2,COUNTIFS('List AC'!$AI:$AI,$C14)>0,'List AC'!$AI$2,COUNTIFS('List AC'!$AJ:$AJ,$C14)>0,'List AC'!$AJ$2,COUNTIFS('List AC'!$AK:$AK,$C14)>0,'List AC'!$AK$2,COUNTIFS('List AC'!$AL:$AL,$C14)>0,'List AC'!$AL$2,COUNTIFS('List AC'!$AM:$AM,$C14)>0,'List AC'!$AM$2,COUNTIFS('List AC'!$AN:$AN,$C14)>0,'List AC'!$AN$2,COUNTIFS('List AC'!$AO:$AO,$C14)>0,'List AC'!$AO$2,COUNTIFS('List AC'!$AP:$AP,$C14)>0,'List AC'!$AP$2,COUNTIFS('List AC'!$AQ:$AQ,$C14)>0,'List AC'!$AQ$2,COUNTIFS('List AC'!$AR:$AR,$C14)>0,'List AC'!$AR$2,COUNTIFS('List AC'!$AS:$AS,$C14)>0,'List AC'!$AS$2,COUNTIFS('List AC'!$AT:$AT,$C14)>0,'List AC'!$AT$2,COUNTIFS('List AC'!$AU:$AU,$C14)>0,'List AC'!$AU$2,COUNTIFS('List AC'!$AV:$AV,$C14)>0,'List AC'!$AV$2,COUNTIFS('List AC'!$AW:$AW,$C14)>0,'List AC'!$AW$2,COUNTIFS('List AC'!$AX:$AX,$C14)>0,'List AC'!$AX$2,COUNTIFS('List AC'!$AY:$AY,$C14)>0,'List AC'!$AY$2,COUNTIFS('List AC'!$AZ:$AZ,$C14)>0,'List AC'!$AZ$2,COUNTIFS('List AC'!$BA:$BA,$C14)>0,'List AC'!$BA$2,COUNTIFS('List AC'!$BB:$BB,$C14)>0,'List AC'!$BB$2,COUNTIFS('List AC'!$BC:$BC,$C14)>0,'List AC'!$BC$2,COUNTIFS('List AC'!$BD:$BD,$C14)>0,'List AC'!$BD$2),"")
A15: 46283 | B15: WG 08 | C15: PK-SAS | D15: NSAJ002547 | E15: CABLE HANDSET AT 4L BAD CONDITIOJ | F15: CBM | G15: 46269 | H15: 46389 | I15: N40-1B20000-100 | J15: SUPPORT-BRACKET | K15: WAITING PERFORM | L15: IU | M15: A320 | N15: CGK | O15: 46287 | P15: PL: 591750 | Q15: CLOSED | R15: 46287 | S15: =IFNA(IFS(COUNTIFS('List AC'!$A:$A,$C15)>0,'List AC'!$A$2,COUNTIFS('List AC'!$B:$B,$C15)>0,'List AC'!$B$2,COUNTIFS('List AC'!$C:$C,$C15)>0,'List AC'!$C$2,COUNTIFS('List AC'!$D:$D,$C15)>0,'List AC'!$D$2,COUNTIFS('List AC'!$E:$E,$C15)>0,'List AC'!$E$2,COUNTIFS('List AC'!$F:$F,$C15)>0,'List AC'!$F$2,COUNTIFS('List AC'!$G:$G,$C15)>0,'List AC'!$G$2,COUNTIFS('List AC'!$H:$H,$C15)>0,'List AC'!$H$2,COUNTIFS('List AC'!$I:$I,$C15)>0,'List AC'!$I$2,COUNTIFS('List AC'!$J:$J,$C15)>0,'List AC'!$J$2,COUNTIFS('List AC'!$K:$K,$C15)>0,'List AC'!$K$2,COUNTIFS('List AC'!$L:$L,$C15)>0,'List AC'!$L$2,COUNTIFS('List AC'!$Q:$Q,$C15)>0,'List AC'!$Q$2,COUNTIFS('List AC'!$M:$M,$C15)>0,'List AC'!$M$2,COUNTIFS('List AC'!$N:$N,$C15)>0,'List AC'!$N$2,COUNTIFS('List AC'!$O:$O,$C15)>0,'List AC'!$O$2,COUNTIFS('List AC'!$P:$P,$C15)>0,'List AC'!$P$2,COUNTIFS('List AC'!$R:$R,$C15)>0,'List AC'!$R$2,COUNTIFS('List AC'!$S:$S,$C15)>0,'List AC'!$S$2,COUNTIFS('List AC'!$T:$T,$C15)>0,'List AC'!$T$2,COUNTIFS('List AC'!$U:$U,$C15)>0,'List AC'!$U$2,COUNTIFS('List AC'!$V:$V,$C15)>0,'List AC'!$V$2,COUNTIFS('List AC'!$W:$W,$C15)>0,'List AC'!$W$2,COUNTIFS('List AC'!$X:$X,$C15)>0,'List AC'!$X$2,COUNTIFS('List AC'!$Y:$Y,$C15)>0,'List AC'!$Y$2,COUNTIFS('List AC'!$Z:$Z,$C15)>0,'List AC'!$Z$2,COUNTIFS('List AC'!$AA:$AA,$C15)>0,'List AC'!$AA$2,COUNTIFS('List AC'!$AB:$AB,$C15)>0,'List AC'!$AB$2,COUNTIFS('List AC'!$AC:$AC,$C15)>0,'List AC'!$AC$2,COUNTIFS('List AC'!$AD:$AD,$C15)>0,'List AC'!$AD$2,COUNTIFS('List AC'!$AE:$AE,$C15)>0,'List AC'!$AE$2,COUNTIFS('List AC'!$AF:$AF,$C15)>0,'List AC'!$AF$2,COUNTIFS('List AC'!$AG:$AG,$C15)>0,'List AC'!$AG$2,COUNTIFS('List AC'!$AH:$AH,$C15)>0,'List AC'!$AH$2,COUNTIFS('List AC'!$AI:$AI,$C15)>0,'List AC'!$AI$2,COUNTIFS('List AC'!$AJ:$AJ,$C15)>0,'List AC'!$AJ$2,COUNTIFS('List AC'!$AK:$AK,$C15)>0,'List AC'!$AK$2,COUNTIFS('List AC'!$AL:$AL,$C15)>0,'List AC'!$AL$2,COUNTIFS('List AC'!$AM:$AM,$C15)>0,'List AC'!$AM$2,COUNTIFS('List AC'!$AN:$AN,$C15)>0,'List AC'!$AN$2,COUNTIFS('List AC'!$AO:$AO,$C15)>0,'List AC'!$AO$2,COUNTIFS('List AC'!$AP:$AP,$C15)>0,'List AC'!$AP$2,COUNTIFS('List AC'!$AQ:$AQ,$C15)>0,'List AC'!$AQ$2,COUNTIFS('List AC'!$AR:$AR,$C15)>0,'List AC'!$AR$2,COUNTIFS('List AC'!$AS:$AS,$C15)>0,'List AC'!$AS$2,COUNTIFS('List AC'!$AT:$AT,$C15)>0,'List AC'!$AT$2,COUNTIFS('List AC'!$AU:$AU,$C15)>0,'List AC'!$AU$2,COUNTIFS('List AC'!$AV:$AV,$C15)>0,'List AC'!$AV$2,COUNTIFS('List AC'!$AW:$AW,$C15)>0,'List AC'!$AW$2,COUNTIFS('List AC'!$AX:$AX,$C15)>0,'List AC'!$AX$2,COUNTIFS('List AC'!$AY:$AY,$C15)>0,'List AC'!$AY$2,COUNTIFS('List AC'!$AZ:$AZ,$C15)>0,'List AC'!$AZ$2,COUNTIFS('List AC'!$BA:$BA,$C15)>0,'List AC'!$BA$2,COUNTIFS('List AC'!$BB:$BB,$C15)>0,'List AC'!$BB$2,COUNTIFS('List AC'!$BC:$BC,$C15)>0,'List AC'!$BC$2,COUNTIFS('List AC'!$BD:$BD,$C15)>0,'List AC'!$BD$2),"")
A16: 46283 | B16: WG 08 | C16: PK-SAS | D16: NSAJ002548 | E16: REFF NSRDI NO NSAJ002512,ACCES DOOR AT LAVATORY D CANT LOCK PROPERLY | F16: CBM | G16: 46269 | H16: 46389 | I16: A325400431-204 | J16: CATCH | K16: WAITING PERFORM | L16: IU | M16: A320 | N16: CGK | O16: 46287 | P16: AVAIL K1 : 4 EA (please replace with ex.repair part delta | Q16: CLOSED | R16: 46287 | S16: =IFNA(IFS(COUNTIFS('List AC'!$A:$A,$C16)>0,'List AC'!$A$2,COUNTIFS('List AC'!$B:$B,$C16)>0,'List AC'!$B$2,COUNTIFS('List AC'!$C:$C,$C16)>0,'List AC'!$C$2,COUNTIFS('List AC'!$D:$D,$C16)>0,'List AC'!$D$2,COUNTIFS('List AC'!$E:$E,$C16)>0,'List AC'!$E$2,COUNTIFS('List AC'!$F:$F,$C16)>0,'List AC'!$F$2,COUNTIFS('List AC'!$G:$G,$C16)>0,'List AC'!$G$2,COUNTIFS('List AC'!$H:$H,$C16)>0,'List AC'!$H$2,COUNTIFS('List AC'!$I:$I,$C16)>0,'List AC'!$I$2,COUNTIFS('List AC'!$J:$J,$C16)>0,'List AC'!$J$2,COUNTIFS('List AC'!$K:$K,$C16)>0,'List AC'!$K$2,COUNTIFS('List AC'!$L:$L,$C16)>0,'List AC'!$L$2,COUNTIFS('List AC'!$Q:$Q,$C16)>0,'List AC'!$Q$2,COUNTIFS('List AC'!$M:$M,$C16)>0,'List AC'!$M$2,COUNTIFS('List AC'!$N:$N,$C16)>0,'List AC'!$N$2,COUNTIFS('List AC'!$O:$O,$C16)>0,'List AC'!$O$2,COUNTIFS('List AC'!$P:$P,$C16)>0,'List AC'!$P$2,COUNTIFS('List AC'!$R:$R,$C16)>0,'List AC'!$R$2,COUNTIFS('List AC'!$S:$S,$C16)>0,'List AC'!$S$2,COUNTIFS('List AC'!$T:$T,$C16)>0,'List AC'!$T$2,COUNTIFS('List AC'!$U:$U,$C16)>0,'List AC'!$U$2,COUNTIFS('List AC'!$V:$V,$C16)>0,'List AC'!$V$2,COUNTIFS('List AC'!$W:$W,$C16)>0,'List AC'!$W$2,COUNTIFS('List AC'!$X:$X,$C16)>0,'List AC'!$X$2,COUNTIFS('List AC'!$Y:$Y,$C16)>0,'List AC'!$Y$2,COUNTIFS('List AC'!$Z:$Z,$C16)>0,'List AC'!$Z$2,COUNTIFS('List AC'!$AA:$AA,$C16)>0,'List AC'!$AA$2,COUNTIFS('List AC'!$AB:$AB,$C16)>0,'List AC'!$AB$2,COUNTIFS('List AC'!$AC:$AC,$C16)>0,'List AC'!$AC$2,COUNTIFS('List AC'!$AD:$AD,$C16)>0,'List AC'!$AD$2,COUNTIFS('List AC'!$AE:$AE,$C16)>0,'List AC'!$AE$2,COUNTIFS('List AC'!$AF:$AF,$C16)>0,'List AC'!$AF$2,COUNTIFS('List AC'!$AG:$AG,$C16)>0,'List AC'!$AG$2,COUNTIFS('List AC'!$AH:$AH,$C16)>0,'List AC'!$AH$2,COUNTIFS('List AC'!$AI:$AI,$C16)>0,'List AC'!$AI$2,COUNTIFS('List AC'!$AJ:$AJ,$C16)>0,'List AC'!$AJ$2,COUNTIFS('List AC'!$AK:$AK,$C16)>0,'List AC'!$AK$2,COUNTIFS('List AC'!$AL:$AL,$C16)>0,'List AC'!$AL$2,COUNTIFS('List AC'!$AM:$AM,$C16)>0,'List AC'!$AM$2,COUNTIFS('List AC'!$AN:$AN,$C16)>0,'List AC'!$AN$2,COUNTIFS('List AC'!$AO:$AO,$C16)>0,'List AC'!$AO$2,COUNTIFS('List AC'!$AP:$AP,$C16)>0,'List AC'!$AP$2,COUNTIFS('List AC'!$AQ:$AQ,$C16)>0,'List AC'!$AQ$2,COUNTIFS('List AC'!$AR:$AR,$C16)>0,'List AC'!$AR$2,COUNTIFS('List AC'!$AS:$AS,$C16)>0,'List AC'!$AS$2,COUNTIFS('List AC'!$AT:$AT,$C16)>0,'List AC'!$AT$2,COUNTIFS('List AC'!$AU:$AU,$C16)>0,'List AC'!$AU$2,COUNTIFS('List AC'!$AV:$AV,$C16)>0,'List AC'!$AV$2,COUNTIFS('List AC'!$AW:$AW,$C16)>0,'List AC'!$AW$2,COUNTIFS('List AC'!$AX:$AX,$C16)>0,'List AC'!$AX$2,COUNTIFS('List AC'!$AY:$AY,$C16)>0,'List AC'!$AY$2,COUNTIFS('List AC'!$AZ:$AZ,$C16)>0,'List AC'!$AZ$2,COUNTIFS('List AC'!$BA:$BA,$C16)>0,'List AC'!$BA$2,COUNTIFS('List AC'!$BB:$BB,$C16)>0,'List AC'!$BB$2,COUNTIFS('List AC'!$BC:$BC,$C16)>0,'List AC'!$BC$2,COUNTIFS('List AC'!$BD:$BD,$C16)>0,'List AC'!$BD$2),"")
A17: 46276 | B17: WG 08 | C17: PK-SGD | D17: NSAJ008205 | E17: WORKING LIGHT FA1 & FA4 STILL DIM | F17: CBM | G17: 46283 | H17: 46403 | K17: INVESTIGATE | L17: IU | M17: A320 | N17: CGK | O17: 46287 | P17: PLEASE INVESTIGATE AND RECTIFICATION. IF NEED SPARE PARTS, PLEASE CREATE RQ IN EMRO | Q17: CLOSED | R17: 46287 | S17: =IFNA(IFS(COUNTIFS('List AC'!$A:$A,$C17)>0,'List AC'!$A$2,COUNTIFS('List AC'!$B:$B,$C17)>0,'List AC'!$B$2,COUNTIFS('List AC'!$C:$C,$C17)>0,'List AC'!$C$2,COUNTIFS('List AC'!$D:$D,$C17)>0,'List AC'!$D$2,COUNTIFS('List AC'!$E:$E,$C17)>0,'List AC'!$E$2,COUNTIFS('List AC'!$F:$F,$C17)>0,'List AC'!$F$2,COUNTIFS('List AC'!$G:$G,$C17)>0,'List AC'!$G$2,COUNTIFS('List AC'!$H:$H,$C17)>0,'List AC'!$H$2,COUNTIFS('List AC'!$I:$I,$C17)>0,'List AC'!$I$2,COUNTIFS('List AC'!$J:$J,$C17)>0,'List AC'!$J$2,COUNTIFS('List AC'!$K:$K,$C17)>0,'List AC'!$K$2,COUNTIFS('List AC'!$L:$L,$C17)>0,'List AC'!$L$2,COUNTIFS('List AC'!$Q:$Q,$C17)>0,'List AC'!$Q$2,COUNTIFS('List AC'!$M:$M,$C17)>0,'List AC'!$M$2,COUNTIFS('List AC'!$N:$N,$C17)>0,'List AC'!$N$2,COUNTIFS('List AC'!$O:$O,$C17)>0,'List AC'!$O$2,COUNTIFS('List AC'!$P:$P,$C17)>0,'List AC'!$P$2,COUNTIFS('List AC'!$R:$R,$C17)>0,'List AC'!$R$2,COUNTIFS('List AC'!$S:$S,$C17)>0,'List AC'!$S$2,COUNTIFS('List AC'!$T:$T,$C17)>0,'List AC'!$T$2,COUNTIFS('List AC'!$U:$U,$C17)>0,'List AC'!$U$2,COUNTIFS('List AC'!$V:$V,$C17)>0,'List AC'!$V$2,COUNTIFS('List AC'!$W:$W,$C17)>0,'List AC'!$W$2,COUNTIFS('List AC'!$X:$X,$C17)>0,'List AC'!$X$2,COUNTIFS('List AC'!$Y:$Y,$C17)>0,'List AC'!$Y$2,COUNTIFS('List AC'!$Z:$Z,$C17)>0,'List AC'!$Z$2,COUNTIFS('List AC'!$AA:$AA,$C17)>0,'List AC'!$AA$2,COUNTIFS('List AC'!$AB:$AB,$C17)>0,'List AC'!$AB$2,COUNTIFS('List AC'!$AC:$AC,$C17)>0,'List AC'!$AC$2,COUNTIFS('List AC'!$AD:$AD,$C17)>0,'List AC'!$AD$2,COUNTIFS('List AC'!$AE:$AE,$C17)>0,'List AC'!$AE$2,COUNTIFS('List AC'!$AF:$AF,$C17)>0,'List AC'!$AF$2,COUNTIFS('List AC'!$AG:$AG,$C17)>0,'List AC'!$AG$2,COUNTIFS('List AC'!$AH:$AH,$C17)>0,'List AC'!$AH$2,COUNTIFS('List AC'!$AI:$AI,$C17)>0,'List AC'!$AI$2,COUNTIFS('List AC'!$AJ:$AJ,$C17)>0,'List AC'!$AJ$2,COUNTIFS('List AC'!$AK:$AK,$C17)>0,'List AC'!$AK$2,COUNTIFS('List AC'!$AL:$AL,$C17)>0,'List AC'!$AL$2,COUNTIFS('List AC'!$AM:$AM,$C17)>0,'List AC'!$AM$2,COUNTIFS('List AC'!$AN:$AN,$C17)>0,'List AC'!$AN$2,COUNTIFS('List AC'!$AO:$AO,$C17)>0,'List AC'!$AO$2,COUNTIFS('List AC'!$AP:$AP,$C17)>0,'List AC'!$AP$2,COUNTIFS('List AC'!$AQ:$AQ,$C17)>0,'List AC'!$AQ$2,COUNTIFS('List AC'!$AR:$AR,$C17)>0,'List AC'!$AR$2,COUNTIFS('List AC'!$AS:$AS,$C17)>0,'List AC'!$AS$2,COUNTIFS('List AC'!$AT:$AT,$C17)>0,'List AC'!$AT$2,COUNTIFS('List AC'!$AU:$AU,$C17)>0,'List AC'!$AU$2,COUNTIFS('List AC'!$AV:$AV,$C17)>0,'List AC'!$AV$2,COUNTIFS('List AC'!$AW:$AW,$C17)>0,'List AC'!$AW$2,COUNTIFS('List AC'!$AX:$AX,$C17)>0,'List AC'!$AX$2,COUNTIFS('List AC'!$AY:$AY,$C17)>0,'List AC'!$AY$2,COUNTIFS('List AC'!$AZ:$AZ,$C17)>0,'List AC'!$AZ$2,COUNTIFS('List AC'!$BA:$BA,$C17)>0,'List AC'!$BA$2,COUNTIFS('List AC'!$BB:$BB,$C17)>0,'List AC'!$BB$2,COUNTIFS('List AC'!$BC:$BC,$C17)>0,'List AC'!$BC$2,COUNTIFS('List AC'!$BD:$BD,$C17)>0,'List AC'!$BD$2),"")
